<?xml version='1.0' encoding='UTF-8'?>
<mujoco model="model">
  <option timestep="0.002" gravity="0.0 0.0 -9.81"/>
  <compiler angle="radian"/>
  <asset>
    <mesh file="visuals/Blade001.obj" name="Blade001_vis"/>
    <mesh file="visuals/Body001.obj" name="Body001_vis"/>
    <mesh file="visuals/Button001.obj" name="Button001_vis"/>
    <mesh file="visuals/Jug001.obj" name="Jug001_vis"/>
    <mesh file="visuals/Jug001_Clear.obj" name="Jug001_Clear_vis"/>
    <mesh file="visuals/Knob001.obj" name="Knob001_vis"/>
    <mesh file="visuals/Lid001.obj" name="Lid001_vis"/>
    <texture file="visuals/T_BC001.png" name="Body001_material" type="2d"/>
    <material name="Body001_material" rgba="1 1 1 1.0" texture="Body001_material" shininess="0.141421377658844" specular="0.3103448502657381"/>
    <texture file="visuals/T_BC001.png" name="Button001_material" type="2d"/>
    <material name="Button001_material" rgba="1 1 1 1.0" texture="Button001_material" shininess="0.141421377658844" specular="0.3103448502657381"/>
    <texture file="visuals/T_BC001.png" name="Jug001_Clear_material" type="2d"/>
    <material name="Jug001_Clear_material" rgba="1 1 1 0.699999988079071" texture="Jug001_Clear_material" shininess="0.141421377658844" specular="0.3103448502657381"/>
    <texture file="visuals/T_BC001.png" name="Blade001_material" type="2d"/>
    <material name="Blade001_material" rgba="1 1 1 1.0" texture="Blade001_material" shininess="0.141421377658844" specular="3"/>
    <texture file="visuals/T_BC001.png" name="Jug001_material" type="2d"/>
    <material name="Jug001_material" rgba="1 1 1 1.0" texture="Jug001_material" shininess="0.141421377658844" specular="0.3103448502657381"/>
    <texture file="visuals/T_BC001.png" name="Lid001_material" type="2d"/>
    <material name="Lid001_material" rgba="1 1 1 1.0" texture="Lid001_material" shininess="0.141421377658844" specular="0.3103448502657381"/>
    <texture file="visuals/T_BC001.png" name="Knob001_material" type="2d"/>
    <material name="Knob001_material" rgba="1 1 1 1.0" texture="Knob001_material" shininess="0.141421377658844" specular="0.3103448502657381"/>
  </asset>
  <default>
    <default class="visual">
      <geom conaffinity="0" contype="0" group="1" type="mesh"/>
    </default>
    <default class="collision">
      <geom group="0" rgba="0.5 0 0 0.5"/>
    </default>
    <default class="spawn">
      <geom group="0" rgba="1 1 1 0.5" contype="0" conaffinity="0"/>
      <site group="0" rgba="1 1 1 0.5"/>
    </default>
    <default class="region">
      <geom group="1" conaffinity="0" contype="0" rgba="0 1 0 0"/>
    </default>
  </default>
  <worldbody>
    <body>
      <body name="object">
        <geom mesh="Body001_vis" type="mesh" solimp="0.998 0.998 0.001" solref="0.001 1" friction="0.95 0.3 0.1" class="visual" material="Body001_material"/>
        <geom class="collision" type="box" pos="-0.00002147 -0.00441655 -0.17498938" size="0.09426623582839966 0.12018150091171265 0.05047569051384926" quat="1.0 0.0 0.0 0.0"/>
        <geom class="collision" type="box" pos="-0.00064245 -0.06574792 -0.12190512" size="0.09364525973796844 0.053700391203165054 0.023921413347125053" quat="0.9748296737670898 0.22295093536376953 0.0 0.0"/>
        <geom class="collision" type="box" pos="0.00018059 0.02595534 -0.06946505" size="0.0737367644906044 0.0752071812748909 0.013908842578530312" quat="1.0 0.0 0.0 0.0"/>
        <geom class="collision" type="box" pos="-0.00064245 0.03169942 -0.10404636" size="0.09364525973796844 0.08006376773118973 0.02117438241839409" quat="1.0 0.0 0.0 0.0"/>
        <body name="Button001">
          <joint axis="0.0 0.4999999403953552 -0.8660253882408142" pos="-0.04367841 -0.06530490 -0.08817581" limited="true" name="Button001_joint" range="0.0 0.002" type="slide" damping="1" frictionloss="1" armature=".01" stiffness="0.5" springref="-0.5"/>
          <geom mesh="Button001_vis" type="mesh" solimp="0.998 0.998 0.001" solref="0.001 1" friction="0.95 0.3 0.1" class="visual" material="Button001_material"/>
          <geom class="collision" type="cylinder" pos="-0.04389239 -0.06643220 -0.08646378" size="0.006768199615180492 0.0021915838588029146" quat="0.9639899730682373 0.2659386098384857 -4.0169945262216606e-17 -4.33204661115555e-18"/>
        </body>
        <body name="Jug001_Clear">
          <geom class="region" name="reg_int" type="box" pos="0.0024833899999999985 0.023565485 0.10616642" size="0.037405469999999996 0.038185975000000004 0.0820578"/>
          <!-- <joint axis="0.0 0.0 1.0" pos="0.01373654 0.03952696 0.08051294" limited="true" name="Jug001_Clear_joint" range="0.0 0.05" type="slide" damping="1" frictionloss="1" armature=".01" stiffness="0.05"/> -->
          <geom mesh="Jug001_Clear_vis" type="mesh" solimp="0.998 0.998 0.001" solref="0.001 1" friction="0.95 0.3 0.1" class="visual" material="Jug001_Clear_material"/>
          <geom class="collision" type="box" pos="-0.00033165 -0.03700097 0.07271677" size="0.05070013180375099 0.006148476153612137 0.1268603503704071" quat="1.0 0.0 0.0 0.0"/>
          <geom class="collision" type="box" pos="-0.05555039 0.02377511 0.07271677" size="0.0061484710313379765 0.06666272133588791 0.1268603503704071" quat="1.0 0.0 0.0 0.0"/>
          <geom class="collision" type="box" pos="0.05462990 0.02377511 0.07271677" size="0.0061484710313379765 0.06666272133588791 0.1268603503704071" quat="1.0 0.0 0.0 0.0"/>
          <geom class="collision" type="box" pos="-0.00033165 0.08407823 0.07271677" size="0.05070013180375099 0.006148476153612137 0.1268603503704071" quat="1.0 0.0 0.0 0.0"/>
          <geom class="collision" type="box" pos="0.07456364 0.10604493 0.17313410" size="0.008146869018673897 0.014489687979221344 0.01081995852291584" quat="0.9147748947143555 -0.18078604340553284 0.07120805233716965 -0.35416480898857117"/>
          <geom class="collision" type="box" pos="0.06166478 0.09281201 0.18320061" size="0.008105769753456116 0.012879735790193081 0.01025380939245224" quat="0.9265184998512268 0.0 -0.0 -0.376249223947525"/>
          <geom class="collision" type="box" pos="0.08343097 0.11537700 0.15525619" size="0.008146869018673897 0.014489687979221344 0.01081995852291584" quat="0.8578605055809021 -0.36547520756721497 0.14268623292446136 -0.33187922835350037"/>
          <geom class="collision" type="box" pos="0.08176104 0.11330621 0.10343436" size="0.008295845240354538 0.020325474441051483 0.012872149236500263" quat="0.6699399948120117 -0.6485963463783264 0.2521308958530426 -0.2587145268917084"/>
          <geom class="collision" type="box" pos="0.08591630 0.11754181 0.13361492" size="0.008146869018673897 0.014489687979221344 0.01081995852291584" quat="0.7432904839515686 -0.5630417466163635 0.21907974779605865 -0.2872408926486969"/>
          <geom class="collision" type="box" pos="0.06638283 0.09800544 0.06453448" size="0.008534789085388184 0.029685476794838905 0.016163652762770653" quat="0.551007866859436 -0.7522546648979187 0.2921375334262848 -0.2125062644481659"/>
          <geom class="collision" type="box" pos="0.00046516 0.02377511 -0.03018199" size="0.058229099959135056 0.06666272133588791 0.02488800324499607" quat="1.0 0.0 0.0 0.0"/>
          <body name="Blade001">
            <joint axis="0.0 0.0 1.0" pos="0.00283731 0.02211281 0.00559409" limited="false" name="Blade001_joint" range="0 360" type="hinge" damping="1" frictionloss="1" armature=".01" stiffness="0.05"/>
            <geom mesh="Blade001_vis" type="mesh" solimp="0.998 0.998 0.001" solref="0.001 1" friction="0.95 0.3 0.1" class="visual" material="Blade001_material"/>
            <geom class="collision" type="cylinder" pos="0.00223650 0.02223911 0.00248152" size="0.010992518626153469 0.0019860181491822004" quat="1.0 0.0 0.0 0.0"/>
            <geom class="collision" type="box" pos="-0.00622816 0.03753667 0.00460831" size="0.004382163751870394 0.009873579256236553 0.0014099429827183485" quat="0.9596688747406006 0.10713987052440643 0.02883859910070896 0.2583118677139282"/>
            <geom class="collision" type="box" pos="-0.01331299 0.04974379 0.01119832" size="0.004382163751870394 0.006865778472274542 0.0006997823365963995" quat="0.9061315655708313 0.33371978998184204 0.08982662111520767 0.24390141665935516"/>
            <geom class="collision" type="box" pos="-0.01503233 0.02199415 0.00991785" size="0.002498094690963626 0.003913902677595615 0.00039891761844046414" quat="0.657715380191803 0.2422304004430771 0.246499702334404 0.6693077087402344"/>
            <geom class="collision" type="box" pos="-0.00744480 0.02213470 0.00548553" size="0.002498094690963626 0.005628528073430061 0.000803751521743834" quat="0.6832320690155029 0.15710075199604034 0.1570800542831421 0.6955854892730713"/>
            <geom class="collision" type="box" pos="-0.01368735 -0.00627486 0.01119832" size="0.004382163751870394 0.006865778472274542 0.0006997823365963995" quat="0.24510179460048676 0.09026868641376495 0.33360037207603455 0.905807614326477"/>
            <geom class="collision" type="box" pos="-0.00657020 0.00591344 0.00460831" size="0.004382163751870394 0.009873579256236553 0.0014099429827183485" quat="0.2595832347869873 0.02898053452372551 0.10710156708955765 0.9593257904052734"/>
            <geom class="collision" type="box" pos="0.02113731 0.02173126 0.00460831" size="0.004382163751870394 0.009873579256236553 0.0014099429827183485" quat="0.7020411491394043 0.07837764918804169 -0.07853382080793381 -0.7034398317337036"/>
            <geom class="collision" type="box" pos="0.03525141 0.02170317 0.01119832" size="0.004382163751870394 0.006865778472274542 0.0006997823365963995" quat="0.6628762483596802 0.24413099884986877 -0.24461738765239716 -0.6641968488693237"/>
            <geom class="collision" type="box" pos="0.00918651 0.01180637 0.00583893" size="0.0024980942253023386 0.005628528073430061 0.000803751521743834" quat="0.26403868198394775 0.05822960287332535 -0.21439240872859955 -0.9385780692100525"/>
            <geom class="collision" type="box" pos="0.01314704 0.00533300 0.01027125" size="0.0024980942253023386 0.003913902677595615 0.00039891761844046414" quat="0.2539174556732178 0.09351541101932526 -0.33270493149757385 -0.903376042842865"/>
            <geom class="collision" type="box" pos="0.01284448 0.03860110 0.01003208" size="0.0024980944581329823 0.003913902677595615 0.00039891761844046414" quat="0.9036177396774292 0.3327938914299011 -0.09319815039634705 -0.25305595993995667"/>
            <geom class="collision" type="box" pos="0.00890995 0.03211190 0.00559976" size="0.0024980942253023386 0.005628528073430061 0.0008037514635361731" quat="0.9389471411705017 0.21339333057403564 -0.06179073452949524 -0.2627231776714325"/>
          </body>
          <body name="Jug001">
            <geom mesh="Jug001_vis" type="mesh" solimp="0.998 0.998 0.001" solref="0.001 1" friction="0.95 0.3 0.1" class="visual" material="Jug001_material"/>
            <geom class="collision" type="box" pos="-0.00025046 0.02358901 -0.02734018" size="0.053218137472867966 0.05842722952365875 0.02310650795698166" quat="1.0 0.0 0.0 0.0"/>
            <geom class="collision" type="cylinder" pos="0.00293614 0.02158020 -0.00302864" size="0.03135425224900246 0.0020198319107294083" quat="1.0 0.0 0.0 0.0"/>
            <geom class="collision" type="box" pos="-0.00033165 -0.03700097 0.07271677" size="0.05070013180375099 0.006148476153612137 0.1268603503704071" quat="1.0 0.0 0.0 0.0"/>
            <geom class="collision" type="box" pos="-0.05555039 0.02377511 0.07271677" size="0.0061484710313379765 0.06666272133588791 0.1268603503704071" quat="1.0 0.0 0.0 0.0"/>
            <geom class="collision" type="box" pos="0.05462990 0.02377511 0.07271677" size="0.0061484710313379765 0.06666272133588791 0.1268603503704071" quat="1.0 0.0 0.0 0.0"/>
            <geom class="collision" type="box" pos="-0.00033165 0.08407823 0.07271677" size="0.05070013180375099 0.006148476153612137 0.1268603503704071" quat="1.0 0.0 0.0 0.0"/>
            <geom class="collision" type="box" pos="0.07456364 0.10604493 0.17313410" size="0.008146869018673897 0.014489687979221344 0.01081995852291584" quat="0.9147748947143555 -0.18078604340553284 0.07120805233716965 -0.35416480898857117"/>
            <geom class="collision" type="box" pos="0.06166478 0.09281201 0.18320061" size="0.008105769753456116 0.012879735790193081 0.01025380939245224" quat="0.9265184998512268 0.0 -0.0 -0.376249223947525"/>
            <geom class="collision" type="box" pos="0.08343097 0.11537700 0.15525619" size="0.008146869018673897 0.014489687979221344 0.01081995852291584" quat="0.8578605055809021 -0.36547520756721497 0.14268623292446136 -0.33187922835350037"/>
            <geom class="collision" type="box" pos="0.08176104 0.11330621 0.10343436" size="0.008295845240354538 0.020325474441051483 0.012872149236500263" quat="0.6699399948120117 -0.6485963463783264 0.2521308958530426 -0.2587145268917084"/>
            <geom class="collision" type="box" pos="0.08591630 0.11754181 0.13361492" size="0.008146869018673897 0.014489687979221344 0.01081995852291584" quat="0.7432904839515686 -0.5630417466163635 0.21907974779605865 -0.2872408926486969"/>
            <geom class="collision" type="box" pos="0.06638283 0.09800544 0.06453448" size="0.008534789085388184 0.029685476794838905 0.016163652762770653" quat="0.551007866859436 -0.7522546648979187 0.2921375334262848 -0.2125062644481659"/>
            <geom class="collision" type="box" pos="0.00046516 0.02377511 -0.03018199" size="0.058229099959135056 0.06666272133588791 0.02488800324499607" quat="1.0 0.0 0.0 0.0"/>
          </body>
        </body>
        <body name="Knob001">
          <joint axis="0.0 0.5 -0.8660253882408142" pos="0.00031825 -0.09462214 -0.09418894" limited="true" name="Knob001_joint" range="0.0 3.141592653589793" type="hinge" damping="0.05" armature="0.001"/>
          <geom mesh="Knob001_vis" type="mesh" solimp="0.998 0.998 0.001" solref="0.001 1" friction="0.95 0.3 0.1" class="visual" material="Knob001_material"/>
          <geom class="collision" type="cylinder" pos="0.00041298 -0.09133510 -0.09954298" size="0.022349528968334198 0.004747109953314066" quat="0.9639899730682373 0.2659386098384857 -4.0169945262216606e-17 -4.33204661115555e-18"/>
          <geom class="collision" type="box" pos="0.00066754 -0.09641392 -0.09038294" size="0.005063396412879229 0.017123965546488762 0.009264831431210041" quat="0.6668792963027954 0.21136312186717987 0.17960307002067566 -0.6916215419769287"/>
        </body>
        <geom class="region" name="reg_main" type="box" pos="1.000000000001e-06 -0.004121 6.005000000003369e-06" size="0.09521162 0.12073614 0.226515665"/>
      </body>
      <site rgba="0 1 0 0" size="0.005" pos="0.00114566 0.0249901 0.21263005" name="anchor_site"/>
    </body>
  </worldbody>
  <actuator>
    <motor name="Button001_joint_actuator" joint="Button001_joint" gear="0.5"/>
    <!-- <motor name="Jug001_Clear_joint_actuator" joint="Jug001_Clear_joint" gear="0.5"/> -->
    <motor name="Knob001_joint_actuator" joint="Knob001_joint" gear="10"/>
    <motor name="Blade001_joint_actuator" joint="Blade001_joint" gear="10"/>
    <!-- <motor name="Lid001_joint_actuator" joint="Lid001_joint" gear="0.5"/> -->
  </actuator>
</mujoco>
