<?xml version='1.0' encoding='UTF-8'?>
<mujoco model="model">
  <option timestep="0.002" gravity="0.0 0.0 -9.81"/>
  <compiler angle="radian"/>
  <asset>
    <mesh file="visuals/blade.obj" name="blade_vis"/>
    <mesh file="visuals/Body001.obj" name="Body001_vis"/>
    <mesh file="visuals/knob_speed.obj" name="knob_speed_vis"/>
    <mesh file="visuals/pitcher.obj" name="pitcher_vis"/>
    <mesh file="visuals/pitcher_main.obj" name="pitcher_main_vis"/>
    <mesh file="visuals/power_button.obj" name="power_button_vis"/>
    <texture file="visuals/T_BC001.png" name="Body001_material" type="2d"/>
    <material name="Body001_material" rgba="1 1 1 1.0" texture="Body001_material" shininess="0.4472135901451111" specular="0.3103448502657381"/>
    <texture file="visuals/T_BC001.png" name="knob_speed_material" type="2d"/>
    <material name="knob_speed_material" rgba="1 1 1 1.0" texture="knob_speed_material" shininess="0.4472135901451111" specular="0.3103448502657381"/>
    <texture file="visuals/T_BC001.png" name="pitcher_material" type="2d"/>
    <material name="pitcher_material" rgba="1 1 1 0.800000011920929" texture="pitcher_material" shininess="0.4472135901451111" specular="0.3103448502657381"/>
    <texture file="visuals/T_BC001.png" name="blade_material" type="2d"/>
    <material name="blade_material" rgba="1 1 1 1.0" texture="blade_material" shininess="0.4472135901451111" specular="0.3103448502657381"/>
    <texture file="visuals/T_BC001.png" name="pitcher_main_material" type="2d"/>
    <material name="pitcher_main_material" rgba="1 1 1 1.0" texture="pitcher_main_material" shininess="0.4472135901451111" specular="0.3103448502657381"/>
    <texture file="visuals/T_BC001.png" name="power_button_material" type="2d"/>
    <material name="power_button_material" rgba="1 1 1 1.0" texture="power_button_material" shininess="0.4472135901451111" specular="0.3103448502657381"/>
  </asset>
  <default>
    <default class="visual">
      <geom conaffinity="0" contype="0" group="1" type="mesh"/>
    </default>
    <default class="collision">
      <geom group="0" rgba="0.5 0 0 0.5" density="1.0" solref="0.004 1" solimp="0.998 0.998 0.001"/>
    </default>
    <default class="spawn">
      <geom group="0" rgba="1 1 1 0.5" contype="0" conaffinity="0"/>
      <site group="0" rgba="1 1 1 0.5"/>
    </default>
    <default class="region">
      <geom group="1" conaffinity="0" contype="0" rgba="0 1 0 0" mass="0"/>
    </default>
  </default>
  <worldbody>
    <body>
      <body name="object">
        <geom mesh="Body001_vis" type="mesh" solimp="0.998 0.998 0.001" solref="0.001 1" friction="0.95 0.3 0.1" class="visual" material="Body001_material"/>
        <geom type="cylinder" pos="-0.00000350 0.00646550 -0.10880267" size="0.05027838423848152 0.050639983266592026" quat="1.0 0.0 0.0 0.0" class="collision"/>
        <geom type="box" pos="-0.00043333 -0.04804078 -0.12045336" size="0.02084752358496189 0.00483823474496603 0.020090635865926743" quat="1.0 0.0 0.0 0.0" class="collision"/>
        <geom type="box" pos="-0.00017542 -0.04277979 -0.05224721" size="0.02063511684536934 0.00401512673124671 0.008426142856478691" quat="1.0 0.0 0.0 0.0" class="collision"/>
        <geom type="box" pos="-0.05364602 0.00646552 -0.14757853" size="0.004174570087343454 0.010854005813598633 0.010854005813598633" quat="0.985356867313385 5.595070839132361e-16 -0.17050467431545258 -2.290881262467792e-08" class="collision"/>
        <geom type="box" pos="-0.05405436 0.00646551 -0.09121377" size="0.004025053698569536 0.010854005813598633 0.047436073422431946" quat="0.9993108510971069 3.921987009518433e-16 0.03711973503232002 4.987374513376608e-09" class="collision"/>
        <geom type="box" pos="-0.05030481 0.02510148 -0.14757853" size="0.004174570087343454 0.010854006744921207 0.010854005813598633" quat="0.9698918461799622 -0.03008974716067314 -0.16782867908477783 -0.17389047145843506" class="collision"/>
        <geom type="box" pos="-0.04106523 0.04098297 -0.14757853" size="0.004174570087343454 0.010854005813598633 0.010854004882276058" quat="0.9257819652557373 -0.05838760733604431 -0.16019588708877563 -0.33742547035217285" class="collision"/>
        <geom type="box" pos="-0.02651591 0.05309825 -0.14757853" size="0.004174570087343454 0.010854005813598633 0.010854004882276058" quat="0.8517047762870789 -0.08574175089597702 -0.14737769961357117 -0.4955069422721863" class="collision"/>
        <geom type="box" pos="-0.01005051 -0.04622776 -0.14757853" size="0.004174570087343454 0.010854005813598633 0.010854004882276058" quat="0.7592028379440308 0.1086895614862442 -0.13137130439281464 0.6281235814094543" class="collision"/>
        <geom type="box" pos="-0.02773087 -0.03945523 -0.14757853" size="0.004174570087343454 0.010854005813598633 0.010854004882276058" quat="0.8581354022026062 0.08379990607500076 -0.14849039912223816 0.4842848777770996" class="collision"/>
        <geom type="box" pos="-0.04160080 -0.02740462 -0.14757853" size="0.004174570087343454 0.010854004882276058 0.010854004882276058" quat="0.9283958673477173 0.057131316512823105 -0.1606481820344925 0.33016547560691833" class="collision"/>
        <geom type="box" pos="-0.05077667 -0.01084365 -0.14757853" size="0.004174570087343454 0.010854005813598633 0.010854006744921207" quat="0.9720907211303711 0.027884382754564285 -0.16820929944515228 0.1611451506614685" class="collision"/>
        <geom type="box" pos="0.04984379 -0.01335288 -0.14757853" size="0.004174570087343454 0.010854004882276058 0.010854004882276058" quat="0.18532882630825043 0.16746164858341217 -0.03206900879740715 0.9677713513374329" class="collision"/>
        <geom type="box" pos="0.03985387 -0.02943592 -0.14757853" size="0.004174570087343454 0.010854005813598633 0.010854004882276058" quat="0.35320740938186646 0.15917399525642395 -0.06111845746636391 0.9198764562606812" class="collision"/>
        <geom type="box" pos="0.02540053 -0.04078020 -0.14757853" size="0.004174570087343454 0.010854005813598633 0.010854004882276058" quat="0.5055273175239563 0.14635516703128815 -0.08747565746307373 0.8457956910133362" class="collision"/>
        <geom type="box" pos="0.00740456 -0.04666303 -0.14757853" size="0.004174570087343454 0.010854005813598633 0.010854004882276058" quat="0.646854817867279 0.12862089276313782 -0.1119307428598404 0.7433081865310669" class="collision"/>
        <geom type="box" pos="0.02917042 0.05148109 -0.14757853" size="0.004174570087343454 0.010854004882276058 0.010854005813598633" quat="0.4705747365951538 -0.1498044729232788 -0.08142750710248947 -0.8657295107841492" class="collision"/>
        <geom type="box" pos="0.04299215 0.03854189 -0.14757853" size="0.004174570087343454 0.010854006744921207 0.010854005813598633" quat="0.3104095458984375 -0.16182319819927216 -0.05371277779340744 -0.9351866841316223" class="collision"/>
        <geom type="box" pos="0.05129452 0.02215097 -0.14757853" size="0.004174570087343454 0.010854005813598633 0.010854004882276058" quat="0.1456633359193802 -0.16863130033016205 -0.02520536445081234 -0.9745308756828308" class="collision"/>
        <geom type="box" pos="0.05354862 0.00335250 -0.14757853" size="0.004174570087343454 0.010854005813598633 0.010854006744921207" quat="0.028603164479136467 0.17043240368366241 -0.004949431866407394 0.9849417209625244" class="collision"/>
        <geom type="box" pos="-0.01982993 0.05630959 -0.14757853" size="0.004174570087343454 0.010854005813598633 0.010854004882276058" quat="0.8154098391532898 -0.09572560340166092 -0.14109724760055542 -0.5532042980194092" class="collision"/>
        <geom type="box" pos="-0.00184653 0.06007635 -0.14757853" size="0.004174570087343454 0.010854004882276058 0.010854004882276058" quat="0.7086209058761597 -0.11847569048404694 -0.1226186603307724 -0.6846784949302673" class="collision"/>
        <geom type="box" pos="0.01689322 0.05737740 -0.14757853" size="0.004174570087343454 0.010854005813598633 0.010854005813598633" quat="0.5766705870628357 -0.13825532793998718 -0.0997861847281456 -0.7989863753318787" class="collision"/>
        <geom type="box" pos="-0.02775627 -0.03991638 -0.09121376" size="0.004025053698569536 0.010854003950953484 0.04743606224656105" quat="0.8693017959594727 -0.018308410421013832 0.0322905033826828 0.49288591742515564" class="collision"/>
        <geom type="box" pos="-0.04164471 -0.02799469 -0.09121377" size="0.004025053698569536 0.010854006744921207 0.047436073422431946" quat="0.9402043223381042 -0.012576751410961151 0.034924205392599106 0.33858224749565125" class="collision"/>
        <geom type="box" pos="-0.05095529 -0.01157364 -0.09121377" size="0.004025053698569536 0.010854006744921207 0.047436073422431946" quat="0.9848824739456177 -0.006284964736551046 0.036583706736564636 0.16919994354248047" class="collision"/>
        <geom type="box" pos="-0.01197282 0.05917443 -0.09121377" size="0.004025053698569536 0.010854005813598633 0.047436073422431946" quat="0.7809489965438843 0.023159775882959366 0.029008612036705017 -0.6234908103942871" class="collision"/>
        <geom type="box" pos="-0.05137957 0.02325818 -0.09121377" size="0.004025053698569536 0.010854004882276058 0.047436077147722244" quat="0.9868703484535217 0.005838928744196892 0.036657728254795074 -0.1571912169456482" class="collision"/>
        <geom type="box" pos="-0.04282941 0.03944181 -0.09121377" size="0.004025053698569536 0.010854005813598633 0.047436073422431946" quat="0.9460065364837646 0.011961393058300018 0.035139743238687515 -0.3220151960849762" class="collision"/>
        <geom type="box" pos="-0.02887783 0.05215760 -0.09121377" size="0.004025053698569536 0.010854005813598633 0.047436073422431946" quat="0.8752408027648926 0.01791374571621418 0.032511115074157715 -0.48226097226142883" class="collision"/>
        <geom type="box" pos="0.03789883 0.04500001 -0.09121377" size="0.004025053698569536 0.010854004882276058 0.047436073422431946" quat="0.3862343728542328 0.034235093742609024 0.014346794225275517 -0.9216535091400146" class="collision"/>
        <geom type="box" pos="0.00462902 0.06031748 -0.09121377" size="0.004025053698569536 0.010854005813598633 0.047436073422431946" quat="0.6756603717803955 0.027349231764674187 0.025097547098994255 -0.7362779378890991" class="collision"/>
        <geom type="box" pos="0.02286499 0.05544026 -0.09121377" size="0.004025053698569536 0.010854004882276058 0.047436073422431946" quat="0.5367090106010437 0.031311675906181335 0.019936243072152138 -0.8429505228996277" class="collision"/>
        <geom type="box" pos="0.04596761 -0.02196252 -0.09121377" size="0.004025053698569536 0.010854005813598633 0.047436073422431946" quat="0.2732015550136566 -0.03570559248328209 0.010148162953555584 0.9612403512001038" class="collision"/>
        <geom type="box" pos="0.04799519 0.03131748 -0.09121377" size="0.004025053698569536 0.010854005813598633 0.047436073422431946" quat="0.23645034432411194 0.03606566786766052 0.008783024735748768 -0.970934271812439" class="collision"/>
        <geom type="box" pos="0.05353733 0.01387329 -0.09121376" size="0.004025053698569536 0.010854005813598633 0.04743606969714165" quat="0.06864112615585327 0.037031952291727066 0.0025496904272586107 -0.996950626373291" class="collision"/>
        <geom type="box" pos="0.05281948 -0.00498998 -0.09121377" size="0.004025053698569536 0.010854004882276058 0.047436073422431946" quat="0.10650292783975601 -0.03690831735730171 0.003956086467951536 0.9936192631721497" class="collision"/>
        <geom type="box" pos="0.03453228 -0.03511304 -0.09121377" size="0.004025053698569536 0.010854005813598633 0.047436073422431946" quat="0.4245893955230713 -0.033602576702833176 0.01577151007950306 0.9046247601509094" class="collision"/>
        <geom type="box" pos="0.02250941 -0.04267372 -0.09121375" size="0.004025053698569536 0.010854005813598633 0.04743606597185135" quat="0.5397603511810303 -0.031239204108715057 0.0200495645403862 0.840999960899353" class="collision"/>
        <geom type="box" pos="-0.02198797 -0.04291240 -0.09121375" size="0.004025051835924387 0.010854003950953484 0.047436054795980453" quat="0.838092565536499 -0.020216846838593483 0.031131189316511154 0.5442637205123901" class="collision"/>
        <body name="power_button">
          <joint axis="0.0 1.0 0.0" pos="-0.00003876 -0.04566293 -0.06626846" limited="true" name="power_button_joint" range="0.0 0.002" type="slide" damping="1" frictionloss="1" armature=".01" stiffness="0.5" springref="-0.5"/>
          <geom mesh="power_button_vis" type="mesh" solimp="0.998 0.998 0.001" solref="0.001 1" friction="0.95 0.3 0.1" class="visual" material="power_button_material"/>
          <geom class="collision" type="box" pos="-0.00023299 -0.04643640 -0.06612332" size="0.00738384947180748 0.0018029806669801474 0.003648989135399461" quat="1.0 0.0 0.0 0.0" name="power_button_main"/>
        </body>
        <body name="pitcher">
          <!-- <joint axis="0.0 0.0 1.0" pos="-0.00008259 0.00657816 0.04125873" limited="true" name="pitcher_joint" range="0.0 0.05" type="slide" damping="1" frictionloss="1" armature=".01" stiffness="0.05"/> -->
          <geom mesh="pitcher_vis" type="mesh" solimp="0.998 0.998 0.001" solref="0.001 1" friction="0.95 0.3 0.1" class="visual" material="pitcher_material"/>
          <geom type="box" pos="0.04333248 0.00646550 0.00355366" size="0.0035044727846980095 0.012674807570874691 0.04332708194851875" quat="0.9983056783676147 2.1190591700792887e-15 -0.05818738788366318 -7.81798892290908e-09" class="collision"/>
          <geom type="box" pos="0.04132131 0.00646551 0.09231527" size="0.0035068036522716284 0.012674807570874691 0.048212192952632904" quat="0.9992659687995911 2.45362172589345e-15 0.03830776736140251 5.146997050786695e-09" class="collision"/>
          <geom type="box" pos="0.03796790 0.02735042 0.00355366" size="0.003504473017528653 0.012674807570874691 0.04332708567380905" quat="0.9669170379638672 0.014476297423243523 -0.05635787919163704 0.24836596846580505" class="collision"/>
          <geom type="box" pos="0.03620569 0.02638118 0.09231527" size="0.003506803885102272 0.012674806639552116 0.0482121966779232" quat="0.9678471684455872 -0.009530461393296719 0.03710317239165306 0.248604878783226" class="collision"/>
          <geom type="box" pos="0.02369902 0.04274494 0.00355366" size="0.003504473017528653 0.012674807570874691 0.04332708194851875" quat="0.8779835104942322 0.02769414521753788 -0.05117426812648773 0.4751411974430084" class="collision"/>
          <geom type="box" pos="0.02259900 0.04106126 0.09231527" size="0.003506803885102272 0.012674807570874691 0.0482121966779232" quat="0.8788281083106995 -0.018232425674796104 0.03369055688381195 0.47559821605682373" class="collision"/>
          <geom type="box" pos="0.00328072 0.04967685 0.00355366" size="0.003504473017528653 0.012674807570874691 0.04332708194851875" quat="0.732168972492218 0.0395549014210701 -0.04267530143260956 0.6786330938339233" class="collision"/>
          <geom type="box" pos="0.00312829 0.04767146 0.09231527" size="0.003506803885102272 0.012674807570874691 0.0482121966779232" quat="0.7328732013702393 -0.02604093588888645 0.028095250949263573 0.6792859435081482" class="collision"/>
          <geom type="box" pos="-0.01692824 0.04635987 0.00355366" size="0.003504473017528653 0.012674807570874691 0.04332708194851875" quat="0.5510849952697754 0.048518408089876175 -0.032120585441589355 0.832417905330658" class="collision"/>
          <geom type="box" pos="-0.01614279 0.04450841 0.09231527" size="0.0035068036522716284 0.012674807570874691 0.0482121966779232" quat="0.5516152381896973 -0.03194207698106766 0.02114659734070301 0.8332185745239258" class="collision"/>
          <geom type="box" pos="-0.03405942 0.03326479 0.00355366" size="0.003504473017528653 0.012674807570874691 0.04332708194851875" quat="0.3266628086566925 0.054984088987112045 -0.019039904698729515 0.9433481097221375" class="collision"/>
          <geom type="box" pos="-0.03247893 0.03202105 0.09231527" size="0.003506803885102272 0.012674807570874691 0.0482121966779232" quat="0.3269769251346588 -0.03619876131415367 0.012534912675619125 0.9442555904388428" class="collision"/>
          <geom type="box" pos="-0.04265868 0.01411681 0.00355366" size="0.003504473017528653 0.012674807570874691 0.04332708939909935" quat="0.08847763389348984 0.057958297431468964 -0.005157011561095715 0.9943771958351135" class="collision"/>
          <geom type="box" pos="-0.04067911 0.01376172 0.09231527" size="0.0035068041179329157 0.012674807570874691 0.048212192952632904" quat="0.0885627493262291 -0.038156673312187195 0.003395108273252845 0.995333731174469" class="collision"/>
          <geom type="box" pos="-0.04106578 -0.00738717 0.00355365" size="0.003504473017528653 0.012674807570874691 0.04332708194851875" quat="0.16169296205043793 -0.057419054210186005 -0.009424450807273388 -0.9851241707801819" class="collision"/>
          <geom type="box" pos="-0.03916012 -0.00674430 0.09231527" size="0.0035068041179329157 0.012674807570874691 0.0482121966779232" quat="0.1618485003709793 0.037801697850227356 0.006204571109265089 -0.9860718250274658" class="collision"/>
          <geom type="box" pos="-0.03033342 -0.02448774 0.00355365" size="0.003504473017528653 0.012674807570874691 0.04332708194851875" quat="0.3867202699184418 -0.053644176572561264 -0.022540420293807983 -0.9203595519065857" class="collision"/>
          <geom type="box" pos="-0.02892584 -0.02305124 0.09231527" size="0.0035068041179329157 0.012674807570874691 0.0482121966779232" quat="0.38709238171577454 0.03531663864850998 0.014839478768408298 -0.9212448000907898" class="collision"/>
          <geom type="box" pos="-0.01166157 -0.03527293 0.00355365" size="0.0035044727846980095 0.012674808502197266 0.04332708194851875" quat="0.6035350561141968 -0.04634973034262657 -0.035177696496248245 -0.7952104806900024" class="collision"/>
          <geom type="box" pos="-0.01112052 -0.03333590 0.09231527" size="0.0035068036522716284 0.012674807570874691 0.0482121966779232" quat="0.6041155457496643 0.03051433339715004 0.023159237578511238 -0.7959754467010498" class="collision"/>
          <geom type="box" pos="0.00932065 -0.03585550 0.00355366" size="0.003504473017528653 0.012674807570874691 0.04332708194851875" quat="0.7781533598899841 -0.0364505834877491 -0.04535554721951485 -0.6253731846809387" class="collision"/>
          <geom type="box" pos="0.00888793 -0.03389143 0.09231527" size="0.0035068041179329157 0.012674807570874691 0.0482121966779232" quat="0.7789018750190735 0.023997221142053604 0.029859796166419983 -0.6259747743606567" class="collision"/>
          <geom type="box" pos="0.02856218 -0.02612298 0.00355365" size="0.0035044727846980095 0.012674806639552116 0.04332708194851875" quat="0.9092717170715332 -0.024020615965127945 -0.052997905761003494 -0.41211551427841187" class="collision"/>
          <geom type="box" pos="0.02723648 -0.02461058 0.09231527" size="0.003506803885102272 0.012674806639552116 0.0482121966779232" quat="0.9101463556289673 0.01581396348774433 0.03489115461707115 -0.41251200437545776" class="collision"/>
          <geom type="box" pos="0.03958975 -0.01115216 0.00355366" size="0.003504473017528653 0.012674807570874691 0.04332708194851875" quat="0.9765130281448364 -0.012091603130102158 -0.05691717192530632 -0.20745247602462769" class="collision"/>
          <geom type="box" pos="0.03775227 -0.01033453 0.09231527" size="0.0035068041179329157 0.012674807570874691 0.0482121966779232" quat="0.9774523973464966 0.007960498332977295 0.03747131675481796 -0.2076520472764969" class="collision"/>
          <body name="blade">
            <joint axis="0.0 0.0 1.0" pos="-0.00000250 0.00644435 -0.03668665" limited="false" name="blade_joint" range="0 360" type="hinge" damping="1" frictionloss="1" armature=".01" stiffness="0.05"/>
            <geom mesh="blade_vis" type="mesh" solimp="0.998 0.998 0.001" solref="0.001 1" friction="0.95 0.3 0.1" class="visual" material="blade_material"/>
            <geom type="cylinder" pos="-0.00000350 0.00646550 -0.03204990" size="0.031703922897577286 0.011009951122105122" quat="1.0 0.0 0.0 0.0" class="collision"/>
          </body>
          <body name="pitcher_main">
            <geom class="region" type="cylinder" size="0.03383820876479149 0.07321330904960632" pos="-0.00013724 0.00655650 0.05660385" rgba="0 0 1 0.5" name="reg_int"/>
            <geom mesh="pitcher_main_vis" type="mesh" solimp="0.998 0.998 0.001" solref="0.001 1" friction="0.95 0.3 0.1" class="visual" material="pitcher_main_material"/>
            <geom type="cylinder" pos="-0.00000350 0.00646550 -0.05209770" size="0.044104933738708496 0.004458223003894091" quat="1.0 0.0 0.0 0.0" class="collision"/>
          </body>
        </body>
        <body name="knob_speed">
          <joint axis="0.0 1.0 0.0" pos="-0.00001943 -0.05512573 -0.08862664" limited="true" name="knob_speed_joint" range="0.0 4.71238898038469" type="hinge" damping="0.05" frictionloss="0.1" armature="0.001"/>
          <geom mesh="knob_speed_vis" type="mesh" solimp="0.998 0.998 0.001" solref="0.001 1" friction="0.95 0.3 0.1" class="visual" material="knob_speed_material"/>
          <geom type="cylinder" pos="-0.00005389 -0.04848021 -0.08866108" size="0.010512183420360088 0.0038811657577753067" quat="0.7071067094802856 0.7071068286895752 0.0 0.0" class="collision" density="0.001"/>
          <geom class="collision" type="box" pos="-0.00020290 -0.05809158 -0.08858658" size="0.003975735977292061 0.006238631904125214 0.010526491329073906" quat="0.9099612236022949 0.0 0.41469329595565796 0.0" name="knob_speed_main" density="0.001"/>
        </body>
        <geom class="region" name="reg_main" type="box" pos="2.1500000000132524e-07 0.005763934999999998 2.500000000071889e-08" size="0.058867235000000004 0.059565095 0.16028904500000002"/>
      </body>
      <site rgba="0 1 0 0" size="0.005" pos="-1.09494422e-04 6.57808673e-03 1.41758517e-01" name="anchor_site"/>
    </body>
  </worldbody>
  <actuator>
    <motor name="knob_speed_joint_actuator" joint="knob_speed_joint" gear="10"/>
    <!-- <motor name="pitcher_joint_actuator" joint="pitcher_joint" gear="10"/> -->
    <motor name="power_button_joint_actuator" joint="power_button_joint" gear="0.5"/>
    <motor name="blade_joint_actuator" joint="blade_joint" gear="10"/>
    <!-- <motor name="lid_joint_actuator" joint="lid_joint" gear="0.5"/> -->
  </actuator>
</mujoco>
