<?xml version='1.0' encoding='UTF-8'?>
<mujoco model="model">
  <option timestep="0.002" gravity="0.0 0.0 -9.81"/>
  <compiler angle="radian"/>
  <asset>
    <mesh file="visuals/Blade001.obj" name="Blade001_vis"/>
    <mesh file="visuals/Body001.obj" name="Body001_vis"/>
    <mesh file="visuals/Button001.obj" name="Button001_vis"/>
    <mesh file="visuals/Handle001.obj" name="Handle001_vis"/>
    <mesh file="visuals/Jug001.obj" name="Jug001_vis"/>
    <mesh file="visuals/Jug001_Clear.obj" name="Jug001_Clear_vis"/>
    <mesh file="visuals/Knob001.obj" name="Knob001_vis"/>
    <mesh file="visuals/Lid001.obj" name="Lid001_vis"/>
    <texture file="visuals/T_BC001.png" name="Body001_material" type="2d"/>
    <material name="Body001_material" rgba="1 1 1 1.0" texture="Body001_material" shininess="0.1472135901451111" specular="1.5"/>
    <texture file="visuals/T_BC001.png" name="Button001_material" type="2d"/>
    <material name="Button001_material" rgba="1 1 1 1.0" texture="Button001_material" shininess="0.4472135901451111" specular="0.3103448502657381"/>
    <texture file="visuals/T_BC001.png" name="Jug001_Clear_material" type="2d"/>
    <material name="Jug001_Clear_material" rgba="1 1 1 0.699999988079071" texture="Jug001_Clear_material" shininess="0.5" specular="0.3103448502657381"/>
    <texture file="visuals/T_BC001.png" name="Blade001_material" type="2d"/>
    <material name="Blade001_material" rgba="1 1 1 1.0" texture="Blade001_material" shininess="0.4472135901451111" specular="1"/>
    <texture file="visuals/T_BC001.png" name="Handle001_material" type="2d"/>
    <material name="Handle001_material" rgba="1 1 1 1.0" texture="Handle001_material" shininess="0.4472135901451111" specular="0.3103448502657381"/>
    <texture file="visuals/T_BC001.png" name="Jug001_material" type="2d"/>
    <material name="Jug001_material" rgba="1 1 1 1.0" texture="Jug001_material" shininess="0.4472135901451111" specular="0.3103448502657381"/>
    <texture file="visuals/T_BC001.png" name="Lid001_material" type="2d"/>
    <material name="Lid001_material" rgba="1 1 1 1.0" texture="Lid001_material" shininess="0.4472135901451111" specular="0.3103448502657381"/>
    <texture file="visuals/T_BC001.png" name="Knob001_material" type="2d"/>
    <material name="Knob001_material" rgba="1 1 1 1.0" texture="Knob001_material" shininess="0.4472135901451111" specular="0.3103448502657381"/>
  </asset>
  <default>
    <default class="visual">
      <geom conaffinity="0" contype="0" group="1" type="mesh"/>
    </default>
    <default class="collision">
      <geom group="0" rgba="0.5 0 0 0.5"/>
    </default>
    <default class="spawn">
      <geom group="0" rgba="1 1 1 0.5" contype="0" conaffinity="0"/>
      <site group="0" rgba="1 1 1 0.5"/>
    </default>
    <default class="region">
      <geom group="1" conaffinity="0" contype="0" rgba="0 1 0 0"/>
    </default>
  </default>
  <worldbody>
    <body>
      <body name="object">
        <geom mesh="Body001_vis" type="mesh" solimp="0.998 0.998 0.001" solref="0.001 1" friction="0.95 0.3 0.1" class="visual" material="Body001_material"/>
        <geom class="collision" type="cylinder" pos="-0.01364894 0.00517901 -0.17729765" size="0.07223193347454071 0.01565600000321865" quat="1.0 0.0 0.0 0.0"/>
        <geom class="collision" type="cylinder" pos="-0.01364892 0.00517901 -0.10186557" size="0.059829890727996826 0.0677737444639206" quat="1.0 0.0 0.0 0.0"/>
        <geom class="collision" type="box" pos="-0.07513081 0.01196584 -0.09163070" size="0.00474097765982151 0.018581919372081757 0.07518734037876129" quat="0.9983850717544556 0.001589016173966229 0.03639443591237068 -0.04359044134616852"/>
        <geom class="collision" type="box" pos="-0.04137623 0.06109778 -0.09163070" size="0.00474097765982151 0.018581921234726906 0.07518734037876129" quat="0.8520742058753967 0.01903415098786354 0.03106090985238552 -0.52215176820755"/>
        <geom class="collision" type="box" pos="-0.01340979 0.06755958 -0.09163070" size="0.004740977194160223 0.018581919372081757 0.07518734037876129" quat="0.706637442111969 0.025759262964129448 0.025759262964129448 -0.706637442111969"/>
        <geom class="collision" type="box" pos="-0.06460671 0.04089657 -0.09163070" size="0.004740977194160223 0.018581919372081757 0.07518734037876129" quat="0.9556699991226196 0.01065084058791399 0.03483732417225838 -0.29217764735221863"/>
        <geom class="collision" type="box" pos="-0.07030949 -0.01843974 -0.09163070" size="0.004740977194160223 0.018581919372081757 0.07518734037876129" quat="0.9774983525276184 -0.007574035320430994 0.03563303127884865 0.20777370035648346"/>
        <geom class="collision" type="box" pos="-0.05777650 -0.03701354 -0.09163070" size="0.004740977194160223 0.018581919372081757 0.07518734037876129" quat="0.9232662916183472 -0.013940813019871712 0.03365609422326088 0.38242942094802856"/>
        <geom class="collision" type="box" pos="0.01444209 0.06062059 -0.09163070" size="0.00474097765982151 0.018581919372081757 0.07518734037876129" quat="0.5221518278121948 0.031060902401804924 0.019034147262573242 -0.8520742058753967"/>
        <geom class="collision" type="box" pos="0.03483135 0.04351816 -0.09163070" size="0.004740977194160223 0.018581919372081757 0.07518734037876129" quat="0.32535216212272644 0.03444439172744751 0.011860158294439316 -0.9448909163475037"/>
        <geom class="collision" type="box" pos="0.04669719 0.01624186 -0.09163070" size="0.004740977194160223 0.018581919372081757 0.07518734037876129" quat="0.08709795027971268 0.03629047051072121 0.0031750064808875322 -0.9955334663391113"/>
        <geom class="collision" type="box" pos="0.04401952 -0.01442692 -0.09163070" size="0.004740977194160223 0.018581919372081757 0.07518734037876129" quat="0.16493791341781616 -0.03592948243021965 0.006012528203427792 0.985630989074707"/>
        <geom class="collision" type="box" pos="0.02992116 -0.03699794 -0.09163070" size="0.004740977194160223 0.018581919372081757 0.07518734037876129" quat="0.3743578791618347 -0.03377646952867508 0.01364657748490572 0.9265684485435486"/>
        <geom class="collision" type="box" pos="0.00436888 -0.05326415 -0.10183717" size="0.004860866814851761 0.018987733870744705 0.0649624690413475" quat="0.5873950719833374 -0.029471756890416145 0.021412484347820282 0.8084800243377686"/>
        <geom class="collision" type="box" pos="-0.03054678 -0.05387982 -0.10183717" size="0.004740977194160223 0.018581919372081757 0.06495371460914612" quat="0.7928267121315002 -0.022176628932356834 0.02890114299952984 0.6083573698997498"/>
        <geom class="collision" type="box" pos="0.01075822 -0.04574376 -0.03591481" size="0.00474097765982151 0.018581917509436607 0.016848616302013397" quat="0.5295674204826355 -0.030893627554178238 0.01930447481572628 0.8474852442741394"/>
        <geom class="collision" type="box" pos="-0.03857974 -0.04552223 -0.03288599" size="0.004740977194160223 0.018581919372081757 0.014263604767620564" quat="0.8428314924240112 -0.01957334391772747 0.03072398342192173 0.5369431972503662"/>
        <body name="Button001">
          <joint axis="0.0 1.0 0.0" pos="-0.01376783 -0.05584328 -0.02839275" limited="true" name="Button001_joint" range="0.0 0.0013" type="slide" damping="1" frictionloss="1" armature=".01" stiffness="0.05"/>
          <geom mesh="Button001_vis" type="mesh" solimp="0.998 0.998 0.001" solref="0.001 1" friction="0.95 0.3 0.1" class="visual" material="Button001_material"/>
          <geom class="collision" type="cylinder" pos="-0.01373722 -0.05575219 -0.02841941" size="0.004705463536083698 0.0024300196673721075" quat="0.7071068286895752 -0.7071067690849304 -0.0 0.0"/>
        </body>
        <body name="Jug001_Clear">
          <geom class="region" name="reg_int" type="box" pos="-0.013648935000000001 0.005179005 0.066261555" size="0.026692025 0.026692025 0.081107445"/>
          <!-- <joint axis="0.0 0.0 1.0" pos="0.00000001 0.00428046 0.07791832" limited="true" name="Jug001_Clear_joint" range="0.0 0.05" type="slide" damping="1" frictionloss="1" armature=".01" stiffness="0.05"/> -->
          <geom mesh="Jug001_Clear_vis" type="mesh" solimp="0.998 0.998 0.001" solref="0.001 1" friction="0.95 0.3 0.1" class="visual" material="Jug001_Clear_material"/>
          <geom class="collision" type="box" pos="-0.01340979 -0.05356316 0.07928143" size="0.004740975797176361 0.018581919372081757 0.09355513006448746" quat="0.7044395804405212 0.0613589882850647 0.0613589882850647 -0.7044395208358765"/>
          <geom class="collision" type="box" pos="-0.01340978 0.06392115 0.07928143" size="0.004740975797176361 0.018581919372081757 0.09355513006448746" quat="0.7044395804405212 -0.0613589882850647 0.0613589882850647 0.7044395208358765"/>
          <geom class="collision" type="box" pos="-0.01340978 0.06392115 0.07928143" size="0.004740975797176361 0.018581919372081757 0.09355513006448746" quat="0.7044395804405212 -0.0613589882850647 0.0613589882850647 0.7044395208358765"/>
          <geom class="collision" type="box" pos="-0.01340979 -0.05356316 0.07928143" size="0.004740975797176361 0.018581919372081757 0.09355513006448746" quat="0.7044395804405212 0.0613589882850647 0.0613589882850647 -0.7044395208358765"/>
          <geom class="collision" type="box" pos="-0.07215194 0.00517899 0.07928143" size="0.004740975797176361 0.018581919372081757 0.09355513751506805" quat="7.475989605154609e-08 0.08677461743354797 1.3479709570773935e-09 -0.9962279796600342"/>
          <geom class="collision" type="box" pos="0.04533237 0.00517900 0.07928143" size="0.004740975797176361 0.018581919372081757 0.09355513006448746" quat="0.9962279796600342 -5.203319997093558e-09 0.08677471429109573 4.5322723352114735e-10"/>
          <geom class="collision" type="box" pos="0.03746241 0.03455008 0.07928143" size="0.004740975797176361 0.018581919372081757 0.09355513006448746" quat="0.9622822999954224 -0.02245895378291607 0.08381793648004532 0.2578427791595459"/>
          <geom class="collision" type="box" pos="-0.06428199 -0.02419209 0.07928143" size="0.004740975797176361 0.018581919372081757 0.09355513751506805" quat="0.2578427791595459 0.08381803333759308 0.02245897427201271 -0.9622822999954224"/>
          <geom class="collision" type="box" pos="-0.04278086 -0.04569321 0.07928143" size="0.004740975797176361 0.018581919372081757 0.09355513751506805" quat="0.49811404943466187 0.07514900714159012 0.043387334793806076 -0.8627586960792542"/>
          <geom class="collision" type="box" pos="0.01596129 0.05605120 0.07928143" size="0.004740975797176361 0.018581919372081757 0.09355513751506805" quat="0.8627587556838989 -0.04338733106851578 0.07514902949333191 0.4981139600276947"/>
          <geom class="collision" type="box" pos="-0.04278086 0.05605120 0.07928143" size="0.004740975797176361 0.018581919372081757 0.09355513751506805" quat="0.49811404943466187 -0.07514900714159012 0.043387334793806076 0.8627586960792542"/>
          <geom class="collision" type="box" pos="0.01596129 -0.04569320 0.07928143" size="0.004740975797176361 0.018581919372081757 0.09355513006448746" quat="0.8627587556838989 0.04338734969496727 0.07514909654855728 -0.4981139302253723"/>
          <geom class="collision" type="box" pos="0.03746241 -0.02419208 0.07928143" size="0.004740975797176361 0.018581919372081757 0.09355513006448746" quat="0.9622823596000671 0.022458944469690323 0.08381792157888412 -0.25784268975257874"/>
          <geom class="collision" type="box" pos="-0.06428199 0.03455007 0.07928143" size="0.004740975797176361 0.018581919372081757 0.09355513751506805" quat="0.2578427791595459 -0.08381803333759308 0.02245897427201271 0.9622822999954224"/>
          <geom class="collision" type="box" pos="0.08060288 0.00442261 0.13820456" size="0.011232865042984486 0.012886925600469112 0.010835387744009495" quat="0.9739777445793152 0.0 0.2266436368227005 0.0"/>
          <geom class="collision" type="box" pos="0.08998093 0.00442261 0.12905489" size="0.008133475668728352 0.012886925600469112 0.009914564900100231" quat="0.8326515555381775 0.0 0.5537972450256348 0.0"/>
          <geom class="collision" type="box" pos="0.09003628 0.00442261 0.08520831" size="0.04113192483782768 0.012886925600469112 0.00918785110116005" quat="0.6727584004402161 3.2991174236940424e-09 0.7398622632026672 -2.8109128358266844e-09"/>
          <geom class="collision" type="box" pos="0.08013169 0.00442261 0.03771976" size="0.012385156936943531 0.012886925600469112 0.00875075999647379" quat="0.4286668002605438 0.0 0.9034626483917236 0.0"/>
          <geom class="collision" type="box" pos="0.06025315 0.00442261 0.02319772" size="0.015387085266411304 0.012886925600469112 0.009129141457378864" quat="0.2087034434080124 0.0 0.9779789447784424 0.0"/>
          <body name="Blade001">
            <joint axis="0.0 0.0 1.0" pos="-0.01393533 0.00608437 -0.02500419" limited="false" name="Blade001_joint" range="0 360" type="hinge" damping="1" frictionloss="1" armature=".01" stiffness="0.05"/>
            <geom mesh="Blade001_vis" type="mesh" solimp="0.998 0.998 0.001" solref="0.001 1" friction="0.95 0.3 0.1" class="visual" material="Blade001_material"/>
            <geom class="collision" type="cylinder" pos="-0.01364893 0.00517901 -0.02543145" size="0.003170922864228487 0.004099421203136444" quat="1.0 0.0 0.0 0.0"/>
            <geom class="collision" type="box" pos="-0.01410603 0.00418800 -0.02250797" size="0.014141938649117947 0.00791434571146965 0.0002459282986819744" quat="0.9841994047164917 0.0 0.0 0.17706358432769775"/>
            <geom class="collision" type="box" pos="0.00506045 0.01131501 -0.01903470" size="0.009196617640554905 0.0075520845130085945 0.00036561701563186944" quat="0.956265926361084 0.06398852914571762 -0.22334979474544525 0.17769597470760345"/>
            <geom class="collision" type="box" pos="-0.03441685 -0.00336454 -0.02532603" size="0.008302983827888966 0.007914342917501926 0.00034735887311398983" quat="0.9655296802520752 0.029465211555361748 -0.1717633605003357 0.19334332644939423"/>
            <geom class="collision" type="box" pos="-0.01410603 0.00418800 -0.02371466" size="0.014141938649117947 0.007914344780147076 0.0002824610273819417" quat="0.8216372132301331 0.0 -0.0 -0.570010781288147"/>
            <geom class="collision" type="box" pos="-0.00667013 -0.01570229 -0.01987419" size="0.008311481215059757 0.00791434571146965 0.0002459282986819744" quat="0.7972676753997803 -0.1377963125705719 -0.1986253559589386 -0.5531043410301208"/>
            <geom class="collision" type="box" pos="-0.02175518 0.02464871 -0.02674755" size="0.008314153179526329 0.007914344780147076 0.0002459282986819744" quat="0.8104860782623291 -0.09359202533960342 -0.13490740954875946 -0.5622747540473938"/>
          </body>
          <body name="Handle001">
            <geom mesh="Handle001_vis" type="mesh" solimp="0.998 0.998 0.001" solref="0.001 1" friction="0.95 0.3 0.1" class="visual" material="Handle001_material"/>
            <geom class="collision" type="box" pos="0.05502011 0.00517900 0.07935458" size="0.006446782033890486 0.027016857638955116 0.094341941177845" quat="0.9966984391212463 0.0 0.08119235932826996 0.0"/>
          </body>
          <body name="Jug001">
            <geom mesh="Jug001_vis" type="mesh" solimp="0.998 0.998 0.001" solref="0.001 1" friction="0.95 0.3 0.1" class="visual" material="Jug001_material"/>
            <geom class="collision" type="box" pos="-0.01340979 -0.05356316 0.07928143" size="0.004740975797176361 0.018581919372081757 0.09355513006448746" quat="0.7044395804405212 0.0613589882850647 0.0613589882850647 -0.7044395208358765"/>
            <geom class="collision" type="box" pos="-0.01340978 0.06392115 0.07928143" size="0.004740975797176361 0.018581919372081757 0.09355513006448746" quat="0.7044395804405212 -0.0613589882850647 0.0613589882850647 0.7044395208358765"/>
            <geom class="collision" type="box" pos="-0.01340978 0.06392115 0.07928143" size="0.004740975797176361 0.018581919372081757 0.09355513006448746" quat="0.7044395804405212 -0.0613589882850647 0.0613589882850647 0.7044395208358765"/>
            <geom class="collision" type="box" pos="-0.01340979 -0.05356316 0.07928143" size="0.004740975797176361 0.018581919372081757 0.09355513006448746" quat="0.7044395804405212 0.0613589882850647 0.0613589882850647 -0.7044395208358765"/>
            <geom class="collision" type="box" pos="-0.07215194 0.00517899 0.07928143" size="0.004740975797176361 0.018581919372081757 0.09355513751506805" quat="7.475989605154609e-08 0.08677461743354797 1.3479709570773935e-09 -0.9962279796600342"/>
            <geom class="collision" type="box" pos="0.04533237 0.00517900 0.07928143" size="0.004740975797176361 0.018581919372081757 0.09355513006448746" quat="0.9962279796600342 -5.203319997093558e-09 0.08677471429109573 4.5322723352114735e-10"/>
            <geom class="collision" type="box" pos="0.03746241 0.03455008 0.07928143" size="0.004740975797176361 0.018581919372081757 0.09355513006448746" quat="0.9622822999954224 -0.02245895378291607 0.08381793648004532 0.2578427791595459"/>
            <geom class="collision" type="box" pos="-0.06428199 -0.02419209 0.07928143" size="0.004740975797176361 0.018581919372081757 0.09355513751506805" quat="0.2578427791595459 0.08381803333759308 0.02245897427201271 -0.9622822999954224"/>
            <geom class="collision" type="box" pos="-0.04278086 -0.04569321 0.07928143" size="0.004740975797176361 0.018581919372081757 0.09355513751506805" quat="0.49811404943466187 0.07514900714159012 0.043387334793806076 -0.8627586960792542"/>
            <geom class="collision" type="box" pos="0.01596129 0.05605120 0.07928143" size="0.004740975797176361 0.018581919372081757 0.09355513751506805" quat="0.8627587556838989 -0.04338733106851578 0.07514902949333191 0.4981139600276947"/>
            <geom class="collision" type="box" pos="-0.04278086 0.05605120 0.07928143" size="0.004740975797176361 0.018581919372081757 0.09355513751506805" quat="0.49811404943466187 -0.07514900714159012 0.043387334793806076 0.8627586960792542"/>
            <geom class="collision" type="box" pos="0.01596129 -0.04569320 0.07928143" size="0.004740975797176361 0.018581919372081757 0.09355513006448746" quat="0.8627587556838989 0.04338734969496727 0.07514909654855728 -0.4981139302253723"/>
            <geom class="collision" type="box" pos="0.03746241 -0.02419208 0.07928143" size="0.004740975797176361 0.018581919372081757 0.09355513006448746" quat="0.9622823596000671 0.022458944469690323 0.08381792157888412 -0.25784268975257874"/>
            <geom class="collision" type="box" pos="-0.06428199 0.03455007 0.07928143" size="0.004740975797176361 0.018581919372081757 0.09355513751506805" quat="0.2578427791595459 -0.08381803333759308 0.02245897427201271 0.9622822999954224"/>
            <geom class="collision" type="box" pos="0.08060288 0.00442261 0.13820456" size="0.011232865042984486 0.012886925600469112 0.010835387744009495" quat="0.9739777445793152 0.0 0.2266436368227005 0.0"/>
            <geom class="collision" type="box" pos="0.08998093 0.00442261 0.12905489" size="0.008133475668728352 0.012886925600469112 0.009914564900100231" quat="0.8326515555381775 0.0 0.5537972450256348 0.0"/>
            <geom class="collision" type="box" pos="0.09003628 0.00442261 0.08520831" size="0.04113192483782768 0.012886925600469112 0.00918785110116005" quat="0.6727584004402161 3.2991174236940424e-09 0.7398622632026672 -2.8109128358266844e-09"/>
            <geom class="collision" type="box" pos="0.08013169 0.00442261 0.03771976" size="0.012385156936943531 0.012886925600469112 0.00875075999647379" quat="0.4286668002605438 0.0 0.9034626483917236 0.0"/>
            <geom class="collision" type="box" pos="0.06025315 0.00442261 0.02319772" size="0.015387085266411304 0.012886925600469112 0.009129141457378864" quat="0.2087034434080124 0.0 0.9779789447784424 0.0"/>
            <geom class="collision" type="cylinder" pos="-0.01364892 0.00517901 -0.03183776" size="0.03966093435883522 0.0012146634981036186" quat="1.0 0.0 0.0 0.0"/>
          </body>
        </body>
        <body name="Knob001">
          <joint axis="0.0 1.0 0.0" pos="-0.01317398 -0.07470910 -0.09942290" limited="true" name="Knob001_joint" range="0.0 4.799655442984406" type="hinge" damping="0.05" armature="0.001"/>
          <geom mesh="Knob001_vis" type="mesh" solimp="0.998 0.998 0.001" solref="0.001 1" friction="0.95 0.3 0.1" class="visual" material="Knob001_material"/>
          <geom class="collision" type="cylinder" pos="-0.01364893 -0.07254580 -0.09890006" size="0.025688841938972473 0.005045394878834486" quat="0.7071068286895752 -0.7071067690849304 -0.0 0.0"/>
          <geom class="collision" type="box" pos="-0.01317081 -0.08396378 -0.09950612" size="0.010556374676525593 0.007968936115503311 0.023776941001415253" quat="0.3608556091785431 -4.1255592719835477e-08 -0.9326217174530029 -7.759047093713889e-08"/>
        </body>
        <geom class="region" name="reg_main" type="box" pos="-0.011913235000000001 0.004331044999999999 0.0" size="0.09066411499999999 0.085063515 0.19429822"/>
      </body>
      <site rgba="0 1 0 0" size="0.005" pos="-0.01137218 0.00440853 0.16801763" name="anchor_site"/>
    </body>
  </worldbody>
  <actuator>
    <motor name="Button001_joint_actuator" joint="Button001_joint" gear="0.5"/>
    <!-- <motor name="Jug001_Clear_joint_actuator" joint="Jug001_Clear_joint" gear="70"/> -->
    <motor name="Knob001_joint_actuator" joint="Knob001_joint" gear="10"/>
    <motor name="Blade001_joint_actuator" joint="Blade001_joint" gear="20"/>
    <!-- <motor name="Lid001_joint_actuator" joint="Lid001_joint" gear="20"/> -->
  </actuator>
</mujoco>
