<?xml version='1.0' encoding='UTF-8'?>
<mujoco model="model">
  <option timestep="0.002" gravity="0.0 0.0 -9.81"/>
  <compiler angle="radian"/>
  <asset>
    <mesh file="visuals/blade.obj" name="blade_vis"/>
    <mesh file="visuals/Body001.obj" name="Body001_vis"/>
    <mesh file="visuals/knob_speed.obj" name="knob_speed_vis"/>
    <mesh file="visuals/pitcher.obj" name="pitcher_vis"/>
    <mesh file="visuals/pitcher_main.obj" name="pitcher_main_vis"/>
    <mesh file="visuals/power_button.obj" name="power_button_vis"/>
    <texture file="visuals/T_BC001.png" name="Body001_material" type="2d"/>
    <material name="Body001_material" rgba="1 1 1 1.0" texture="Body001_material" shininess="0.4472135901451111" specular="0.3103448502657381"/>
    <texture file="visuals/T_BC001.png" name="knob_speed_material" type="2d"/>
    <material name="knob_speed_material" rgba="1 1 1 1.0" texture="knob_speed_material" shininess="0.4472135901451111" specular="0.3103448502657381"/>
    <material name="pitcher_material" rgba="0.5 0.5 0.5 0.699999988079071" shininess="0.5" specular="0.3103448502657381"/>
    <texture file="visuals/T_BC001.png" name="blade_material" type="2d"/>
    <material name="blade_material" rgba="1 1 1 1.0" texture="blade_material" shininess="0.4472135901451111" specular="0.3103448502657381"/>
    <texture file="visuals/T_BC001.png" name="pitcher_main_material" type="2d"/>
    <material name="pitcher_main_material" rgba="1 1 1 1.0" texture="pitcher_main_material" shininess="0.4472135901451111" specular="0.3103448502657381"/>
    <texture file="visuals/T_BC001.png" name="power_button_material" type="2d"/>
    <material name="power_button_material" rgba="1 1 1 1.0" texture="power_button_material" shininess="0.4472135901451111" specular="0.3103448502657381"/>
  </asset>
  <default>
    <default class="visual">
      <geom conaffinity="0" contype="0" group="1" type="mesh"/>
    </default>
    <default class="collision">
      <geom group="0" rgba="0.5 0 0 0.5" density="1.0" solref="0.004 1" solimp="0.998 0.998 0.001"/>
    </default>
    <default class="spawn">
      <geom group="0" rgba="1 1 1 0.5" contype="0" conaffinity="0"/>
      <site group="0" rgba="1 1 1 0.5"/>
    </default>
    <default class="region">
      <geom group="1" conaffinity="0" contype="0" rgba="0 1 0 0" mass="0"/>
    </default>
  </default>
  <worldbody>
    <body>
      <body name="object">
        <geom mesh="Body001_vis" type="mesh" solimp="0.998 0.998 0.001" solref="0.001 1" friction="0.95 0.3 0.1" class="visual" material="Body001_material"/>
        <geom type="cylinder" pos="-0.01364894 0.00517901 -0.17729765" size="0.07223193347454071 0.01565600000321865" quat="1.0 0.0 0.0 0.0" class="collision"/>
        <geom type="cylinder" pos="-0.01364892 0.00517901 -0.10186557" size="0.059829890727996826 0.0677737444639206" quat="1.0 0.0 0.0 0.0" class="collision"/>
        <geom type="box" pos="-0.07513081 0.01196584 -0.09163070" size="0.004740977194160223 0.018581919372081757 0.07518734037876129" quat="0.9983850717544556 0.0015890260692685843 0.03639451414346695 -0.043590571731328964" class="collision"/>
        <geom type="box" pos="-0.04137623 0.06109778 -0.09163070" size="0.00474097765982151 0.018581921234726906 0.07518734037876129" quat="0.8520742058753967 0.01903415098786354 0.03106090985238552 -0.52215176820755" class="collision"/>
        <geom type="box" pos="-0.01340979 0.06755958 -0.09163070" size="0.004740977194160223 0.018581919372081757 0.07518734037876129" quat="0.706637442111969 0.025759262964129448 0.025759262964129448 -0.706637442111969" class="collision"/>
        <geom type="box" pos="-0.06460671 0.04089657 -0.09163070" size="0.004740977194160223 0.018581919372081757 0.07518734037876129" quat="0.9556699991226196 0.01065084058791399 0.03483732417225838 -0.29217764735221863" class="collision"/>
        <geom type="box" pos="-0.07030949 -0.01843974 -0.09163070" size="0.004740977194160223 0.018581919372081757 0.07518734037876129" quat="0.9774983525276184 -0.007574041374027729 0.03563303127884865 0.20777371525764465" class="collision"/>
        <geom type="box" pos="-0.05777650 -0.03701354 -0.09163070" size="0.004740977194160223 0.018581919372081757 0.07518734037876129" quat="0.9232662916183472 -0.013940813951194286 0.03365609422326088 0.38242942094802856" class="collision"/>
        <geom type="box" pos="0.01444209 0.06062059 -0.09163070" size="0.00474097765982151 0.018581919372081757 0.07518734037876129" quat="0.5221518278121948 0.031060900539159775 0.019034145399928093 -0.8520742058753967" class="collision"/>
        <geom type="box" pos="0.03483135 0.04351816 -0.09163070" size="0.004740977194160223 0.018581919372081757 0.07518734037876129" quat="0.32535216212272644 0.03444444015622139 0.011860170401632786 -0.9448909163475037" class="collision"/>
        <geom type="box" pos="0.04669719 0.01624186 -0.09163070" size="0.004740977194160223 0.018581919372081757 0.07518734037876129" quat="0.08709795027971268 0.03629047051072121 0.0031750064808875322 -0.9955334663391113" class="collision"/>
        <geom type="box" pos="0.04401952 -0.01442692 -0.09163070" size="0.00474097765982151 0.018581919372081757 0.07518734037876129" quat="0.16493791341781616 -0.03592943400144577 0.00601251982152462 0.985630989074707" class="collision"/>
        <geom type="box" pos="0.02992116 -0.03699794 -0.09163070" size="0.004740977194160223 0.018581919372081757 0.07518734037876129" quat="0.3743578791618347 -0.03377646952867508 0.01364657748490572 0.9265684485435486" class="collision"/>
        <geom type="box" pos="0.00436888 -0.05326415 -0.10183717" size="0.004860866814851761 0.018987733870744705 0.0649624690413475" quat="0.5873950719833374 -0.029471756890416145 0.021412484347820282 0.8084800243377686" class="collision"/>
        <geom type="box" pos="-0.03054678 -0.05387982 -0.10183717" size="0.004740977194160223 0.018581919372081757 0.06495371460914612" quat="0.792826771736145 -0.02217664010822773 0.028901150450110435 0.6083573698997498" class="collision"/>
        <geom type="box" pos="0.01075822 -0.04574376 -0.03591481" size="0.00474097765982151 0.018581917509436607 0.016848616302013397" quat="0.5295674204826355 -0.030893627554178238 0.01930447481572628 0.8474852442741394" class="collision"/>
        <geom type="box" pos="-0.03857974 -0.04552223 -0.03288599" size="0.004740977194160223 0.018581919372081757 0.014263604767620564" quat="0.8428314924240112 -0.01957334391772747 0.03072398342192173 0.5369431972503662" class="collision"/>
        <body name="power_button">
          <joint axis="0.0 1.0 0.0" pos="-0.01376783 -0.05584328 -0.02839275" limited="true" name="power_button_joint" range="0.0 0.002" type="slide" damping="1" frictionloss="1" armature=".01" stiffness="0.5" springref="-0.5"/>
          <geom mesh="power_button_vis" type="mesh" solimp="0.998 0.998 0.001" solref="0.001 1" friction="0.95 0.3 0.1" class="visual" material="power_button_material"/>
          <geom class="collision" type="box" pos="-0.01373722 -0.05575219 -0.02841941" size="0.004705454688519239 0.0024300110526382923 0.004778042435646057" quat="1.0 0.0 0.0 0.0" name="power_button_main"/>
        </body>
        <body name="pitcher">
          <!-- <joint axis="0.0 0.0 1.0" pos="0.00000001 0.00428046 0.07791832" limited="true" name="pitcher_joint" range="0.0 0.05" type="slide" damping="1" frictionloss="1" armature=".01" stiffness="0.05"/> -->
          <geom mesh="pitcher_vis" type="mesh" solimp="0.998 0.998 0.001" solref="0.001 1" friction="0.95 0.3 0.1" class="visual" material="pitcher_material"/>
          <geom type="box" pos="-0.01340979 -0.05356316 0.07928143" size="0.004740975797176361 0.018581919372081757 0.09355513006448746" quat="0.7044395804405212 0.0613589882850647 0.0613589882850647 -0.7044395208358765" class="collision"/>
          <geom type="box" pos="-0.01340978 0.06392115 0.07928143" size="0.004740975797176361 0.018581919372081757 0.09355513006448746" quat="0.7044395804405212 -0.0613589882850647 0.0613589882850647 0.7044395208358765" class="collision"/>
          <geom type="box" pos="-0.01340978 0.06392115 0.07928143" size="0.004740975797176361 0.018581919372081757 0.09355513006448746" quat="0.7044395804405212 -0.0613589882850647 0.0613589882850647 0.7044395208358765" class="collision"/>
          <geom type="box" pos="-0.01340979 -0.05356316 0.07928143" size="0.004740975797176361 0.018581919372081757 0.09355513006448746" quat="0.7044395804405212 0.0613589882850647 0.0613589882850647 -0.7044395208358765" class="collision"/>
          <geom type="box" pos="-0.07215194 0.00517899 0.07928143" size="0.004740975797176361 0.018581919372081757 0.09355513751506805" quat="7.475988894611874e-08 0.08677461743354797 1.3479705129881836e-09 -0.9962279796600342" class="collision"/>
          <geom type="box" pos="0.04533237 0.00517900 0.07928143" size="0.004740975797176361 0.018581919372081757 0.09355513006448746" quat="0.9962279796600342 -5.203322217539608e-09 0.08677471429109573 4.5322756658805474e-10" class="collision"/>
          <geom type="box" pos="0.03746241 0.03455008 0.07928143" size="0.004740975797176361 0.018581919372081757 0.09355513006448746" quat="0.9622822999954224 -0.02245895378291607 0.08381793648004532 0.2578427791595459" class="collision"/>
          <geom type="box" pos="-0.06428199 -0.02419209 0.07928143" size="0.004740975797176361 0.018581919372081757 0.09355513751506805" quat="0.2578427791595459 0.08381803333759308 0.02245897427201271 -0.9622822999954224" class="collision"/>
          <geom type="box" pos="-0.04278086 -0.04569321 0.07928143" size="0.004740975797176361 0.018581919372081757 0.09355513751506805" quat="0.49811404943466187 0.07514900714159012 0.043387334793806076 -0.8627586960792542" class="collision"/>
          <geom type="box" pos="0.01596129 0.05605120 0.07928143" size="0.004740975797176361 0.018581919372081757 0.09355513751506805" quat="0.8627587556838989 -0.04338733106851578 0.07514902949333191 0.4981139600276947" class="collision"/>
          <geom type="box" pos="-0.04278086 0.05605120 0.07928143" size="0.004740975797176361 0.018581919372081757 0.09355513751506805" quat="0.49811404943466187 -0.07514900714159012 0.043387334793806076 0.8627586960792542" class="collision"/>
          <geom type="box" pos="0.01596129 -0.04569320 0.07928143" size="0.004740975797176361 0.018581919372081757 0.09355513006448746" quat="0.8627587556838989 0.04338734969496727 0.07514909654855728 -0.4981139302253723" class="collision"/>
          <geom type="box" pos="0.03746241 -0.02419208 0.07928143" size="0.004740975797176361 0.018581919372081757 0.09355513006448746" quat="0.9622823596000671 0.022458944469690323 0.08381792157888412 -0.25784268975257874" class="collision"/>
          <geom type="box" pos="-0.06428199 0.03455007 0.07928143" size="0.004740975797176361 0.018581919372081757 0.09355513751506805" quat="0.2578427791595459 -0.08381803333759308 0.02245897427201271 0.9622822999954224" class="collision"/>
          <geom class="collision" type="box" pos="0.08060288 0.00442261 0.13820456" size="0.011232865042984486 0.012886925600469112 0.010835387744009495" quat="0.9739777445793152 0.0 0.2266436368227005 0.0" name="pitcher_handle_0"/>
          <geom class="collision" type="box" pos="0.08998093 0.00442261 0.12905489" size="0.008133475668728352 0.012886925600469112 0.009914564900100231" quat="0.8326515555381775 0.0 0.5537972450256348 0.0" name="pitcher_handle_1"/>
          <geom class="collision" type="box" pos="0.09003628 0.00442261 0.08520831" size="0.04113192483782768 0.012886925600469112 0.00918785110116005" quat="0.6727584004402161 3.299103656928537e-09 0.7398622632026672 -2.810899513150389e-09" name="pitcher_handle_2"/>
          <geom class="collision" type="box" pos="0.08013169 0.00442261 0.03771976" size="0.012385156936943531 0.012886925600469112 0.00875075999647379" quat="0.4286668002605438 0.0 0.9034626483917236 0.0" name="pitcher_handle_3"/>
          <geom class="collision" type="box" pos="0.06025315 0.00442261 0.02319772" size="0.015387085266411304 0.012886925600469112 0.009129141457378864" quat="0.2087034434080124 0.0 0.9779789447784424 0.0" name="pitcher_handle_4"/>
          <body name="blade">
            <!-- <joint axis="0.0 0.0 1.0" pos="-0.01424467 0.00591594 -0.02193279" limited="false" name="blade_joint" range="0 360" type="hinge" damping="1" frictionloss="1" armature=".01" stiffness="0.05"/> -->
            <geom mesh="blade_vis" type="mesh" solimp="0.998 0.998 0.001" solref="0.001 1" friction="0.95 0.3 0.1" class="visual" material="blade_material"/>
            <geom type="cylinder" pos="-0.01364893 0.00517901 -0.02543145" size="0.003170922864228487 0.004099421203136444" quat="1.0 0.0 0.0 0.0" class="collision"/>
            <geom type="box" pos="-0.01410603 0.00418800 -0.02250797" size="0.014141938649117947 0.00791434571146965 0.0002459282986819744" quat="0.9841994047164917 0.0 0.0 0.17706358432769775" class="collision"/>
            <geom type="box" pos="0.00506045 0.01131501 -0.01903470" size="0.009196617640554905 0.0075520845130085945 0.00036561701563186944" quat="0.956265926361084 0.06398852914571762 -0.22334979474544525 0.17769597470760345" class="collision"/>
            <geom type="box" pos="-0.03441685 -0.00336454 -0.02532603" size="0.008302983827888966 0.007914342917501926 0.00034735887311398983" quat="0.9655296802520752 0.029465211555361748 -0.1717633605003357 0.19334332644939423" class="collision"/>
            <geom type="box" pos="-0.01410603 0.00418800 -0.02371466" size="0.014141938649117947 0.007914344780147076 0.0002824610273819417" quat="0.8216372132301331 0.0 -0.0 -0.570010781288147" class="collision"/>
            <geom type="box" pos="-0.00667013 -0.01570229 -0.01987419" size="0.008311481215059757 0.00791434571146965 0.0002459282986819744" quat="0.7972676753997803 -0.1377963125705719 -0.1986253559589386 -0.5531043410301208" class="collision"/>
            <geom type="box" pos="-0.02175518 0.02464871 -0.02674755" size="0.008314153179526329 0.007914344780147076 0.0002459282986819744" quat="0.8104860782623291 -0.09359202533960342 -0.13490740954875946 -0.5622747540473938" class="collision"/>
          </body>
          <body name="pitcher_main">
            <geom class="region" type="cylinder" size="0.03664357587695122 0.07928308844566345" pos="-0.01319418 0.00478656 0.06569185" rgba="0 0 1 0.5" name="reg_int"/>
            <geom mesh="pitcher_main_vis" type="mesh" solimp="0.998 0.998 0.001" solref="0.001 1" friction="0.95 0.3 0.1" class="visual" material="pitcher_main_material"/>
            <geom type="box" pos="0.05502011 0.00517900 0.07935458" size="0.006446782033890486 0.027016857638955116 0.094341941177845" quat="0.9966984391212463 0.0 0.08119235932826996 0.0" class="collision"/>
            <geom type="cylinder" pos="-0.01364892 0.00517901 -0.03183776" size="0.03966103494167328 0.0012146661756560206" quat="1.0 0.0 0.0 0.0" class="collision"/>
          </body>
        </body>
        <body name="knob_speed">
          <joint axis="0.0 1.0 0.0" pos="-0.01317398 -0.07470910 -0.09942290" limited="true" name="knob_speed_joint" range="0.0 4.71238898038469" type="hinge" damping="0.05" frictionloss="0.1" armature="0.001"/>
          <geom mesh="knob_speed_vis" type="mesh" solimp="0.998 0.998 0.001" solref="0.001 1" friction="0.95 0.3 0.1" class="visual" material="knob_speed_material"/>
          <geom type="cylinder" pos="-0.01364893 -0.07254580 -0.09890006" size="0.025688841938972473 0.005045394878834486" quat="0.7071068286895752 -0.7071067690849304 -0.0 0.0" class="collision" density="0.001"/>
          <geom class="collision" type="box" pos="-0.01317081 -0.08396378 -0.09950612" size="0.010556374676525593 0.007968936115503311 0.023776941001415253" quat="0.3608556091785431 -4.125555008727133e-08 -0.9326217174530029 -7.759037146115588e-08" name="knob_speed_main" density="0.001"/>
        </body>
        <geom class="region" name="reg_main" type="box" pos="-0.011913235000000001 0.004331044999999999 0.0" size="0.09066411499999999 0.085063515 0.19429822"/>
      </body>
      <site rgba="0 1 0 0" size="0.005" pos="-0.01137218 0.00440853 0.16801763" name="anchor_site"/>
    </body>
  </worldbody>
  <actuator>
    <motor name="knob_speed_joint_actuator" joint="knob_speed_joint" gear="10"/>
    <!-- <motor name="pitcher_joint_actuator" joint="pitcher_joint" gear="80"/> -->
    <motor name="power_button_joint_actuator" joint="power_button_joint" gear="0.5"/>
    <!-- <motor name="blade_joint_actuator" joint="blade_joint" gear="20"/> -->
    <!-- <motor name="lid_joint_actuator" joint="lid_joint" gear="20"/> -->
  </actuator>
</mujoco>
