<?xml version='1.0' encoding='UTF-8'?>
<mujoco model="model">
  <option timestep="0.002" gravity="0.0 0.0 -9.81"/>
  <compiler angle="radian"/>
  <asset>
    <mesh file="visuals/Blade001.obj" name="Blade001_vis"/>
    <mesh file="visuals/Body001.obj" name="Body001_vis"/>
    <mesh file="visuals/Button001.obj" name="Button001_vis"/>
    <mesh file="visuals/Jug001.obj" name="Jug001_vis"/>
    <mesh file="visuals/Jug001_Clear.obj" name="Jug001_Clear_vis"/>
    <mesh file="visuals/Knob001.obj" name="Knob001_vis"/>
    <mesh file="visuals/Lid001.obj" name="Lid001_vis"/>
    <texture file="visuals/T_BC001.png" name="Body001_material" type="2d"/>
    <material name="Body001_material" rgba="1 1 1 1.0" texture="Body001_material" shininess="0.1" specular="2"/>
    <texture file="visuals/T_BC001.png" name="Button001_material" type="2d"/>
    <material name="Button001_material" rgba="1 1 1 1.0" texture="Button001_material" shininess="0.4472135901451111" specular="0.3103448502657381"/>
    <material name="Jug001_Clear_material" rgba="0.5881999731063843 0.5881999731063843 0.5881999731063843 0.800000011920929" shininess="0.10000002384185791" specular="0.33333333333333337"/>
    <texture file="visuals/T_BC001.png" name="Jug001_material" type="2d"/>
    <material name="Jug001_material" rgba="1 1 1 1.0" texture="Jug001_material" shininess="0.4472135901451111" specular="0.3103448502657381"/>
    <texture file="visuals/T_BC001.png" name="Blade001_material" type="2d"/>
    <material name="Blade001_material" rgba="1 1 1 1.0" texture="Blade001_material" shininess="0.4472135901451111" specular="0.3103448502657381"/>
    <texture file="visuals/T_BC001.png" name="Lid001_material" type="2d"/>
    <material name="Lid001_material" rgba="1 1 1 1.0" texture="Lid001_material" shininess="0.4472135901451111" specular="0.3103448502657381"/>
    <texture file="visuals/T_BC001.png" name="Knob001_material" type="2d"/>
    <material name="Knob001_material" rgba="1 1 1 1.0" texture="Knob001_material" shininess="0.4472135901451111" specular="0.3103448502657381"/>
  </asset>
  <default>
    <default class="visual">
      <geom conaffinity="0" contype="0" group="1" type="mesh"/>
    </default>
    <default class="collision">
      <geom group="0" rgba="0.5 0 0 0.5"/>
    </default>
    <default class="spawn">
      <geom group="0" rgba="1 1 1 0.5" contype="0" conaffinity="0"/>
      <site group="0" rgba="1 1 1 0.5"/>
    </default>
    <default class="region">
      <geom group="1" conaffinity="0" contype="0" rgba="0 1 0 0"/>
    </default>
  </default>
  <worldbody>
    <body>
      <body name="object">
        <geom mesh="Body001_vis" type="mesh" solimp="0.998 0.998 0.001" solref="0.001 1" friction="0.95 0.3 0.1" class="visual" material="Body001_material"/>
        <geom class="collision" type="box" pos="-0.09515609 0.01476613 -0.12396966" size="0.0054743182845413685 0.04164137691259384 0.09551781415939331" quat="0.9992919564247131 0.0 0.03762407973408699 0.0"/>
        <geom class="collision" type="box" pos="-0.02070477 -0.05600017 -0.12523258" size="0.0054743182845413685 0.04164137691259384 0.09551780670881271" quat="0.706755518913269 -0.02228604629635811 0.02228604629635811 0.7067554593086243"/>
        <geom class="collision" type="box" pos="0.05176017 0.00713336 -0.12396966" size="0.005474318750202656 0.04164137691259384 0.09551782160997391" quat="7.546636027200293e-08 -0.028902044519782066 2.1820438789177388e-09 0.9995822310447693"/>
        <geom class="collision" type="box" pos="-0.01956251 0.08019558 -0.12528173" size="0.0054743182845413685 0.04164137691259384 0.09551781415939331" quat="0.7067351937294006 0.022921277210116386 0.02292126789689064 -0.7067351937294006"/>
        <geom class="collision" type="box" pos="-0.07630777 0.06757122 -0.12396966" size="0.005474318750202656 0.025623897090554237 0.09551780670881271" quat="0.8883739113807678 0.017228038981556892 0.03344782441854477 -0.4575764536857605"/>
        <geom class="collision" type="box" pos="0.03633293 0.06375368 -0.12396966" size="0.005474317818880081 0.025623897090554237 0.09551780670881271" quat="0.3789641857147217 0.026744501665234566 0.010957466438412666 -0.9249598979949951"/>
        <geom class="collision" type="box" pos="0.03317800 -0.04134386 -0.12396966" size="0.0054743182845413685 0.025623897090554237 0.09551780670881271" quat="0.4256477653980255 -0.04192516580224037 0.01974695920944214 0.9037014842033386"/>
        <geom class="collision" type="box" pos="-0.07742481 -0.03855716 -0.12396966" size="0.0054743182845413685 0.025623897090554237 0.09551780670881271" quat="0.9243523478507996 -0.017569629475474358 0.04288322851061821 0.37871503829956055"/>
        <geom class="collision" type="box" pos="-0.02167261 0.01204293 -0.21243714" size="0.07172341644763947 0.07172341644763947 0.01033850759267807" quat="1.0 0.0 0.0 0.0"/>
        <geom class="collision" type="box" pos="-0.02167261 0.01204293 -0.03638610" size="0.05570942535996437 0.05570942535996437 0.008030187338590622" quat="1.0 0.0 0.0 0.0"/>
        <body name="Button001">
          <joint axis="1.5750340873743372e-18 0.9929066896438599 -0.11889630556106567" pos="-0.02125863 -0.07110283 -0.08987315" limited="true" name="Button001_joint" range="0.0 0.002" type="slide" damping="1" frictionloss="1" armature=".01" stiffness="0.05" springref="-0.1"/>
          <geom mesh="Button001_vis" type="mesh" solimp="0.998 0.998 0.001" solref="0.001 1" friction="0.95 0.3 0.1" class="visual" material="Button001_material"/>
          <geom class="collision" type="cylinder" pos="-0.02125863 -0.07136320 -0.08984661" size="0.007087751291692257 0.004477208014577627" quat="0.7420973181724548 0.6702921390533447 0.0 0.0"/>
        </body>
        <body name="Jug001_Clear">
          <!-- <geom class="region" name="reg_int" type="box" pos="-0.020991910000000003 0.009911030000000001 0.111101565" size="0.03723286 0.04280246 0.09043818499999999"/> -->
          <joint axis="0.0 0.0 1.0" pos="0.00025000 0.00390900 0.00100350" limited="true" name="Jug001_Clear_joint" range="0.0 0.1" type="slide" damping="1" frictionloss="1" armature=".01" stiffness="0.05"/>
          <geom mesh="Jug001_Clear_vis" type="mesh" solimp="0.998 0.998 0.001" solref="0.001 1" friction="0.95 0.3 0.1" class="visual" material="Jug001_Clear_material"/>
          <geom class="collision" type="box" pos="-0.02086875 -0.05912482 0.12695498" size="0.023175854235887527 0.007076061796396971 0.07389082759618759" quat="1.0 0.0 0.0 0.0"/>
          <geom class="collision" type="box" pos="-0.02086875 -0.05295889 0.01770921" size="0.023175908252596855 0.005516691133379936 0.03700769692659378" quat="0.9981673955917358 0.060513097792863846 0.0 0.0"/>
          <geom class="collision" type="box" pos="-0.06003613 -0.04693161 0.12695498" size="0.023175911977887154 0.005516692530363798 0.07379065454006195" quat="0.9549254775047302 0.010099019855260849 -0.003137363586574793 -0.2966572344303131"/>
          <geom class="collision" type="box" pos="-0.05654230 -0.04185108 0.01770921" size="0.023175908252596855 0.005516690202057362 0.03700769692659378" quat="0.953228771686554 0.05778857693076134 -0.017952607944607735 -0.29613015055656433"/>
          <geom class="collision" type="box" pos="-0.07916146 -0.01370328 0.01770921" size="0.023175908252596855 0.005516691133379936 0.03700769692659378" quat="0.8282976746559143 0.05021476000547409 -0.03376825898885727 -0.5570108890533447"/>
          <geom class="collision" type="box" pos="-0.08487194 -0.01602906 0.12695498" size="0.023175911977887154 0.005516692530363798 0.07379065454006195" quat="0.8297720551490784 0.008775432594120502 -0.0059012724086642265 -0.558002233505249"/>
          <geom class="collision" type="box" pos="-0.08871573 0.02308562 0.12695498" size="0.023175911977887154 0.0055166929960250854 0.07379065454006195" quat="0.6369348168373108 0.006736038718372583 -0.008152233436703682 -0.7708451151847839"/>
          <geom class="collision" type="box" pos="-0.08266037 0.02192311 0.01770921" size="0.023175908252596855 0.005516691133379936 0.03700769692659378" quat="0.6358030438423157 0.03854496777057648 -0.04664872959256172 -0.7694755792617798"/>
          <geom class="collision" type="box" pos="-0.06591754 0.05396626 0.01770921" size="0.023175908252596855 0.005516690202057362 0.03700769692659378" quat="0.38814669847488403 0.023531027138233185 -0.05575042590498924 -0.9196087718009949"/>
          <geom class="collision" type="box" pos="-0.07033549 0.05826747 0.12695498" size="0.023175911977887154 0.005516692530363798 0.07379065454006195" quat="0.3888375759124756 0.004112234804779291 -0.009742825292050838 -0.9212456345558167"/>
          <geom class="collision" type="box" pos="-0.03564053 0.07754081 0.12695500" size="0.023175911977887154 0.005516692530363798 0.07379065454006195" quat="0.10804449766874313 0.0011426507262513041 -0.01051324512809515 -0.9940897822380066"/>
          <geom class="collision" type="box" pos="-0.03431587 0.07151885 0.01770921" size="0.023175908252596855 0.005516691133379936 0.03700769692659378" quat="0.1078525260090828 0.006538456305861473 -0.06015866994857788 -0.9923235177993774"/>
          <geom class="collision" type="box" pos="0.00226276 0.06859405 0.01770921" size="0.023175908252596855 0.005516691133379936 0.03700769692659378" quat="0.18596415221691132 0.011273913085460663 0.059453509747982025 0.9806913733482361"/>
          <geom class="collision" type="box" pos="0.00452003 0.07433193 0.12695500" size="0.023175911977887154 0.005516692530363798 0.07379065454006195" quat="0.1862950325012207 0.0019702031277120113 0.010389960370957851 0.9824369549751282"/>
          <geom class="collision" type="box" pos="0.03642788 0.04876017 0.12695500" size="0.023175911977887154 0.0055166929960250854 0.07379065454006195" quat="0.46849510073661804 0.00495466822758317 0.009342609904706478 0.8834028244018555"/>
          <geom class="collision" type="box" pos="0.03132352 0.04530124 0.01770921" size="0.023175908252596855 0.005516690202057362 0.03700769692659378" quat="0.4676626920700073 0.028351616114377975 0.053460318595170975 0.8818331956863403"/>
          <geom class="collision" type="box" pos="0.04214088 0.00965553 0.01770921" size="0.023175908252596855 0.005516690202057362 0.03700769692659378" quat="0.7075697779655457 0.042895764112472534 0.042682234197854996 0.7040477395057678"/>
          <geom class="collision" type="box" pos="0.04830674 0.00962476 0.12695500" size="0.00719161331653595 0.023210931569337845 0.07389082759618759" quat="1.0 0.0 0.0 0.0"/>
          <geom class="collision" type="box" pos="0.03669833 -0.02833604 0.12695500" size="0.023175911977887154 0.005516692530363798 0.07379065454006195" quat="0.8814740777015686 0.00932222418487072 0.004992946051061153 0.4721139669418335"/>
          <geom class="collision" type="box" pos="0.03156578 -0.02491909 0.01770921" size="0.023175908252596855 0.005516690202057362 0.03700769692659378" quat="0.87990802526474 0.05334360897541046 0.02857060730457306 0.4712749421596527"/>
          <geom class="collision" type="box" pos="0.00905607 -0.04541609 0.01770921" size="0.023175908252596855 0.005516691133379936 0.03700769692659378" quat="0.9677349925041199 0.058668024837970734 0.014828402549028397 0.2445959448814392"/>
          <geom class="collision" type="box" pos="0.01198580 -0.05084152 0.12695500" size="0.023175911977887154 0.005516692530363798 0.07379065454006195" quat="0.9694575071334839 0.010252689011394978 0.0025913782883435488 0.24503132700920105"/>
          <geom class="collision" type="box" pos="0.08159569 0.01001288 0.16783240" size="0.028919121250510216 0.015560505911707878 0.008479977957904339" quat="1.0 0.0 0.0 0.0"/>
          <geom class="collision" type="box" pos="0.09916771 0.01001288 0.10729443" size="0.011199488304555416 0.015560510568320751 0.051797281950712204" quat="1.0 0.0 0.0 0.0"/>
          <geom class="collision" type="box" pos="0.07771460 0.01001288 0.05714760" size="0.02946845255792141 0.015560523606836796 0.00854925811290741" quat="0.9980339407920837 0.0 -0.06267547607421875 0.0"/>
          <body name="Jug001">
            <geom mesh="Jug001_vis" type="mesh" solimp="0.998 0.998 0.001" solref="0.001 1" friction="0.95 0.3 0.1" class="visual" material="Jug001_material"/>
            <geom class="collision" type="cylinder" pos="-0.01826130 0.01058441 -0.01807209" size="0.013563878834247589 0.0030004368163645267" quat="0.70710688829422 0.0 0.0 -0.7071066498756409"/>
            <geom class="collision" type="box" pos="-0.02086875 -0.05912482 0.12695498" size="0.023175854235887527 0.007076061796396971 0.07389082759618759" quat="1.0 0.0 0.0 0.0"/>
            <geom class="collision" type="box" pos="-0.02086875 -0.05295889 0.01770921" size="0.023175908252596855 0.005516691133379936 0.03700769692659378" quat="0.9981673955917358 0.060513097792863846 0.0 0.0"/>
            <geom class="collision" type="box" pos="-0.06003613 -0.04693161 0.12695498" size="0.023175911977887154 0.005516692530363798 0.07379065454006195" quat="0.9549254775047302 0.010099019855260849 -0.003137363586574793 -0.2966572344303131"/>
            <geom class="collision" type="box" pos="-0.05654230 -0.04185108 0.01770921" size="0.023175908252596855 0.005516690202057362 0.03700769692659378" quat="0.953228771686554 0.05778857693076134 -0.017952607944607735 -0.29613015055656433"/>
            <geom class="collision" type="box" pos="-0.07916146 -0.01370328 0.01770921" size="0.023175908252596855 0.005516691133379936 0.03700769692659378" quat="0.8282976746559143 0.05021476000547409 -0.03376825898885727 -0.5570108890533447"/>
            <geom class="collision" type="box" pos="-0.08487194 -0.01602906 0.12695498" size="0.023175911977887154 0.005516692530363798 0.07379065454006195" quat="0.8297720551490784 0.008775432594120502 -0.0059012724086642265 -0.558002233505249"/>
            <geom class="collision" type="box" pos="-0.08871573 0.02308562 0.12695498" size="0.023175911977887154 0.0055166929960250854 0.07379065454006195" quat="0.6369348168373108 0.006736038718372583 -0.008152233436703682 -0.7708451151847839"/>
            <geom class="collision" type="box" pos="-0.08266037 0.02192311 0.01770921" size="0.023175908252596855 0.005516691133379936 0.03700769692659378" quat="0.6358030438423157 0.03854496777057648 -0.04664872959256172 -0.7694755792617798"/>
            <geom class="collision" type="box" pos="-0.06591754 0.05396626 0.01770921" size="0.023175908252596855 0.005516690202057362 0.03700769692659378" quat="0.38814669847488403 0.023531027138233185 -0.05575042590498924 -0.9196087718009949"/>
            <geom class="collision" type="box" pos="-0.07033549 0.05826747 0.12695498" size="0.023175911977887154 0.005516692530363798 0.07379065454006195" quat="0.3888375759124756 0.004112234804779291 -0.009742825292050838 -0.9212456345558167"/>
            <geom class="collision" type="box" pos="-0.03564053 0.07754081 0.12695500" size="0.023175911977887154 0.005516692530363798 0.07379065454006195" quat="0.10804449766874313 0.0011426507262513041 -0.01051324512809515 -0.9940897822380066"/>
            <geom class="collision" type="box" pos="-0.03431587 0.07151885 0.01770921" size="0.023175908252596855 0.005516691133379936 0.03700769692659378" quat="0.1078525260090828 0.006538456305861473 -0.06015866994857788 -0.9923235177993774"/>
            <geom class="collision" type="box" pos="0.00226276 0.06859405 0.01770921" size="0.023175908252596855 0.005516691133379936 0.03700769692659378" quat="0.18596415221691132 0.011273913085460663 0.059453509747982025 0.9806913733482361"/>
            <geom class="collision" type="box" pos="0.00452003 0.07433193 0.12695500" size="0.023175911977887154 0.005516692530363798 0.07379065454006195" quat="0.1862950325012207 0.0019702031277120113 0.010389960370957851 0.9824369549751282"/>
            <geom class="collision" type="box" pos="0.03642788 0.04876017 0.12695500" size="0.023175911977887154 0.0055166929960250854 0.07379065454006195" quat="0.46849510073661804 0.00495466822758317 0.009342609904706478 0.8834028244018555"/>
            <geom class="collision" type="box" pos="0.03132352 0.04530124 0.01770921" size="0.023175908252596855 0.005516690202057362 0.03700769692659378" quat="0.4676626920700073 0.028351616114377975 0.053460318595170975 0.8818331956863403"/>
            <geom class="collision" type="box" pos="0.04214088 0.00965553 0.01770921" size="0.023175908252596855 0.005516690202057362 0.03700769692659378" quat="0.7075697779655457 0.042895764112472534 0.042682234197854996 0.7040477395057678"/>
            <geom class="collision" type="box" pos="0.04830674 0.00962476 0.12695500" size="0.00719161331653595 0.023210931569337845 0.07389082759618759" quat="1.0 0.0 0.0 0.0"/>
            <geom class="collision" type="box" pos="0.03669833 -0.02833604 0.12695500" size="0.023175911977887154 0.005516692530363798 0.07379065454006195" quat="0.8814740777015686 0.00932222418487072 0.004992946051061153 0.4721139669418335"/>
            <geom class="collision" type="box" pos="0.03156578 -0.02491909 0.01770921" size="0.023175908252596855 0.005516690202057362 0.03700769692659378" quat="0.87990802526474 0.05334360897541046 0.02857060730457306 0.4712749421596527"/>
            <geom class="collision" type="box" pos="0.00905607 -0.04541609 0.01770921" size="0.023175908252596855 0.005516691133379936 0.03700769692659378" quat="0.9677349925041199 0.058668024837970734 0.014828402549028397 0.2445959448814392"/>
            <geom class="collision" type="box" pos="0.01198580 -0.05084152 0.12695500" size="0.023175911977887154 0.005516692530363798 0.07379065454006195" quat="0.9694575071334839 0.010252689011394978 0.0025913782883435488 0.24503132700920105"/>
            <geom class="collision" type="box" pos="0.08159569 0.01001288 0.16783240" size="0.028919121250510216 0.015560505911707878 0.008479977957904339" quat="1.0 0.0 0.0 0.0"/>
            <geom class="collision" type="box" pos="0.09916771 0.01001288 0.10729443" size="0.011199488304555416 0.015560510568320751 0.051797281950712204" quat="1.0 0.0 0.0 0.0"/>
            <geom class="collision" type="box" pos="0.07771460 0.01001288 0.05714760" size="0.02946845255792141 0.015560523606836796 0.00854925811290741" quat="0.9980339407920837 0.0 -0.06267547607421875 0.0"/>
            <geom class="collision" type="cylinder" pos="-0.01792707 0.01009008 -0.02435832" size="0.07933948934078217 0.0035974886268377304" quat="1.0 0.0 0.0 0.0"/>
            <body name="Blade001">
              <joint axis="0.0 0.0 1.0" pos="-0.01812364 0.01042146 -0.00076632" limited="false" name="Blade001_joint" range="0 360" type="hinge" damping="1" frictionloss="1" armature=".01" stiffness="0.05"/>
              <geom mesh="Blade001_vis" type="mesh" solimp="0.998 0.998 0.001" solref="0.001 1" friction="0.95 0.3 0.1" class="visual" material="Blade001_material"/>
              <geom class="collision" type="box" pos="0.00204605 0.01669492 0.00917565" size="0.0015862119616940618 0.018787633627653122 0.008514349348843098" quat="0.22424311935901642 0.4206318259239197 -0.4267450273036957 0.7685522437095642"/>
              <geom class="collision" type="box" pos="-0.04108375 0.00226118 0.00607678" size="0.0014495250070467591 0.018787631765007973 0.00851509440690279" quat="0.46829313039779663 0.6533452272415161 -0.34451261162757874 0.48492538928985596"/>
              <geom class="collision" type="box" pos="-0.01246180 -0.01041368 -0.00240662" size="0.0014507644809782505 0.018769260495901108 0.00669638067483902" quat="0.3194257915019989 -0.6354911923408508 -0.12435971200466156 -0.6918473839759827"/>
              <geom class="collision" type="box" pos="-0.02522345 0.03246708 -0.00698720" size="0.001831724657677114 0.01876925863325596 0.007409302052110434" quat="0.037183113396167755 0.6721182465553284 0.3039575219154358 0.67415452003479"/>
              <geom class="collision" type="cylinder" pos="-0.01812364 0.01042146 -0.00537061" size="0.010318148881196976 0.008342823013663292" quat="1.0 0.0 0.0 0.0"/>
            </body>
          </body>
        </body>
        <body name="Knob001">
          <joint axis="0.0 1.0 0.0" pos="-0.02082800 -0.08041372 -0.16011650" limited="true" name="Knob001_joint" range="0.0 3.752457891787808" type="hinge" damping="0.05" armature="0.001"/>
          <geom mesh="Knob001_vis" type="mesh" solimp="0.998 0.998 0.001" solref="0.001 1" friction="0.95 0.3 0.1" class="visual" material="Knob001_material"/>
          <geom class="collision" type="cylinder" pos="-0.02082819 -0.07287767 -0.16011688" size="0.02244795672595501 0.006288353819400072" quat="0.7071068286895752 0.7071067690849304 0.0 0.0"/>
          <geom class="collision" type="box" pos="-0.02107506 -0.08411061 -0.16031808" size="0.004999999888241291 0.008138016797602177 0.02128095179796219" quat="1.0 0.0 0.0 0.0"/>
        </body>
        <geom class="region" name="reg_main" type="box" pos="-0.023092945000000004 0.009251599999999999 0.0010035000000000044" size="0.087257055 0.08420555 0.22637592"/>
      </body>
      <site rgba="0 1 0 0" size="0.005" pos="-0.02082781 0.01001121 0.20801517" name="anchor_site"/>
    </body>
  </worldbody>
  <actuator>
    <motor name="Button001_joint_actuator" joint="Button001_joint" gear="0.1"/>
    <!-- <motor name="Jug001_Clear_joint_actuator" joint="Jug001_Clear_joint" gear="200"/> -->
    <motor name="Knob001_joint_actuator" joint="Knob001_joint" gear="10"/>
    <!-- <motor name="Lid001_joint_actuator" joint="Lid001_joint" gear="20"/> -->
    <motor name="Blade001_joint_actuator" joint="Blade001_joint" gear="10"/>
  </actuator>
</mujoco>
