<?xml version='1.0' encoding='UTF-8'?>
<mujoco model="model">
  <option timestep="0.002" gravity="0.0 0.0 -9.81"/>
  <compiler angle="radian"/>
  <asset>
    <mesh file="visuals/Blade001.obj" name="Blade001_vis"/>
    <mesh file="visuals/Body001.obj" name="Body001_vis"/>
    <mesh file="visuals/Button001.obj" name="Button001_vis"/>
    <mesh file="visuals/Jug001.obj" name="Jug001_vis"/>
    <mesh file="visuals/Jug001_Clear.obj" name="Jug001_Clear_vis"/>
    <mesh file="visuals/Knob001.obj" name="Knob001_vis"/>
    <mesh file="visuals/Lid001.obj" name="Lid001_vis"/>
    <texture file="visuals/T_BC001.png" name="Body001_material" type="2d"/>
    <material name="Body001_material" rgba="1 1 1 1.0" texture="Body001_material" shininess="0.4472135901451111" specular="0.3103448502657381"/>
    <texture file="visuals/T_BC001.png" name="Button001_material" type="2d"/>
    <material name="Button001_material" rgba="1 1 1 1.0" texture="Button001_material" shininess="0.4472135901451111" specular="0.3103448502657381"/>
    <texture file="visuals/T_BC001.png" name="Jug001_Clear_material" type="2d"/>
    <material name="Jug001_Clear_material" rgba="1 1 1 0.800000011920929" texture="Jug001_Clear_material" shininess="0.8692915439605713" specular="0.33333333333333337"/>
    <texture file="visuals/T_BC001.png" name="Jug001_material" type="2d"/>
    <material name="Jug001_material" rgba="1 1 1 1.0" texture="Jug001_material" shininess="0.4472135901451111" specular="0.3103448502657381"/>
    <texture file="visuals/T_BC001.png" name="Blade001_material" type="2d"/>
    <material name="Blade001_material" rgba="1 1 1 1.0" texture="Blade001_material" shininess="0.4472135901451111" specular="0.3103448502657381"/>
    <texture file="visuals/T_BC001.png" name="Lid001_material" type="2d"/>
    <material name="Lid001_material" rgba="1 1 1 1.0" texture="Lid001_material" shininess="0.4472135901451111" specular="0.3103448502657381"/>
    <texture file="visuals/T_BC001.png" name="Knob001_material" type="2d"/>
    <material name="Knob001_material" rgba="1 1 1 1.0" texture="Knob001_material" shininess="0.4472135901451111" specular="0.3103448502657381"/>
  </asset>
  <default>
    <default class="visual">
      <geom conaffinity="0" contype="0" group="1" type="mesh"/>
    </default>
    <default class="collision">
      <geom group="0" rgba="0.5 0 0 0.5"/>
    </default>
    <default class="spawn">
      <geom group="0" rgba="1 1 1 0.5" contype="0" conaffinity="0"/>
      <site group="0" rgba="1 1 1 0.5"/>
    </default>
    <default class="region">
      <geom group="1" conaffinity="0" contype="0" rgba="0 1 0 0"/>
    </default>
  </default>
  <worldbody>
    <body>
      <body name="object">
        <geom mesh="Body001_vis" type="mesh" solimp="0.998 0.998 0.001" solref="0.001 1" friction="0.95 0.3 0.1" class="visual" material="Body001_material"/>
        <geom class="collision" type="box" pos="-0.01514570 0.00819035 -0.13751809" size="0.07678362727165222 0.07831722497940063 0.1044483631849289" quat="1.0 0.0 0.0 0.0"/>
        <body name="Button001">
          <joint axis="0.0 1.0 0.0" pos="-0.01380459 -0.07846444 -0.19373468" limited="true" name="Button001_joint" range="0.0 0.002" type="slide" damping="1" frictionloss="1" armature=".01" stiffness="0.05"/>
          <geom mesh="Button001_vis" type="mesh" solimp="0.998 0.998 0.001" solref="0.001 1" friction="0.95 0.3 0.1" class="visual" material="Button001_material"/>
          <geom class="collision" type="box" pos="-0.01331331 -0.08189568 -0.19373134" size="0.014210648834705353 0.0018777165096253157 0.005925004370510578" quat="1.0 0.0 0.0 0.0"/>
        </body>
        <body name="Jug001_Clear">
          <geom class="region" name="reg_int" type="box" pos="-0.014905024999999999 0.00882501 0.09482433000000001" size="0.037721345 0.03874804 0.09806829"/>
          <!-- <joint axis="0.0 0.0 1.0" pos="0.00000000 0.00774600 0.00000000" limited="true" name="Jug001_Clear_joint" range="0.0 0.1" type="slide" damping="1" frictionloss="1" armature=".01" stiffness="0.05"/> -->
          <geom mesh="Jug001_Clear_vis" type="mesh" solimp="0.998 0.998 0.001" solref="0.001 1" friction="0.95 0.3 0.1" class="visual" material="Jug001_Clear_material"/>
          <geom class="collision" type="box" pos="0.10569994 -0.01217157 0.11763810" size="0.011882654391229153 0.015193642117083073 0.05532687529921532" quat="0.9955431222915649 -0.0037091949488967657 -0.0444367341697216 -0.08309933543205261"/>
          <geom class="collision" type="box" pos="0.08453979 -0.00878165 0.03727124" size="0.03337487205862999 0.013104078359901905 0.010871321894228458" quat="0.9774189591407776 -0.016214270144701004 -0.19424954056739807 -0.08158649504184723"/>
          <geom class="collision" type="box" pos="0.09116723 -0.00972842 0.17908831" size="0.02543867938220501 0.015193642117083073 0.01057860441505909" quat="0.9774189591407776 0.016214268282055855 0.19424955546855927 -0.08158648014068604"/>
          <geom class="collision" type="box" pos="-0.01369678 0.08226802 0.09996044" size="0.029443033039569855 0.006673652678728104 0.12612296640872955" quat="0.9985349774360657 -0.054110053926706314 -0.0 0.0"/>
          <geom class="collision" type="box" pos="-0.01369678 -0.06365235 0.09615796" size="0.029443033039569855 0.006501862313598394 0.12452355027198792" quat="0.9985349774360657 0.05411006137728691 0.0 0.0"/>
          <geom class="collision" type="box" pos="-0.08666596 0.00778433 0.09875156" size="0.029443033039569855 0.006501862313598394 0.12713243067264557" quat="0.7060708999633789 0.038261592388153076 -0.03826158866286278 -0.7060708403587341"/>
          <geom class="collision" type="box" pos="0.05640423 0.00778434 0.09898844" size="0.029443033039569855 0.006568617653101683 0.127089262008667" quat="0.7060708999633789 -0.03826158493757248 0.03826158493757248 -0.7060708403587341"/>
          <geom class="collision" type="box" pos="0.03581584 0.06147503 0.09893665" size="0.029443033039569855 0.006563021335750818 0.12714074552059174" quat="0.9271512031555176 -0.050241824239492416 0.020091267302632332 -0.37075966596603394"/>
          <geom class="collision" type="box" pos="-0.06443459 -0.04374183 0.09743603" size="0.029443033039569855 0.006501862313598394 0.12580914795398712" quat="0.9271512031555176 0.05024183169007301 -0.02009126916527748 -0.37075966596603394"/>
          <geom class="collision" type="box" pos="0.03301706 -0.04442769 0.09789914" size="0.029443034902215004 0.006501862313598394 0.1262749880552292" quat="0.9296003580093384 0.05037453770637512 0.019756143912672997 0.36457544565200806"/>
          <geom class="collision" type="box" pos="-0.06531331 0.06269629 0.10036092" size="0.029443034902215004 0.006716929841786623 0.12572482228279114" quat="0.9296003580093384 -0.050374530255794525 -0.019756142050027847 0.36457544565200806"/>
          <geom class="collision" type="cylinder" pos="-0.01625181 0.00786050 -0.02786859" size="0.057328250259160995 0.0008909525349736214" quat="1.0 0.0 0.0 0.0"/>
          <body name="Jug001">
            <geom mesh="Jug001_vis" type="mesh" solimp="0.998 0.998 0.001" solref="0.001 1" friction="0.95 0.3 0.1" class="visual" material="Jug001_material"/>
            <geom class="collision" type="box" pos="0.10569994 -0.01217157 0.11763810" size="0.011882654391229153 0.015193642117083073 0.05532687529921532" quat="0.9955431222915649 -0.0037091949488967657 -0.0444367341697216 -0.08309933543205261"/>
            <geom class="collision" type="box" pos="0.08453979 -0.00878165 0.03727124" size="0.03337487205862999 0.013104078359901905 0.010871321894228458" quat="0.9774189591407776 -0.016214270144701004 -0.19424954056739807 -0.08158649504184723"/>
            <geom class="collision" type="box" pos="0.09116723 -0.00972842 0.17908831" size="0.02543867938220501 0.015193642117083073 0.01057860441505909" quat="0.9774189591407776 0.016214268282055855 0.19424955546855927 -0.08158648014068604"/>
            <geom class="collision" type="box" pos="-0.01369678 0.08226802 0.09996044" size="0.029443033039569855 0.006673652678728104 0.12612296640872955" quat="0.9985349774360657 -0.054110053926706314 -0.0 0.0"/>
            <geom class="collision" type="box" pos="-0.01369678 -0.06365235 0.09615796" size="0.029443033039569855 0.006501862313598394 0.12452355027198792" quat="0.9985349774360657 0.05411006137728691 0.0 0.0"/>
            <geom class="collision" type="box" pos="-0.08666596 0.00778433 0.09875156" size="0.029443033039569855 0.006501862313598394 0.12713243067264557" quat="0.7060708999633789 0.038261592388153076 -0.03826158866286278 -0.7060708403587341"/>
            <geom class="collision" type="box" pos="0.05640423 0.00778434 0.09898844" size="0.029443033039569855 0.006568617653101683 0.127089262008667" quat="0.7060708999633789 -0.03826158493757248 0.03826158493757248 -0.7060708403587341"/>
            <geom class="collision" type="box" pos="0.03581584 0.06147503 0.09893665" size="0.029443033039569855 0.006563021335750818 0.12714074552059174" quat="0.9271512031555176 -0.050241824239492416 0.020091267302632332 -0.37075966596603394"/>
            <geom class="collision" type="box" pos="-0.06443459 -0.04374183 0.09743603" size="0.029443033039569855 0.006501862313598394 0.12580914795398712" quat="0.9271512031555176 0.05024183169007301 -0.02009126916527748 -0.37075966596603394"/>
            <geom class="collision" type="box" pos="0.03301706 -0.04442769 0.09789914" size="0.029443034902215004 0.006501862313598394 0.1262749880552292" quat="0.9296003580093384 0.05037453770637512 0.019756143912672997 0.36457544565200806"/>
            <geom class="collision" type="box" pos="-0.06531331 0.06269629 0.10036092" size="0.029443034902215004 0.006716929841786623 0.12572482228279114" quat="0.9296003580093384 -0.050374530255794525 -0.019756142050027847 0.36457544565200806"/>
            <geom class="collision" type="cylinder" pos="-0.01625181 0.00786050 -0.02786859" size="0.057328250259160995 0.0008909525349736214" quat="1.0 0.0 0.0 0.0"/>
            <geom class="collision" type="cylinder" pos="-0.01625181 0.00786050 -0.02501501" size="0.012912442907691002 0.004275952931493521" quat="1.0 0.0 0.0 0.0"/>
            <body name="Blade001">
              <joint axis="0.0 0.0 1.0" pos="-0.01602507 0.00731437 -0.01755270" limited="false" name="Blade001_joint" range="0 360" type="hinge" damping="1" frictionloss="1" armature=".01" stiffness="0.05"/>
              <geom mesh="Blade001_vis" type="mesh" solimp="0.998 0.998 0.001" solref="0.001 1" friction="0.95 0.3 0.1" class="visual" material="Blade001_material"/>
              <geom class="collision" type="cylinder" pos="-0.01625181 0.00786050 -0.01176064" size="0.010120311751961708 0.006583241745829582" quat="1.0 0.0 0.0 0.0"/>
            </body>
          </body>
        </body>
        <body name="Knob001">
          <joint axis="0.0 0.9961947202682495 -0.08715574443340302" pos="-0.01608700 -0.08206573 -0.14010651" limited="true" name="Knob001_joint" range="0.0 3.141592653589793" type="hinge" damping="0.05" armature="0.001"/>
          <geom mesh="Knob001_vis" type="mesh" solimp="0.998 0.998 0.001" solref="0.001 1" friction="0.95 0.3 0.1" class="visual" material="Knob001_material"/>
          <geom class="collision" type="cylinder" pos="-0.01616849 -0.07504041 -0.14093654" size="0.03245633468031883 0.0008922007982619107" quat="0.7324968576431274 0.6807703971862793 0.0 0.0"/>
          <geom class="collision" type="box" pos="-0.01613558 -0.08936560 -0.13958450" size="0.006805765442550182 0.01165817677974701 0.024993430823087692" quat="0.999072253704071 -0.04306577146053314 -1.295046431204483e-10 3.0043463272733106e-09"/>
        </body>
        <geom class="region" name="reg_main" type="box" pos="-0.020575135 0.009352610000000004 0.0" size="0.100675135 0.09490660000000001 0.24944317"/>
      </body>
      <site rgba="0 1 0 0" size="0.005" pos="-0.01447381 0.01065606 0.21799434" name="anchor_site"/>
    </body>
  </worldbody>
  <actuator>
    <motor name="Button001_joint_actuator" joint="Button001_joint" gear="0.2"/>
    <!-- <motor name="Jug001_Clear_joint_actuator" joint="Jug001_Clear_joint" gear="200"/> -->
    <motor name="Knob001_joint_actuator" joint="Knob001_joint" gear="10"/>
    <!-- <motor name="Lid001_joint_actuator" joint="Lid001_joint" gear="20"/> -->
    <motor name="Blade001_joint_actuator" joint="Blade001_joint" gear="10"/>
  </actuator>
</mujoco>
