<?xml version='1.0' encoding='UTF-8'?>
<mujoco model="model">
  <option timestep="0.002" gravity="0.0 0.0 -9.81"/>
  <compiler angle="radian"/>
  <asset>
    <mesh file="visuals/Blade001.obj" name="Blade001_vis"/>
    <mesh file="visuals/Body001.obj" name="Body001_vis"/>
    <mesh file="visuals/Button001.obj" name="Button001_vis"/>
    <mesh file="visuals/Button002.obj" name="Button002_vis"/>
    <mesh file="visuals/Jug001.obj" name="Jug001_vis"/>
    <mesh file="visuals/Jug001_Clear.obj" name="Jug001_Clear_vis"/>
    <mesh file="visuals/Knob001.obj" name="Knob001_vis"/>
    <mesh file="visuals/Lid001.obj" name="Lid001_vis"/>
    <texture file="visuals/T_BC001.png" name="Body001_material" type="2d"/>
    <material name="Body001_material" rgba="1 1 1 1.0" texture="Body001_material" shininess="0.1" specular="1"/>
    <texture file="visuals/T_BC001.png" name="Button001_material" type="2d"/>
    <material name="Button001_material" rgba="1 1 1 1.0" texture="Button001_material" shininess="0.5" specular="0.3103448502657381"/>
    <texture file="visuals/T_BC001.png" name="Button002_material" type="2d"/>
    <material name="Button002_material" rgba="1 1 1 1.0" texture="Button002_material" shininess="0.5" specular="0.3103448502657381"/>
    <texture file="visuals/T_BC001.png" name="Jug001_material" type="2d"/>
    <material name="Jug001_material" rgba="1 1 1 1.0" texture="Jug001_material" shininess="0.5" specular="0.3103448502657381"/>
    <texture file="visuals/T_BC001.png" name="Blade001_material" type="2d"/>
    <material name="Blade001_material" rgba="1 1 1 1.0" texture="Blade001_material" shininess="0.5" specular="0.3103448502657381"/>
    <texture file="visuals/T_BC001.png" name="Jug001_Clear_material" type="2d"/>
    <material name="Jug001_Clear_material" rgba="1 1 1 0.699999988079071" texture="Jug001_Clear_material" shininess="0.5" specular="0.3103448502657381"/>
    <texture file="visuals/T_BC001.png" name="Lid001_material" type="2d"/>
    <material name="Lid001_material" rgba="1 1 1 1.0" texture="Lid001_material" shininess="0.5" specular="0.3103448502657381"/>
    <texture file="visuals/T_BC001.png" name="Knob001_material" type="2d"/>
    <material name="Knob001_material" rgba="1 1 1 1.0" texture="Knob001_material" shininess="0.5" specular="0.3103448502657381"/>
  </asset>
  <default>
    <default class="visual">
      <geom conaffinity="0" contype="0" group="1" type="mesh"/>
    </default>
    <default class="collision">
      <geom group="0" rgba="0.5 0 0 0.5"/>
    </default>
    <default class="spawn">
      <geom group="0" rgba="1 1 1 0.5" contype="0" conaffinity="0"/>
      <site group="0" rgba="1 1 1 0.5"/>
    </default>
    <default class="region">
      <geom group="1" conaffinity="0" contype="0" rgba="0 1 0 0"/>
    </default>
  </default>
  <worldbody>
    <body>
      <body name="object">
        <geom mesh="Body001_vis" type="mesh" solimp="0.998 0.998 0.001" solref="0.001 1" friction="0.95 0.3 0.1" class="visual" material="Body001_material"/>
        <geom class="collision" type="box" pos="-0.01561236 -0.04847207 -0.16883487" size="0.09955644607543945 0.044624779373407364 0.032997120171785355" quat="0.8877590894699097 0.46030834317207336 0.0 0.0"/>
        <geom class="collision" type="box" pos="-0.01561236 0.00582542 -0.21375677" size="0.09955644607543945 0.10717274248600006 0.03572746366262436" quat="1.0 0.0 0.0 0.0"/>
        <geom class="collision" type="box" pos="-0.01561236 0.03171817 -0.14704540" size="0.09955644607543945 0.08168954402208328 0.032997116446495056" quat="1.0 0.0 0.0 0.0"/>
        <geom class="collision" type="cylinder" pos="-0.01604271 0.02733906 -0.10377229" size="0.07834652066230774 0.01722797192633152" quat="1.0 0.0 0.0 0.0"/>
        <body name="Button001">
          <joint axis="0.10692079365253448 0.8121441602706909 -0.5735763907432556" pos="-0.06169808 -0.08929481 -0.15561497" limited="true" name="Button001_joint" range="0.0 0.0015" type="slide" damping="1" frictionloss="1" armature=".01" stiffness="0.05" springref="-0.3"/>
          <geom mesh="Button001_vis" type="mesh" solimp="0.998 0.998 0.001" solref="0.001 1" friction="0.95 0.3 0.1" class="visual" material="Button001_material"/>
          <geom class="collision" type="box" pos="-0.06169808 -0.08929481 -0.15561497" size="0.010050386190414429 0.002920703962445259 0.00618571974337101" quat="0.95280921459198 -0.30041956901550293 0.013116598129272461 -0.041600536555051804"/>
        </body>
        <body name="Button002">
          <joint axis="-0.10692079365253448 0.8121441602706909 -0.5735763907432556" pos="0.03133892 -0.08929481 -0.15561497" limited="true" name="Button002_joint" range="0.0 0.0015" type="slide" damping="1" frictionloss="1" armature=".01" stiffness="0.05" springref="-0.3"/>
          <geom mesh="Button002_vis" type="mesh" solimp="0.998 0.998 0.001" solref="0.001 1" friction="0.95 0.3 0.1" class="visual" material="Button002_material"/>
          <geom class="collision" type="box" pos="0.03133892 -0.08929481 -0.15561497" size="0.010050386190414429 0.002920703962445259 0.00618571974337101" quat="0.95280921459198 -0.30041956901550293 -0.013116598129272461 0.041600536555051804"/>
        </body>
        <body name="Jug001">
          <!-- <joint axis="0.0 0.0 1.0" pos="-0.01632235 0.01660515 0.04915234" limited="true" name="Jug001_joint" range="0.0 0.05" type="slide" damping="1" frictionloss="1" armature=".01" stiffness="0.05"/> -->
          <geom mesh="Jug001_vis" type="mesh" solimp="0.998 0.998 0.001" solref="0.001 1" friction="0.95 0.3 0.1" class="visual" material="Jug001_material"/>
          <geom class="collision" type="box" pos="-0.06454355 -0.01959707 0.08393220" size="0.045629244297742844 0.008825822733342648 0.12603016197681427" quat="0.9212555885314941 0.06958147138357162 -0.028821583837270737 -0.38159650564193726"/>
          <geom class="collision" type="box" pos="-0.01508676 -0.04493246 -0.06207028" size="0.025154929608106613 0.0036438615061342716 0.02311084233224392" quat="1.0 0.0 0.0 0.0"/>
          <geom class="collision" type="box" pos="-0.06107003 0.07443510 0.08395385" size="0.045629244297742844 0.008825824595987797 0.12605208158493042" quat="0.3815966546535492 0.02882159873843193 -0.06958146393299103 -0.9212555289268494"/>
          <geom class="collision" type="box" pos="0.03290795 0.07090272 0.08342756" size="0.045629240572452545 0.008825824595987797 0.12551972270011902" quat="0.38159632682800293 0.02882157266139984 0.06958146393299103 0.9212556481361389"/>
          <geom class="collision" type="box" pos="0.02939798 -0.02298457 0.08310983" size="0.045629244297742844 0.008825824595987797 0.1251983642578125" quat="0.9212555289268494 0.06958146393299103 0.02882159687578678 0.3815966546535492"/>
          <geom class="collision" type="box" pos="-0.06061983 -0.02888154 -0.06207028" size="0.025154929608106613 0.0036438615061342716 0.023110834881663322" quat="0.9397565126419067 0.0 0.0 -0.3418445587158203"/>
          <geom class="collision" type="box" pos="-0.08513130 0.01232006 -0.06207028" size="0.025154927745461464 0.0036438617389649153 0.023110834881663322" quat="0.7679169774055481 0.0 0.0 -0.64054936170578"/>
          <geom class="collision" type="box" pos="-0.07741746 0.06015814 -0.06207028" size="0.025154927745461464 0.0036438615061342716 0.023110834881663322" quat="0.501535177230835 0.0 0.0 -0.8651372790336609"/>
          <geom class="collision" type="box" pos="-0.04175849 0.09134788 -0.06207028" size="0.025154929608106613 0.0036438617389649153 0.023110834881663322" quat="0.1822759509086609 0.0 0.0 -0.9832473993301392"/>
          <geom class="collision" type="box" pos="0.00749289 0.09234687 -0.06207028" size="0.025154929608106613 0.0036438615061342716 0.023110834881663322" quat="0.1721271127462387 0.0 0.0 0.9850747585296631"/>
          <geom class="collision" type="box" pos="0.04495862 0.06168171 -0.06207028" size="0.025154929608106613 0.0036438617389649153 0.023110834881663322" quat="0.4993874430656433 0.0 0.0 0.8663787841796875"/>
          <geom class="collision" type="box" pos="0.05384358 0.01394640 -0.06207028" size="0.02515493333339691 0.003643861971795559 0.023110834881663322" quat="0.7668055891990662 0.0 0.0 0.6418794393539429"/>
          <geom class="collision" type="box" pos="0.02979960 -0.02824716 -0.06207028" size="0.025154931470751762 0.0036438617389649153 0.023110834881663322" quat="0.9407618045806885 0.0 0.0 0.33906814455986023"/>
          <geom class="collision" type="box" pos="-0.09020515 0.02643144 0.08326086" size="0.02850382588803768 0.008825824595987797 0.1265544295310974" quat="0.709650456905365 0.05359915643930435 -0.05290931463241577 -0.700516939163208"/>
          <geom class="collision" type="box" pos="-0.01665352 0.09535334 0.08298609" size="0.02850382775068283 0.008825822733342648 0.12627652287483215" quat="0.03943026438355446 0.00297812232747674 0.07525552809238434 0.9963799715042114"/>
          <geom class="collision" type="box" pos="0.05136751 0.02487786 0.08221428" size="0.02850382775068283 0.008825823664665222 0.12549585103988647" quat="0.6996919512748718 0.0528470017015934 0.05366060510277748 0.7104638814926147"/>
          <geom class="collision" type="box" pos="-0.01955685 -0.04472887 0.08330193" size="0.02850382775068283 0.008825824595987797 0.12659597396850586" quat="0.9962204694747925 0.07524346560239792 0.003268356202170253 0.043272845447063446"/>
          <geom class="collision" type="box" pos="0.11158365 0.02701876 0.07379524" size="0.023755626752972603 0.010479923337697983 0.011317872442305088" quat="0.6425239443778992 0.0 0.7662656307220459 0.0"/>
          <geom class="collision" type="box" pos="0.09651056 0.02701876 0.17049715" size="0.023755624890327454 0.010479923337697983 0.00687967985868454" quat="1.0 0.0 0.0 0.0"/>
          <geom class="collision" type="box" pos="0.11109963 0.02701876 0.13012877" size="0.038404859602451324 0.010479923337697983 0.011317871510982513" quat="0.7342893481254578 0.0 0.6788366436958313 0.0"/>
          <geom class="collision" type="box" pos="0.10175942 0.02705240 0.04725354" size="0.016342977061867714 0.010479924269020557 0.011317871510982513" quat="0.1951066106557846 -1.9346716726431623e-05 0.9807310700416565 -0.00999981164932251"/>
          <geom class="collision" type="box" pos="0.07252684 0.02701976 0.03983370" size="0.023806843906641006 0.010791278444230556 0.011546020396053791" quat="1.0 0.0 0.0 0.0"/>
          <geom class="collision" type="cylinder" pos="-0.01604271 0.02733906 -0.06134024" size="0.07198860496282578 0.023390205577015877" quat="1.0 0.0 0.0 0.0"/>
          <body name="Blade001">
            <joint axis="0.0 0.0 1.0" pos="-0.01633500 0.02565838 -0.01908525" limited="false" name="Blade001_joint" range="0 360" type="hinge" damping="1" frictionloss="1" armature=".01" stiffness="0.05"/>
            <geom mesh="Blade001_vis" type="mesh" solimp="0.998 0.998 0.001" solref="0.001 1" friction="0.95 0.3 0.1" class="visual" material="Blade001_material"/>
            <geom class="collision" type="cylinder" pos="-0.01633884 0.02567838 -0.02440621" size="0.007670124527066946 0.010787472128868103" quat="1.0 0.0 0.0 0.0"/>
            <geom class="collision" type="box" pos="-0.02977562 0.02584977 -0.01657246" size="0.008050992153584957 0.005571782123297453 0.0005175308906473219" quat="0.979388952255249 0.0 -0.20198343694210052 0.0"/>
            <geom class="collision" type="box" pos="-0.04569198 0.02581310 -0.02350581" size="0.009483198635280132 0.003432794939726591 0.0005175308906473219" quat="0.9779711961746216 0.0 -0.20873989164829254 0.0"/>
            <geom class="collision" type="box" pos="0.01213597 0.02581310 -0.02348135" size="0.009483198635280132 0.003432794939726591 0.0005175308906473219" quat="-4.2748478534804235e-08 -0.9779711961746216 -9.124311084462988e-09 0.20873990654945374"/>
            <geom class="collision" type="box" pos="-0.00374394 0.02584977 -0.01642038" size="0.008050991222262383 0.005571782123297453 0.000517530832439661" quat="-4.281045207221723e-08 -0.979388952255249 -8.828975772701142e-09 0.20198342204093933"/>
            <geom class="collision" type="box" pos="-0.01606410 0.05551013 -0.00217943" size="0.009483198635280132 0.003432794939726591 0.0005175308906473219" quat="-0.6829333305358887 -0.18330860137939453 0.18330860137939453 -0.6829333305358887"/>
            <geom class="collision" type="box" pos="-0.01602743 0.04039862 -0.01072601" size="0.008050991222262383 0.005571782123297453 0.000517530832439661" quat="0.6841825246810913 0.17858953773975372 -0.17858952283859253 0.6841826438903809"/>
            <geom class="collision" type="box" pos="-0.01602743 0.01200211 -0.01072601" size="0.008050991222262383 0.005571782123297453 0.000517530832439661" quat="-0.17858955264091492 -0.6841825842857361 -0.6841825246810913 0.17858950793743134"/>
            <geom class="collision" type="box" pos="-0.01606410 -0.00310941 -0.00217943" size="0.009483198635280132 0.003432794939726591 0.0005175308906473219" quat="-0.18330861628055573 -0.6829333901405334 -0.6829333305358887 0.18330857157707214"/>
          </body>
          <body name="Jug001_Clear">
            <geom class="region" name="reg_int" type="box" pos="-0.016219795 0.025428230000000003 0.10080621000000001" size="0.032008365 0.03230699 0.09221367"/>
            <geom mesh="Jug001_Clear_vis" type="mesh" solimp="0.998 0.998 0.001" solref="0.001 1" friction="0.95 0.3 0.1" class="visual" material="Jug001_Clear_material"/>
            <geom class="collision" type="box" pos="-0.06454355 -0.01959707 0.08393220" size="0.045629244297742844 0.008825822733342648 0.12603016197681427" quat="0.9212555885314941 0.06958147138357162 -0.028821583837270737 -0.38159650564193726"/>
            <geom class="collision" type="box" pos="-0.01508676 -0.04493246 -0.06207028" size="0.025154929608106613 0.0036438615061342716 0.02311084233224392" quat="1.0 0.0 0.0 0.0"/>
            <geom class="collision" type="box" pos="-0.06107003 0.07443510 0.08395385" size="0.045629244297742844 0.008825824595987797 0.12605208158493042" quat="0.3815966546535492 0.02882159873843193 -0.06958146393299103 -0.9212555289268494"/>
            <geom class="collision" type="box" pos="0.03290795 0.07090272 0.08342756" size="0.045629240572452545 0.008825824595987797 0.12551972270011902" quat="0.38159632682800293 0.02882157266139984 0.06958146393299103 0.9212556481361389"/>
            <geom class="collision" type="box" pos="0.02939798 -0.02298457 0.08310983" size="0.045629244297742844 0.008825824595987797 0.1251983642578125" quat="0.9212555289268494 0.06958146393299103 0.02882159687578678 0.3815966546535492"/>
            <geom class="collision" type="box" pos="-0.06061983 -0.02888154 -0.06207028" size="0.025154929608106613 0.0036438615061342716 0.023110834881663322" quat="0.9397565126419067 0.0 0.0 -0.3418445587158203"/>
            <geom class="collision" type="box" pos="-0.08513130 0.01232006 -0.06207028" size="0.025154927745461464 0.0036438617389649153 0.023110834881663322" quat="0.7679169774055481 0.0 0.0 -0.64054936170578"/>
            <geom class="collision" type="box" pos="-0.07741746 0.06015814 -0.06207028" size="0.025154927745461464 0.0036438615061342716 0.023110834881663322" quat="0.501535177230835 0.0 0.0 -0.8651372790336609"/>
            <geom class="collision" type="box" pos="-0.04175849 0.09134788 -0.06207028" size="0.025154929608106613 0.0036438617389649153 0.023110834881663322" quat="0.1822759509086609 0.0 0.0 -0.9832473993301392"/>
            <geom class="collision" type="box" pos="0.00749289 0.09234687 -0.06207028" size="0.025154929608106613 0.0036438615061342716 0.023110834881663322" quat="0.1721271127462387 0.0 0.0 0.9850747585296631"/>
            <geom class="collision" type="box" pos="0.04495862 0.06168171 -0.06207028" size="0.025154929608106613 0.0036438617389649153 0.023110834881663322" quat="0.4993874430656433 0.0 0.0 0.8663787841796875"/>
            <geom class="collision" type="box" pos="0.05384358 0.01394640 -0.06207028" size="0.02515493333339691 0.003643861971795559 0.023110834881663322" quat="0.7668055891990662 0.0 0.0 0.6418794393539429"/>
            <geom class="collision" type="box" pos="0.02979960 -0.02824716 -0.06207028" size="0.025154931470751762 0.0036438617389649153 0.023110834881663322" quat="0.9407618045806885 0.0 0.0 0.33906814455986023"/>
            <geom class="collision" type="box" pos="-0.09020515 0.02643144 0.08326086" size="0.02850382588803768 0.008825824595987797 0.1265544295310974" quat="0.709650456905365 0.05359915643930435 -0.05290931463241577 -0.700516939163208"/>
            <geom class="collision" type="box" pos="-0.01665352 0.09535334 0.08298609" size="0.02850382775068283 0.008825822733342648 0.12627652287483215" quat="0.03943026438355446 0.00297812232747674 0.07525552809238434 0.9963799715042114"/>
            <geom class="collision" type="box" pos="0.05136751 0.02487786 0.08221428" size="0.02850382775068283 0.008825823664665222 0.12549585103988647" quat="0.6996919512748718 0.0528470017015934 0.05366060510277748 0.7104638814926147"/>
            <geom class="collision" type="box" pos="-0.01955685 -0.04472887 0.08330193" size="0.02850382775068283 0.008825824595987797 0.12659597396850586" quat="0.9962204694747925 0.07524346560239792 0.003268356202170253 0.043272845447063446"/>
            <geom class="collision" type="box" pos="0.11158365 0.02701876 0.07379524" size="0.023755626752972603 0.010479923337697983 0.011317872442305088" quat="0.6425239443778992 0.0 0.7662656307220459 0.0"/>
            <geom class="collision" type="box" pos="0.09651056 0.02701876 0.17049715" size="0.023755624890327454 0.010479923337697983 0.00687967985868454" quat="1.0 0.0 0.0 0.0"/>
            <geom class="collision" type="box" pos="0.11109963 0.02701876 0.13012877" size="0.038404859602451324 0.010479923337697983 0.011317871510982513" quat="0.7342893481254578 0.0 0.6788366436958313 0.0"/>
            <geom class="collision" type="box" pos="0.10175942 0.02705240 0.04725354" size="0.016342977061867714 0.010479924269020557 0.011317871510982513" quat="0.1951066106557846 -1.9346716726431623e-05 0.9807310700416565 -0.00999981164932251"/>
            <geom class="collision" type="box" pos="0.07252684 0.02701976 0.03983370" size="0.023806843906641006 0.010791278444230556 0.011546020396053791" quat="1.0 0.0 0.0 0.0"/>
          </body>
        </body>
        <body name="Knob001">
          <joint axis="0.0 0.8386704921722412 -0.5446390509605408" pos="-0.01640366 -0.10047842 -0.14891277" limited="true" name="Knob001_joint" range="0.0 3.141592653589793" type="hinge" damping="0.05" frictionloss="0.1" armature="0.001"/>
          <geom mesh="Knob001_vis" type="mesh" solimp="0.998 0.998 0.001" solref="0.001 1" friction="0.95 0.3 0.1" class="visual" material="Knob001_material"/>
          <geom class="collision" type="cylinder" pos="-0.01638245 -0.09661132 -0.15119193" size="0.018016861751675606 0.0032423920929431915" quat="0.8788171410560608 0.4771587550640106 -1.5054356276220082e-16 -4.4593038816215255e-17" density="0.001"/>
          <geom class="collision" type="box" pos="-0.01634084 -0.10449058 -0.14611432" size="0.005413155537098646 0.005655909422785044 0.015304354019463062" quat="0.9588197469711304 -0.28401532769203186 5.934630009640784e-10 -1.7668519980418296e-09" density="0.001"/>
        </body>
        <geom class="region" name="reg_main" type="box" pos="-0.020306625000000002 0.003472349999999999 0.0" size="0.105475765 0.11412227 0.25050263"/>
      </body>
      <site rgba="0 1 0 0" size="0.005" pos="-0.0123983 0.02445243 0.21466948" name="anchor_site"/>
    </body>
  </worldbody>
  <actuator>
    <motor name="Button001_joint_actuator" joint="Button001_joint" gear="0.1"/>
    <motor name="Button002_joint_actuator" joint="Button002_joint" gear="0.1"/>
    <!-- <motor name="Jug001_joint_actuator" joint="Jug001_joint" gear="200"/> -->
    <motor name="Knob001_joint_actuator" joint="Knob001_joint" gear="10"/>
    <motor name="Blade001_joint_actuator" joint="Blade001_joint" gear="10"/>
    <!-- <motor name="Lid001_joint_actuator" joint="Lid001_joint" gear="50"/> -->
  </actuator>
</mujoco>
