<?xml version='1.0' encoding='UTF-8'?>
<mujoco model="model">
  <option timestep="0.002" gravity="0.0 0.0 -9.81"/>
  <compiler angle="radian"/>
  <asset>
    <mesh file="visuals/Blade001.obj" name="Blade001_vis"/>
    <mesh file="visuals/Body001.obj" name="Body001_vis"/>
    <mesh file="visuals/Button001.obj" name="Button001_vis"/>
    <mesh file="visuals/Jug001.obj" name="Jug001_vis"/>
    <mesh file="visuals/Jug001_Clear.obj" name="Jug001_Clear_vis"/>
    <mesh file="visuals/Knob001.obj" name="Knob001_vis"/>
    <mesh file="visuals/Lid001.obj" name="Lid001_vis"/>
    <texture file="visuals/T_BC001.png" name="Body001_material" type="2d"/>
    <material name="Body001_material" rgba="1 1 1 1.0" texture="Body001_material" shininess="0.7126775979995728" specular="0.3103448502657381"/>
    <texture file="visuals/T_BC001.png" name="Button001_material" type="2d"/>
    <material name="Button001_material" rgba="1 1 1 1.0" texture="Button001_material" shininess="0.7126775979995728" specular="0.3103448502657381"/>
    <texture file="visuals/T_BC001.png" name="Jug001_material" type="2d"/>
    <material name="Jug001_material" rgba="1 1 1 1.0" texture="Jug001_material" shininess="0.7126775979995728" specular="0.3103448502657381"/>
    <texture file="visuals/T_BC001.png" name="Blade001_material" type="2d"/>
    <material name="Blade001_material" rgba="1 1 1 1.0" texture="Blade001_material" shininess="0.7126775979995728" specular="0.3103448502657381"/>
    <texture file="visuals/T_BC001.png" name="Jug001_Clear_material" type="2d"/>
    <material name="Jug001_Clear_material" rgba="1 1 1 0.800000011920929" texture="Jug001_Clear_material" shininess="0.8092784583568573" specular="0.3103448502657381"/>
    <texture file="visuals/T_BC001.png" name="Lid001_material" type="2d"/>
    <material name="Lid001_material" rgba="1 1 1 1.0" texture="Lid001_material" shininess="0.7126775979995728" specular="0.3103448502657381"/>
    <texture file="visuals/T_BC001.png" name="Knob001_material" type="2d"/>
    <material name="Knob001_material" rgba="1 1 1 1.0" texture="Knob001_material" shininess="0.7126775979995728" specular="0.3103448502657381"/>
  </asset>
  <default>
    <default class="visual">
      <geom conaffinity="0" contype="0" group="1" type="mesh"/>
    </default>
    <default class="collision">
      <geom group="0" rgba="0.5 0 0 0.5"/>
    </default>
    <default class="spawn">
      <geom group="0" rgba="1 1 1 0.5" contype="0" conaffinity="0"/>
      <site group="0" rgba="1 1 1 0.5"/>
    </default>
    <default class="region">
      <geom group="1" conaffinity="0" contype="0" rgba="0 1 0 0"/>
    </default>
  </default>
  <worldbody>
    <body>
      <body name="object">
        <geom mesh="Body001_vis" type="mesh" solimp="0.998 0.998 0.001" solref="0.001 1" friction="0.95 0.3 0.1" class="visual" material="Body001_material"/>
        <geom class="collision" type="box" pos="-0.06414317 0.00293150 -0.08131555" size="0.003986308351159096 0.015745818614959717 0.054941773414611816" quat="0.9969801902770996 0.002991716144606471 0.05849111080169678 0.05099374055862427"/>
        <geom class="collision" type="box" pos="-0.05898194 0.03102392 -0.08121618" size="0.003986308351159096 0.015745816752314568 0.054941773414611816" quat="0.9726268649101257 0.021922767162322998 0.05430987477302551 -0.22487075626850128"/>
        <geom class="collision" type="box" pos="-0.03821645 0.05216332 -0.08130155" size="0.003986308351159096 0.01574581488966942 0.054941773414611816" quat="0.886173665523529 0.020056521520018578 0.0385282076895237 -0.4613128900527954"/>
        <geom class="collision" type="box" pos="-0.01100860 0.06139588 -0.08139399" size="0.002653482835739851 0.015745816752314568 0.054941773414611816" quat="0.7362769842147827 0.0351811945438385 0.038393545895814896 -0.6746735572814941"/>
        <geom class="collision" type="box" pos="0.01633125 0.05513551 -0.08116253" size="0.0021790468599647284 0.01574581488966942 0.054941777139902115" quat="0.49935898184776306 0.04383734613656998 0.025309504941105843 -0.8649151921272278"/>
        <geom class="collision" type="box" pos="0.03545922 0.03712036 -0.08134439" size="0.0018078562570735812 0.01574581488966942 0.054941773414611816" quat="0.30036523938179016 0.045378535985946655 0.014307779259979725 -0.9526367783546448"/>
        <geom class="collision" type="box" pos="0.04363298 0.01003369 -0.08086122" size="0.0026048512663692236 0.015745816752314568 0.054941773414611816" quat="7.540232616065623e-08 0.05030030384659767 3.797567593721851e-09 -0.9987341165542603"/>
        <geom class="collision" type="box" pos="0.03481350 -0.01944534 -0.08094111" size="0.0027222405187785625 0.015745816752314568 0.054941777139902115" quat="0.30034273862838745 -0.04684454947710037 0.01477002538740635 0.9525658488273621"/>
        <geom class="collision" type="box" pos="0.02587351 -0.03571680 -0.08130847" size="0.0014966638991609216 0.008354835212230682 0.05494178086519241" quat="0.4205015301704407 -0.04792412742972374 0.03366672620177269 0.9053995013237"/>
        <geom class="collision" type="box" pos="-0.05438795 -0.02428223 -0.08246415" size="0.003986308351159096 0.01574581488966942 0.054941773414611816" quat="0.9343163371086121 0.02062777802348137 0.05481475219130516 0.35160043835639954"/>
        <geom class="collision" type="box" pos="-0.03554909 -0.03983053 -0.07036536" size="0.003986308351159096 0.012453826144337654 0.04198986291885376" quat="0.8163965344429016 -0.016887996345758438 0.04775163158774376 0.5752662420272827"/>
        <geom class="collision" type="box" pos="0.00839477 -0.04297458 -0.08388708" size="0.002096703043207526 0.012412848882377148 0.04728870466351509" quat="0.560683012008667 -0.040940262377262115 0.030546532943844795 0.8264535069465637"/>
        <geom class="collision" type="box" pos="-0.04175205 -0.04451987 -0.12138034" size="0.0035907153505831957 0.010427257977426052 0.014271192252635956" quat="0.8109872341156006 0.0060891201719641685 0.05432721972465515 0.5825042128562927"/>
        <geom class="collision" type="box" pos="-0.02215584 -0.05125855 -0.12474555" size="0.003590715117752552 0.010427256114780903 0.010370254516601562" quat="0.8053919076919556 -0.005206680856645107 0.04405323788523674 0.5910804271697998"/>
        <geom class="collision" type="box" pos="-0.00340873 -0.05103144 -0.12598403" size="0.003590715816244483 0.010427255183458328 0.008998429402709007" quat="0.6632282137870789 -0.057456206530332565 0.01936173252761364 0.7459572553634644"/>
        <geom class="collision" type="box" pos="0.01315517 -0.04063753 -0.08596016" size="0.003590715117752552 0.010427254252135754 0.05563155561685562" quat="0.5456677079200745 -0.05234862118959427 0.011771116405725479 0.8362821340560913"/>
        <geom class="collision" type="cylinder" pos="-0.01079778 0.00852986 -0.13985953" size="0.05258236825466156 0.004347818437963724" quat="1.0 0.0 0.0 0.0"/>
        <geom class="collision" type="cylinder" pos="-0.01079778 0.00852986 -0.14579666" size="0.06486986577510834 0.0016201762482523918" quat="1.0 0.0 0.0 0.0"/>
        <geom class="collision" type="cylinder" pos="-0.01113476 0.00702684 -0.02817565" size="0.049913439899683 0.01324945967644453" quat="1.0 0.0 0.0 0.0"/>
        <geom class="collision" type="box" pos="-0.00909902 -0.04518037 -0.07987407" size="0.003590715117752552 0.015328536741435528 0.04948468133807182" quat="0.70053631067276 -0.018481511622667313 0.03286641836166382 0.7126199007034302"/>
        <body name="Button001">
          <joint axis="-0.0747469961643219 0.992827296257019 -0.09331010282039642" pos="-0.01069985 -0.04866998 -0.05617259" limited="true" name="Button001_joint" range="0.0 0.0015" type="slide" damping="1" frictionloss="1" armature=".01" stiffness="0.1" springref="-0.1"/>
          <geom mesh="Button001_vis" type="mesh" solimp="0.998 0.998 0.001" solref="0.001 1" friction="0.95 0.3 0.1" class="visual" material="Button001_material"/>
          <geom class="collision" type="cylinder" pos="-0.01073571 -0.04942436 -0.05600203" size="0.0033137896098196507 0.0009123445488512516" quat="0.7030347585678101 0.6229007840156555 -0.2200489640235901 0.26327773928642273"/>
        </body>
        <body name="Jug001">
          <!-- <joint axis="0.0 0.0 1.0" pos="-0.00974239 0.00680789 0.00393738" limited="true" name="Jug001_joint" range="0.0 0.05" type="slide" damping="1" frictionloss="1" armature=".01" stiffness="0.05"/> -->
          <geom mesh="Jug001_vis" type="mesh" solimp="0.998 0.998 0.001" solref="0.001 1" friction="0.95 0.3 0.1" class="visual" material="Jug001_material"/>
          <geom class="collision" type="cylinder" pos="-0.01116147 0.00577703 0.00309759" size="0.00906098261475563 0.008652156218886375" quat="1.0 0.0 0.0 0.0"/>
          <geom class="collision" type="box" pos="-0.05201297 -0.00544804 0.06401412" size="0.0011411537416279316 0.008665076456964016 0.04689289629459381" quat="0.9886313080787659 -0.0007852297276258469 -0.022206872701644897 0.14870889484882355"/>
          <geom class="collision" type="box" pos="-0.04462621 -0.01957276 0.06363554" size="0.0013928755652159452 0.007175058592110872 0.047899119555950165" quat="0.9493206143379211 -0.010618006810545921 -0.024758541956543922 0.31315281987190247"/>
          <geom class="collision" type="box" pos="-0.03491062 -0.02905723 0.06356143" size="0.0009027808555401862 0.007999305613338947 0.046975307166576385" quat="0.8626777529716492 0.00400641979649663 -0.025761157274246216 0.5050815939903259"/>
          <geom class="collision" type="box" pos="0.00641023 -0.03413283 0.06730504" size="0.0010227970778942108 0.00639775674790144 0.04582451283931732" quat="0.49985271692276 0.00337212230078876 -0.0017554215155541897 0.8661020994186401"/>
          <geom class="collision" type="box" pos="0.01845595 -0.02742273 0.06795305" size="0.0007466371753253043 0.007702946662902832 0.04582451656460762" quat="0.4149072468280792 -0.003698088228702545 0.0005286823725327849 0.9098560214042664"/>
          <geom class="collision" type="box" pos="0.03522604 0.00574075 0.06760135" size="0.0034557972103357315 0.014141874387860298 0.04613758996129036" quat="1.0 0.0 0.0 0.0"/>
          <geom class="collision" type="box" pos="0.01651037 0.04200349 0.06642398" size="0.0007405881187878549 0.005810028873383999 0.04582451283931732" quat="0.4493381381034851 0.004741608630865812 -0.01437248196452856 -0.8932335376739502"/>
          <geom class="collision" type="box" pos="0.00408397 0.04678640 0.06605563" size="0.0008923254208639264 0.007550706155598164 0.04582451283931732" quat="0.6081756353378296 0.001975441351532936 -0.015004957094788551 -0.7936581969261169"/>
          <geom class="collision" type="box" pos="-0.03599252 0.04240891 0.06529191" size="0.0009781541302800179 0.006452578119933605 0.04582451283931732" quat="0.8918564915657043 -0.004716404248028994 -0.014380785636603832 -0.45206522941589355"/>
          <geom class="collision" type="box" pos="-0.04469908 0.03284545 0.06531050" size="0.0011494028149172664 0.007025028578937054 0.04582451656460762" quat="0.9534119963645935 -0.006988314911723137 -0.013424396514892578 -0.30129143595695496"/>
          <geom class="collision" type="box" pos="0.06357763 0.00620615 0.07631346" size="0.005088288802653551 0.009546133689582348 0.023384999483823776" quat="0.9961947202682495 0.0 -0.08715573698282242 0.0"/>
          <geom class="collision" type="box" pos="0.05218959 0.00616715 0.10434674" size="0.007519893813878298 0.008824963122606277 0.01210277620702982" quat="0.7518044114112854 -0.00046680914238095284 0.6593855023384094 0.0008093591895885766"/>
          <geom class="collision" type="box" pos="0.05194099 0.00657414 0.03293036" size="0.0033454347867518663 0.009491372853517532 0.016489258036017418" quat="0.843391478061676 0.0 0.5372995734214783 0.0"/>
          <geom class="collision" type="cylinder" pos="-0.00994867 0.00754640 0.01852010" size="0.04288448393344879 0.0013050753623247147" quat="1.0 0.0 0.0 0.0"/>
          <geom class="collision" type="cylinder" pos="-0.01113476 0.00702684 -0.00106360" size="0.04508111625909805 0.01324945967644453" quat="1.0 0.0 0.0 0.0"/>
          <geom class="collision" type="box" pos="0.06706209 0.00668775 0.04700918" size="0.004980669356882572 0.009491369128227234 0.008270477876067162" quat="0.9994047284126282 0.007976317778229713 0.033564552664756775 -0.0002168510400224477"/>
          <geom class="collision" type="box" pos="-0.00497821 -0.03502184 0.06734587" size="0.001022796961478889 0.006397756282240152 0.04582451283931732" quat="0.6432011723518372 0.003626530757173896 -0.001140607870183885 0.7656878232955933"/>
          <geom class="collision" type="box" pos="-0.01869681 -0.03497289 0.06361109" size="0.0010227971943095326 0.008234738372266293 0.04582451283931732" quat="0.7698814272880554 0.0037721358239650726 -0.0004729771171696484 0.6381756067276001"/>
          <geom class="collision" type="box" pos="-0.05242275 0.02184720 0.06538087" size="0.0011494026985019445 0.007025028113275766 0.04582451656460762" quat="0.9765552878379822 -0.00816198717802763 -0.012744918465614319 -0.2147340178489685"/>
          <geom class="collision" type="box" pos="-0.05422102 0.00973624 0.06560187" size="0.0011494028149172664 0.007025029044598341 0.04582451656460762" quat="0.9976705312728882 -0.009973456151783466 -0.011383378878235817 -0.06651640683412552"/>
          <geom class="collision" type="box" pos="-0.02339473 0.04737251 0.06545511" size="0.0009781541302800179 0.006452578119933605 0.04582451283931732" quat="0.7688629031181335 -0.0013972119195386767 -0.015069808810949326 -0.6392345428466797"/>
          <geom class="collision" type="box" pos="-0.01078633 0.04971658 0.06567467" size="0.000978154013864696 0.006452578119933605 0.04582451283931732" quat="0.7119560837745667 -0.00011576183896977454 -0.015133999288082123 -0.702060878276825"/>
          <geom class="collision" type="box" pos="0.02234555 0.03313158 0.06549271" size="0.000740588060580194 0.005810028873383999 0.04582451283931732" quat="0.3184846043586731 0.006726743653416634 -0.01355736143887043 -0.9478071928024292"/>
          <geom class="collision" type="box" pos="0.03010196 0.02289193 0.06587805" size="0.0007405880023725331 0.005810028873383999 0.04582451283931732" quat="0.1984029859304428 0.008357168175280094 -0.012617817148566246 -0.9800036549568176"/>
          <geom class="collision" type="box" pos="0.02824378 -0.01489266 0.06796412" size="0.0007466371171176434 0.00865502841770649 0.04582451283931732" quat="0.23986472189426422 -0.0035369955003261566 0.0012020895956084132 0.9707991480827332"/>
          <body name="Blade001">
            <joint axis="0.0 0.0 1.0" pos="-0.01134515 0.00675489 0.02532513" limited="false" name="Blade001_joint" range="0 360" type="hinge" damping="1" frictionloss="1" armature=".01" stiffness="0.05"/>
            <geom mesh="Blade001_vis" type="mesh" solimp="0.998 0.998 0.001" solref="0.001 1" friction="0.95 0.3 0.1" class="visual" material="Blade001_material"/>
            <geom class="collision" type="box" pos="-0.01133486 0.00447850 0.02316258" size="0.0030732648447155952 0.020795876160264015 0.0011587267508730292" quat="1.0 0.0 0.0 0.0"/>
            <geom class="collision" type="box" pos="-0.02736820 0.00661103 0.02573356" size="0.0030642191413789988 0.010015010833740234 0.0011587272165343165" quat="0.6698104739189148 -0.09623399376869202 0.08818221837282181 -0.7309697866439819"/>
            <geom class="collision" type="box" pos="0.00365382 0.00661103 0.02564197" size="0.0030642191413789988 0.010015010833740234 0.0011587273329496384" quat="0.6653264760971069 0.12802685797214508 -0.11731503903865814 -0.7260764241218567"/>
          </body>
          <body name="Jug001_Clear">
            <geom class="region" name="reg_int" type="box" pos="-0.009254010000000002 0.00609284 0.071523825" size="0.024752170000000004 0.024752170000000004 0.04180228500000001"/>
            <geom mesh="Jug001_Clear_vis" type="mesh" solimp="0.998 0.998 0.001" solref="0.001 1" friction="0.95 0.3 0.1" class="visual" material="Jug001_Clear_material"/>
            <geom class="collision" type="box" pos="-0.05201297 -0.00544804 0.06401412" size="0.0011411537416279316 0.008665076456964016 0.04689289629459381" quat="0.9886313080787659 -0.0007852297276258469 -0.022206872701644897 0.14870889484882355"/>
            <geom class="collision" type="box" pos="-0.04462621 -0.01957276 0.06363554" size="0.0013928755652159452 0.007175058592110872 0.047899119555950165" quat="0.9493206143379211 -0.010618006810545921 -0.024758541956543922 0.31315281987190247"/>
            <geom class="collision" type="box" pos="-0.03491062 -0.02905723 0.06356143" size="0.0009027808555401862 0.007999305613338947 0.046975307166576385" quat="0.8626777529716492 0.00400641979649663 -0.025761157274246216 0.5050815939903259"/>
            <geom class="collision" type="box" pos="0.00641023 -0.03413283 0.06730504" size="0.0010227970778942108 0.00639775674790144 0.04582451283931732" quat="0.49985271692276 0.00337212230078876 -0.0017554215155541897 0.8661020994186401"/>
            <geom class="collision" type="box" pos="0.01845595 -0.02742273 0.06795305" size="0.0007466371753253043 0.007702946662902832 0.04582451656460762" quat="0.4149072468280792 -0.003698088228702545 0.0005286823725327849 0.9098560214042664"/>
            <geom class="collision" type="box" pos="0.03522604 0.00574075 0.06760135" size="0.0034557972103357315 0.014141874387860298 0.04613758996129036" quat="1.0 0.0 0.0 0.0"/>
            <geom class="collision" type="box" pos="0.01651037 0.04200349 0.06642398" size="0.0007405881187878549 0.005810028873383999 0.04582451283931732" quat="0.4493381381034851 0.004741608630865812 -0.01437248196452856 -0.8932335376739502"/>
            <geom class="collision" type="box" pos="0.00408397 0.04678640 0.06605563" size="0.0008923254208639264 0.007550706155598164 0.04582451283931732" quat="0.6081756353378296 0.001975441351532936 -0.015004957094788551 -0.7936581969261169"/>
            <geom class="collision" type="box" pos="-0.03599252 0.04240891 0.06529191" size="0.0009781541302800179 0.006452578119933605 0.04582451283931732" quat="0.8918564915657043 -0.004716404248028994 -0.014380785636603832 -0.45206522941589355"/>
            <geom class="collision" type="box" pos="-0.04469908 0.03284545 0.06531050" size="0.0011494028149172664 0.007025028578937054 0.04582451656460762" quat="0.9534119963645935 -0.006988314911723137 -0.013424396514892578 -0.30129143595695496"/>
            <geom class="collision" type="box" pos="0.06357763 0.00620615 0.07631346" size="0.005088288802653551 0.009546133689582348 0.023384999483823776" quat="0.9961947202682495 0.0 -0.08715573698282242 0.0"/>
            <geom class="collision" type="box" pos="0.05218959 0.00616715 0.10434674" size="0.007519893813878298 0.008824963122606277 0.01210277620702982" quat="0.7518044114112854 -0.00046680914238095284 0.6593855023384094 0.0008093591895885766"/>
            <geom class="collision" type="box" pos="0.05194099 0.00657414 0.03293036" size="0.0033454347867518663 0.009491372853517532 0.016489258036017418" quat="0.843391478061676 0.0 0.5372995734214783 0.0"/>
            <geom class="collision" type="cylinder" pos="-0.00994867 0.00754640 0.01852010" size="0.04288448393344879 0.0013050753623247147" quat="1.0 0.0 0.0 0.0"/>
            <geom class="collision" type="box" pos="0.06706209 0.00668775 0.04700918" size="0.004980669356882572 0.009491369128227234 0.008270477876067162" quat="0.9994047284126282 0.007976317778229713 0.033564552664756775 -0.0002168510400224477"/>
            <geom class="collision" type="box" pos="-0.00497821 -0.03502184 0.06734587" size="0.001022796961478889 0.006397756282240152 0.04582451283931732" quat="0.6432011723518372 0.003626530757173896 -0.001140607870183885 0.7656878232955933"/>
            <geom class="collision" type="box" pos="-0.01869681 -0.03497289 0.06361109" size="0.0010227971943095326 0.008234738372266293 0.04582451283931732" quat="0.7698814272880554 0.0037721358239650726 -0.0004729771171696484 0.6381756067276001"/>
            <geom class="collision" type="box" pos="-0.05242275 0.02184720 0.06538087" size="0.0011494026985019445 0.007025028113275766 0.04582451656460762" quat="0.9765552878379822 -0.00816198717802763 -0.012744918465614319 -0.2147340178489685"/>
            <geom class="collision" type="box" pos="-0.05422102 0.00973624 0.06560187" size="0.0011494028149172664 0.007025029044598341 0.04582451656460762" quat="0.9976705312728882 -0.009973456151783466 -0.011383378878235817 -0.06651640683412552"/>
            <geom class="collision" type="box" pos="-0.02339473 0.04737251 0.06545511" size="0.0009781541302800179 0.006452578119933605 0.04582451283931732" quat="0.7688629031181335 -0.0013972119195386767 -0.015069808810949326 -0.6392345428466797"/>
            <geom class="collision" type="box" pos="-0.01078633 0.04971658 0.06567467" size="0.000978154013864696 0.006452578119933605 0.04582451283931732" quat="0.7119560837745667 -0.00011576183896977454 -0.015133999288082123 -0.702060878276825"/>
            <geom class="collision" type="box" pos="0.02234555 0.03313158 0.06549271" size="0.000740588060580194 0.005810028873383999 0.04582451283931732" quat="0.3184846043586731 0.006726743653416634 -0.01355736143887043 -0.9478071928024292"/>
            <geom class="collision" type="box" pos="0.03010196 0.02289193 0.06587805" size="0.0007405880023725331 0.005810028873383999 0.04582451283931732" quat="0.1984029859304428 0.008357168175280094 -0.012617817148566246 -0.9800036549568176"/>
            <geom class="collision" type="box" pos="0.02824378 -0.01489266 0.06796412" size="0.0007466371171176434 0.00865502841770649 0.04582451283931732" quat="0.23986472189426422 -0.0035369955003261566 0.0012020895956084132 0.9707991480827332"/>
          </body>
        </body>
        <body name="Knob001">
          <joint axis="0.0 1.0 0.0" pos="-0.01099387 -0.05696104 -0.09707736" limited="true" name="Knob001_joint" range="0.0 4.1887902047863905" type="hinge" damping="0.05" frictionloss="0.1" armature="0.001"/>
          <geom mesh="Knob001_vis" type="mesh" solimp="0.998 0.998 0.001" solref="0.001 1" friction="0.95 0.3 0.1" class="visual" material="Knob001_material"/>
          <geom class="collision" type="cylinder" pos="-0.01121220 -0.05481474 -0.09766724" size="0.01372851338237524 0.0028194477781653404" quat="0.7071067094802856 0.7071068286895752 0.0 0.0" density="0.001"/>
          <geom class="collision" type="box" pos="-0.01058615 -0.06368847 -0.09685497" size="0.003505827160552144 0.00607439037412405 0.011031357571482658" quat="0.5197781324386597 -3.226090683483562e-08 -0.8543012738227844 -5.751893183969514e-08" density="0.001"/>
        </body>
        <geom class="region" name="reg_main" type="box" pos="-0.010925574999999996 0.006807835000000002 0.0" size="0.064281375 0.064282685 0.14836363"/>
      </body>
      <site rgba="0 1 0 0" size="0.005" pos="-0.00489641 0.00664501 0.12470886" name="anchor_site"/>
    </body>
  </worldbody>
  <actuator>
    <motor name="Button001_joint_actuator" joint="Button001_joint" gear="0.1"/>
    <!-- <motor name="Jug001_joint_actuator" joint="Jug001_joint" gear="10"/> -->
    <motor name="Knob001_joint_actuator" joint="Knob001_joint" gear="10"/>
    <motor name="Blade001_joint_actuator" joint="Blade001_joint" gear="10"/>
    <!-- <motor name="Lid001_joint_actuator" joint="Lid001_joint" gear="10"/> -->
  </actuator>
</mujoco>
