<?xml version='1.0' encoding='UTF-8'?>
<mujoco model="model">
  <option timestep="0.0005" gravity="0.0 0.0 -9.81"/>
  <compiler angle="radian"/>
  <asset>
    <mesh file="visuals/Blade001.obj" name="Blade001_vis"/>
    <mesh file="visuals/Body001.obj" name="Body001_vis"/>
    <mesh file="visuals/Button001.obj" name="Button001_vis"/>
    <mesh file="visuals/Jug001.obj" name="Jug001_vis"/>
    <mesh file="visuals/Jug001_Clear.obj" name="Jug001_Clear_vis"/>
    <mesh file="visuals/Knob001.obj" name="Knob001_vis"/>
    <mesh file="visuals/Lid001.obj" name="Lid001_vis"/>
    <texture file="visuals/T_BC001.png" name="Body001_material" type="2d"/>
    <material name="Body001_material" rgba="1 1 1 1.0" texture="Body001_material" shininess="0.4472135901451111" specular="0.3103448502657381"/>
    <texture file="visuals/T_BC001.png" name="Button001_material" type="2d"/>
    <material name="Button001_material" rgba="1 1 1 1.0" texture="Button001_material" shininess="0.4472135901451111" specular="0.3103448502657381"/>
    <texture file="visuals/T_BC001.png" name="Jug001_Clear_material" type="2d"/>
    <material name="Jug001_Clear_material" rgba="1 1 1 0.699999988079071" texture="Jug001_Clear_material" shininess="0.4472135901451111" specular="0.3103448502657381"/>
    <texture file="visuals/T_BC001.png" name="Blade001_material" type="2d"/>
    <material name="Blade001_material" rgba="1 1 1 1.0" texture="Blade001_material" shininess="0.4472135901451111" specular="5"/>
    <texture file="visuals/T_BC001.png" name="Jug001_material" type="2d"/>
    <material name="Jug001_material" rgba="1 1 1 1.0" texture="Jug001_material" shininess="0.4472135901451111" specular="0.3103448502657381"/>
    <texture file="visuals/T_BC001.png" name="Knob001_material" type="2d"/>
    <material name="Knob001_material" rgba="1 1 1 1.0" texture="Knob001_material" shininess="0.4472135901451111" specular="0.3103448502657381"/>
    <texture file="visuals/T_BC001.png" name="Lid001_material" type="2d"/>
    <material name="Lid001_material" rgba="1 1 1 1.0" texture="Lid001_material" shininess="0.4472135901451111" specular="0.3103448502657381"/>
  </asset>
  <default>
    <default class="visual">
      <geom conaffinity="0" contype="0" group="1" type="mesh"/>
    </default>
    <default class="collision">
      <geom group="0" rgba="0.5 0 0 0.5"/>
    </default>
    <default class="spawn">
      <geom group="0" rgba="1 1 1 0.5" contype="0" conaffinity="0"/>
      <site group="0" rgba="1 1 1 0.5"/>
    </default>
    <default class="region">
      <geom group="1" conaffinity="0" contype="0" rgba="0 1 0 0"/>
    </default>
  </default>
  <worldbody>
    <body>
      <body name="object">
        <geom mesh="Body001_vis" type="mesh" solimp="0.998 0.998 0.001" solref="0.001 1" friction="0.95 0.3 0.1" class="visual" material="Body001_material"/>
        <geom class="collision" type="box" pos="-0.03150521 0.01790235 -0.15448266" size="0.09086184948682785 0.08694292604923248 0.12657050788402557" quat="1.0 0.0 0.0 0.0"/>
        <body name="Button001">
          <joint axis="0.0 1.0 0.0" pos="-0.03199682 -0.07664007 -0.08264117" limited="true" name="Button001_joint" range="0.0 0.005" type="slide" damping="1" frictionloss="1" armature=".01" stiffness="0.05"/>
          <geom mesh="Button001_vis" type="mesh" solimp="0.998 0.998 0.001" solref="0.001 1" friction="0.95 0.3 0.1" class="visual" material="Button001_material"/>
          <geom class="collision" type="box" pos="-0.03208427 -0.08243477 -0.06164037" size="0.012408987618982792 0.006734694819897413 0.008026663213968277" quat="1.0 0.0 0.0 0.0"/>
        </body>
        <body name="Jug001_Clear">
          <geom class="region" name="reg_int" type="box" pos="-0.032130729999999996 0.009665190000000004 0.13343475" size="0.06979121 0.0672799 0.08648693"/>
          <!-- <joint axis="0.0 0.0 1.0" pos="0.00048447 0.01028055 0.10387684" limited="true" name="Jug001_Clear_joint" range="0.0 0.05" type="slide" damping="1" frictionloss="1" armature=".01" stiffness="0.05"/> -->
          <geom mesh="Jug001_Clear_vis" type="mesh" solimp="0.998 0.998 0.001" solref="0.001 1" friction="0.95 0.3 0.1" class="visual" material="Jug001_Clear_material"/>
          <geom class="collision" type="box" pos="-0.03396280 0.10241802 0.11139487" size="0.056509215384721756 0.008711088448762894 0.12795716524124146" quat="1.0 0.0 0.0 0.0"/>
          <geom class="collision" type="box" pos="-0.11034779 0.08306386 0.11139487" size="0.032513655722141266 0.008711197413504124 0.12795889377593994" quat="0.933960497379303 0.0 0.0 0.35737624764442444"/>
          <geom class="collision" type="box" pos="0.04290636 0.08456930 0.11139487" size="0.032513655722141266 0.008711197413504124 0.12795889377593994" quat="0.933960497379303 0.0 -0.0 -0.35737624764442444"/>
          <geom class="collision" type="box" pos="-0.03396280 -0.08584690 0.11139487" size="0.05650930479168892 0.008711099624633789 0.12795734405517578" quat="1.0 0.0 0.0 0.0"/>
          <geom class="collision" type="box" pos="0.04290637 -0.06799819 0.11139487" size="0.032513655722141266 0.008711197413504124 0.12795889377593994" quat="0.933960497379303 0.0 0.0 0.35737624764442444"/>
          <geom class="collision" type="box" pos="-0.10846017 -0.06547634 0.11139487" size="0.03251366317272186 0.008711198344826698 0.12795889377593994" quat="0.9170170426368713 0.0 -0.0 -0.3988479971885681"/>
          <geom class="collision" type="box" pos="0.06268667 0.00538297 0.11139487" size="0.008711114525794983 0.05650939792394638 0.1279575228691101" quat="1.0 0.0 0.0 0.0"/>
          <geom class="collision" type="box" pos="-0.13156153 -0.02833338 0.11139487" size="0.017218004912137985 0.008711198344826698 0.12795889377593994" quat="0.5351915955543518 0.0 0.0 0.8447307348251343"/>
          <geom class="collision" type="box" pos="-0.14480387 -0.00115176 0.11139487" size="0.017218004912137985 0.008711198344826698 0.12795889377593994" quat="0.5351915955543518 0.0 0.0 0.8447307348251343"/>
          <geom class="collision" type="box" pos="-0.14253873 0.02812075 0.11139487" size="0.017218006774783134 0.008711198344826698 0.12795889377593994" quat="0.8767032623291016 0.0 0.0 0.481031596660614"/>
          <geom class="collision" type="box" pos="-0.13347819 0.05112058 0.11139487" size="0.017218006774783134 0.008711198344826698 0.12795889377593994" quat="0.7761645317077637 0.0 0.0 0.6305304169654846"/>
          <geom class="collision" type="box" pos="-0.04270641 0.00459594 -0.01354376" size="0.09490712732076645 0.0923057422041893 0.006025748793035746" quat="1.0 0.0 0.0 0.0"/>
          <geom class="collision" type="box" pos="0.09001044 0.01013495 0.21243706" size="0.02718629129230976 0.02422558329999447 0.018655451014637947" quat="1.0 0.0 0.0 0.0"/>
          <geom class="collision" type="box" pos="0.12858595 0.01013495 0.20359226" size="0.02718629315495491 0.02422558329999447 0.023177461698651314" quat="0.9241241216659546 -2.755961454328163e-15 0.38209235668182373 5.1337494255676575e-08"/>
          <geom class="collision" type="box" pos="0.13291556 0.01013495 0.10968557" size="0.01915726438164711 0.02422558329999447 0.07122552394866943" quat="1.0 0.0 0.0 0.0"/>
          <geom class="collision" type="box" pos="0.08524320 0.01013495 0.01115648" size="0.02718629129230976 0.02422558329999447 0.018655451014637947" quat="1.0 0.0 0.0 0.0"/>
          <geom class="collision" type="box" pos="0.12381871 0.01013495 0.02000128" size="0.02718629315495491 0.02422558329999447 0.023177461698651314" quat="0.9241241216659546 4.973259717388242e-16 -0.3820923864841461 5.133750136110393e-08"/>
          <body name="Blade001">
            <joint axis="0.0 0.0 1.0" pos="-0.03193976 0.01031788 0.01786305" limited="false" name="Blade001_joint" range="0 360" type="hinge" damping="1" frictionloss="1" armature=".01" stiffness="0.05"/>
            <geom mesh="Blade001_vis" type="mesh" solimp="0.998 0.998 0.001" solref="0.001 1" friction="0.95 0.3 0.1" class="visual" material="Blade001_material"/>
            <geom class="collision" type="box" pos="-0.03158057 0.01036866 0.00090644" size="0.015457836911082268 0.00963042676448822 0.0011948224855586886" quat="1.0 0.0 0.0 0.0"/>
            <geom class="collision" type="box" pos="-0.03187269 0.03373652 0.01832443" size="0.019890112802386284 0.00963042676448822 0.0011948226019740105" quat="0.5970932841300964 0.378787100315094 -0.3787870407104492 0.5970932245254517"/>
            <geom class="collision" type="box" pos="-0.03187269 0.01066077 0.00090644" size="0.009630427695810795 0.015457837842404842 0.0011948224855586886" quat="1.0 0.0 0.0 0.0"/>
            <geom class="collision" type="box" pos="-0.03187269 -0.01338489 0.01832443" size="0.019890112802386284 0.00963042676448822 0.0011948226019740105" quat="0.5970932245254517 -0.37878715991973877 0.3787870705127716 0.5970932245254517"/>
            <geom class="collision" type="box" pos="-0.05585026 0.01028198 0.01832443" size="0.019890110939741135 0.00963042676448822 0.0011948224855586886" quat="0.8444173336029053 -3.837460837985418e-08 0.5356858968734741 -5.7312807832943236e-09"/>
            <geom class="collision" type="box" pos="-0.00828349 0.01028198 0.01832443" size="0.019890112802386284 0.00963042676448822 0.0011948226019740105" quat="1.0835157837618681e-07 0.5356858968734741 1.1074719452608406e-07 -0.8444173336029053"/>
          </body>
          <body name="Jug001">
            <geom mesh="Jug001_vis" type="mesh" solimp="0.998 0.998 0.001" solref="0.001 1" friction="0.95 0.3 0.1" class="visual" material="Jug001_material"/>
            <geom class="collision" type="cylinder" pos="-0.03100953 0.01057824 -0.01475727" size="0.053082868456840515 0.012121236883103848" quat="1.0 0.0 0.0 0.0"/>
            <geom class="collision" type="box" pos="-0.03396280 0.10241802 0.11139487" size="0.056509215384721756 0.008711088448762894 0.12795716524124146" quat="1.0 0.0 0.0 0.0"/>
            <geom class="collision" type="box" pos="-0.11034779 0.08306386 0.11139487" size="0.032513655722141266 0.008711197413504124 0.12795889377593994" quat="0.933960497379303 0.0 0.0 0.35737624764442444"/>
            <geom class="collision" type="box" pos="0.04290636 0.08456930 0.11139487" size="0.032513655722141266 0.008711197413504124 0.12795889377593994" quat="0.933960497379303 0.0 -0.0 -0.35737624764442444"/>
            <geom class="collision" type="box" pos="-0.03396280 -0.08584690 0.11139487" size="0.05650930479168892 0.008711099624633789 0.12795734405517578" quat="1.0 0.0 0.0 0.0"/>
            <geom class="collision" type="box" pos="0.04290637 -0.06799819 0.11139487" size="0.032513655722141266 0.008711197413504124 0.12795889377593994" quat="0.933960497379303 0.0 0.0 0.35737624764442444"/>
            <geom class="collision" type="box" pos="-0.10846017 -0.06547634 0.11139487" size="0.03251366317272186 0.008711198344826698 0.12795889377593994" quat="0.9170170426368713 0.0 -0.0 -0.3988479971885681"/>
            <geom class="collision" type="box" pos="0.06268667 0.00538297 0.11139487" size="0.008711114525794983 0.05650939792394638 0.1279575228691101" quat="1.0 0.0 0.0 0.0"/>
            <geom class="collision" type="box" pos="-0.13156153 -0.02833338 0.11139487" size="0.017218004912137985 0.008711198344826698 0.12795889377593994" quat="0.5351915955543518 0.0 0.0 0.8447307348251343"/>
            <geom class="collision" type="box" pos="-0.14480387 -0.00115176 0.11139487" size="0.017218004912137985 0.008711198344826698 0.12795889377593994" quat="0.5351915955543518 0.0 0.0 0.8447307348251343"/>
            <geom class="collision" type="box" pos="-0.14253873 0.02812075 0.11139487" size="0.017218006774783134 0.008711198344826698 0.12795889377593994" quat="0.8767032623291016 0.0 0.0 0.481031596660614"/>
            <geom class="collision" type="box" pos="-0.13347819 0.05112058 0.11139487" size="0.017218006774783134 0.008711198344826698 0.12795889377593994" quat="0.7761645317077637 0.0 0.0 0.6305304169654846"/>
            <geom class="collision" type="box" pos="-0.04270641 0.00459594 -0.01354376" size="0.09490712732076645 0.0923057422041893 0.006025748793035746" quat="1.0 0.0 0.0 0.0"/>
            <geom class="collision" type="box" pos="0.09001044 0.01013495 0.21243706" size="0.02718629129230976 0.02422558329999447 0.018655451014637947" quat="1.0 0.0 0.0 0.0"/>
            <geom class="collision" type="box" pos="0.12858595 0.01013495 0.20359226" size="0.02718629315495491 0.02422558329999447 0.023177461698651314" quat="0.9241241216659546 -2.755961454328163e-15 0.38209235668182373 5.1337494255676575e-08"/>
            <geom class="collision" type="box" pos="0.13291556 0.01013495 0.10968557" size="0.01915726438164711 0.02422558329999447 0.07122552394866943" quat="1.0 0.0 0.0 0.0"/>
            <geom class="collision" type="box" pos="0.08524320 0.01013495 0.01115648" size="0.02718629129230976 0.02422558329999447 0.018655451014637947" quat="1.0 0.0 0.0 0.0"/>
            <geom class="collision" type="box" pos="0.12381871 0.01013495 0.02000128" size="0.02718629315495491 0.02422558329999447 0.023177461698651314" quat="0.9241241216659546 4.973259717388242e-16 -0.3820923864841461 5.133750136110393e-08"/>
          </body>
        </body>
        <body name="Knob001">
          <joint axis="1.163581941909797e-07 1.0 2.0153819946244766e-07" pos="-0.03241558 -0.09221647 -0.13983136" limited="true" name="Knob001_joint" range="0.0 4.153883619746504" type="hinge" damping="0.05" frictionloss="0.1" armature="0.001"/>
          <geom mesh="Knob001_vis" type="mesh" solimp="0.998 0.998 0.001" solref="0.001 1" friction="0.95 0.3 0.1" class="visual" material="Knob001_material"/>
          <geom class="collision" type="cylinder" pos="-0.03200669 -0.08238636 -0.13961077" size="0.030412523075938225 0.006172697059810162" quat="0.7071067094802856 0.7071068286895752 0.0 0.0"/>
          <geom class="collision" type="box" pos="-0.03214500 -0.09542076 -0.13954633" size="0.006515718065202236 0.014615816064178944 0.023852845653891563" quat="0.8647358417510986 -4.5700311651554904e-15 0.5022270083427429 6.747864489398125e-08"/>
        </body>
        <geom class="region" name="reg_main" type="box" pos="-0.041557159999999996 0.010226100000000002 0.0" size="0.11028239 0.10077628 0.28032143"/>
      </body>
      <site rgba="0 1 0 0" size="0.005" pos="-0.03408582 0.01025725 0.25190478" name="anchor_site"/>
    </body>
  </worldbody>
  <actuator>
    <motor name="Button001_joint_actuator" joint="Button001_joint" gear="0.5"/>
    <motor name="Jug001_Clear_joint_actuator" joint="Jug001_Clear_joint" gear="0.5"/>
    <motor name="Knob001_joint_actuator" joint="Knob001_joint" gear="10"/>
    <motor name="Lid001_joint_actuator" joint="Lid001_joint" gear="0.5"/>
    <motor name="Blade001_joint_actuator" joint="Blade001_joint" gear="10"/>
  </actuator>
</mujoco>
