<?xml version='1.0' encoding='UTF-8'?>
<mujoco model="model">
  <option timestep="0.0005" gravity="0.0 0.0 -9.81"/>
  <compiler angle="radian"/>
  <asset>
    <mesh file="visuals/Blade001.obj" name="Blade001_vis"/>
    <mesh file="visuals/Body001.obj" name="Body001_vis"/>
    <mesh file="visuals/Button001.obj" name="Button001_vis"/>
    <mesh file="visuals/Button002.obj" name="Button002_vis"/>
    <mesh file="visuals/Jug001.obj" name="Jug001_vis"/>
    <mesh file="visuals/Jug001_Clear.obj" name="Jug001_Clear_vis"/>
    <mesh file="visuals/Knob001.obj" name="Knob001_vis"/>
    <mesh file="visuals/Lid001.obj" name="Lid001_vis"/>
    <texture file="visuals/T_BC001.png" name="Body001_material" type="2d"/>
    <material name="Body001_material" rgba="1 1 1 1.0" texture="Body001_material" shininess="0.141421377658844" specular="0.33333333333333337"/>
    <texture file="visuals/T_BC001.png" name="Button001_material" type="2d"/>
    <material name="Button001_material" rgba="1 1 1 1.0" texture="Button001_material" shininess="0.141421377658844" specular="0.33333333333333337"/>
    <texture file="visuals/T_BC001.png" name="Button002_material" type="2d"/>
    <material name="Button002_material" rgba="1 1 1 1.0" texture="Button002_material" shininess="0.141421377658844" specular="0.33333333333333337"/>
    <texture file="visuals/T_BC001.png" name="Jug001_material" type="2d"/>
    <material name="Jug001_material" rgba="1 1 1 1.0" texture="Jug001_material" shininess="0.141421377658844" specular="0.33333333333333337"/>
    <texture file="visuals/T_BC001.png" name="Blade001_material" type="2d"/>
    <material name="Blade001_material" rgba="1 1 1 1.0" texture="Blade001_material" shininess="0.141421377658844" specular="3"/>
    <texture file="visuals/T_BC001.png" name="Jug001_Clear_material" type="2d"/>
    <material name="Jug001_Clear_material" rgba="1 1 1 0.699999988079071" texture="Jug001_Clear_material" shininess="0.8264863044023514" specular="0.7872340339187474"/>
    <texture file="visuals/T_BC001.png" name="Knob001_material" type="2d"/>
    <material name="Knob001_material" rgba="1 1 1 1.0" texture="Knob001_material" shininess="0.141421377658844" specular="0.33333333333333337"/>
    <texture file="visuals/T_BC001.png" name="Lid001_material" type="2d"/>
    <material name="Lid001_material" rgba="1 1 1 1.0" texture="Lid001_material" shininess="0.141421377658844" specular="0.33333333333333337"/>
  </asset>
  <default>
    <default class="visual">
      <geom conaffinity="0" contype="0" group="1" type="mesh"/>
    </default>
    <default class="collision">
      <geom group="0" rgba="0.5 0 0 0.5"/>
    </default>
    <default class="spawn">
      <geom group="0" rgba="1 1 1 0.5" contype="0" conaffinity="0"/>
      <site group="0" rgba="1 1 1 0.5"/>
    </default>
    <default class="region">
      <geom group="1" conaffinity="0" contype="0" rgba="0 1 0 0"/>
    </default>
  </default>
  <worldbody>
    <body>
      <body name="object">
        <geom mesh="Body001_vis" type="mesh" solimp="0.998 0.998 0.001" solref="0.001 1" friction="0.95 0.3 0.1" class="visual" material="Body001_material"/>
        <geom class="collision" type="box" pos="-0.01743007 -0.01908264 -0.22553408" size="0.12968866527080536 0.05051147937774658 0.07040132582187653" quat="1.0 0.0 0.0 0.0"/>
        <geom class="collision" type="box" pos="-0.01822870 -0.11254722 -0.24224916" size="0.1301640272140503 0.05060109868645668 0.053686242550611496" quat="1.0 0.0 0.0 0.0"/>
        <geom class="collision" type="cylinder" pos="-0.01745005 0.04508350 -0.15840825" size="0.09668879210948944 0.03932907059788704" quat="1.0 0.0 0.0 0.0"/>
        <geom class="collision" type="cylinder" pos="-0.01728963 0.02501012 -0.23692481" size="0.1277042180299759 0.059179969131946564" quat="1.0 0.0 0.0 0.0"/>
        <geom class="collision" type="cylinder" pos="-0.06051707 0.04713970 -0.18221265" size="0.07243027538061142 0.033565230667591095" quat="1.0 0.0 0.0 0.0"/>
        <geom class="collision" type="cylinder" pos="-0.01141017 0.07806424 -0.18221265" size="0.07243027538061142 0.033565230667591095" quat="1.0 0.0 0.0 0.0"/>
        <geom class="collision" type="cylinder" pos="0.01400837 0.06626657 -0.18221265" size="0.07243027538061142 0.033565230667591095" quat="1.0 0.0 0.0 0.0"/>
        <geom class="collision" type="cylinder" pos="0.03372710 0.03997962 -0.18221265" size="0.07243027538061142 0.033565230667591095" quat="1.0 0.0 0.0 0.0"/>
        <geom class="collision" type="cylinder" pos="-0.04073561 0.07124133 -0.18221265" size="0.07243027538061142 0.033565230667591095" quat="1.0 0.0 0.0 0.0"/>
        <body name="Button001">
          <joint axis="0.0 0.4226183593273163 -0.9063079357147217" pos="0.05751518 -0.11553806 -0.17846154" limited="true" name="Button001_joint" range="0.0 0.003" type="slide" damping="1" frictionloss="1" armature=".01" stiffness="0.5" springref="-0.5"/>
          <geom mesh="Button001_vis" type="mesh" solimp="0.998 0.998 0.001" solref="0.001 1" friction="0.95 0.3 0.1" class="visual" material="Button001_material"/>
          <geom class="collision" type="box" pos="0.05703367 -0.11604892 -0.17720503" size="0.015535996295511723 0.009651546366512775 0.0032402225770056248" quat="0.969495415687561 0.24482029676437378 0.009978671558201313 0.00648893415927887"/>
        </body>
        <body name="Button002">
          <joint axis="-5.6152605808054936e-18 0.4226183593273163 -0.9063079357147217" pos="-0.08866869 -0.11558645 -0.17845373" limited="true" name="Button002_joint" range="0.0 0.003" type="slide" damping="1" frictionloss="1" armature=".01" stiffness="0.5" springref="-0.5"/>
          <geom mesh="Button002_vis" type="mesh" solimp="0.998 0.998 0.001" solref="0.001 1" friction="0.95 0.3 0.1" class="visual" material="Button002_material"/>
          <geom class="collision" type="box" pos="-0.08898954 -0.11713010 -0.17729708" size="0.015483303926885128 0.008930300362408161 0.002988857915624976" quat="0.9694134593009949 0.2453550100326538 -0.0021198231261223555 -0.005826357286423445"/>
        </body>
        <body name="Jug001">
          <!-- <joint axis="0.0 0.0 1.0" pos="0.03004597 0.04699287 0.04808532" limited="true" name="Jug001_joint" range="0.0 0.05" type="slide" damping="1" frictionloss="1" armature=".01" stiffness="0.05"/> -->
          <geom mesh="Jug001_vis" type="mesh" solimp="0.998 0.998 0.001" solref="0.001 1" friction="0.95 0.3 0.1" class="visual" material="Jug001_material"/>
          <geom class="collision" type="box" pos="0.02975277 -0.01388730 0.07544540" size="0.0721902921795845 0.012196497060358524 0.13525761663913727" quat="0.9156303405761719 0.017245326191186905 0.007563496939837933 0.40157994627952576"/>
          <geom class="collision" type="box" pos="-0.06811962 0.11111925 0.07610477" size="0.07833114266395569 0.012838413007557392 0.13396118581295013" quat="0.914870023727417 -0.019253043457865715 -0.032436903566122055 0.4019826352596283"/>
          <geom class="collision" type="box" pos="-0.07223981 -0.01232059 0.07612204" size="0.0721672773361206 0.012000609189271927 0.13558508455753326" quat="0.4066144526004791 -0.017574811354279518 -0.011982575058937073 0.9133521914482117"/>
          <geom class="collision" type="box" pos="0.03248799 0.10532500 0.07599545" size="0.07356119900941849 0.010724218562245369 0.13674744963645935" quat="0.4069778621196747 -0.0019201186951249838 0.007655052468180656 0.9134039282798767"/>
          <geom class="collision" type="box" pos="0.10085973 0.04720987 0.19090898" size="0.018853865563869476 0.016030292958021164 0.010851765982806683" quat="1.0 0.0 0.0 0.0"/>
          <geom class="collision" type="box" pos="0.09130741 0.04704521 0.02014696" size="0.017213819548487663 0.013093107379972935 0.014991587027907372" quat="1.0 0.0 0.0 0.0"/>
          <geom class="collision" type="box" pos="0.13611458 0.04720987 0.13432606" size="0.015919027850031853 0.016030292958021164 0.06743469834327698" quat="1.0 0.0 0.0 0.0"/>
          <geom class="collision" type="box" pos="0.12093865 0.04692338 0.04219097" size="0.02517963945865631 0.014718655496835709 0.014991587027907372" quat="0.917942225933075 0.0 -0.39671412110328674 0.0"/>
          <geom class="collision" type="cylinder" pos="-0.01745005 0.04508350 -0.08908665" size="0.09668877720832825 0.02689594402909279" quat="1.0 0.0 0.0 0.0"/>
          <body name="Blade001">
            <joint axis="0.0 0.0 1.0" pos="-0.01694712 0.04698000 -0.03920843" limited="false" name="Blade001_joint" range="0 360" type="hinge" damping="1" frictionloss="1" armature=".01" stiffness="0.05"/>
            <geom mesh="Blade001_vis" type="mesh" solimp="0.998 0.998 0.001" solref="0.001 1" friction="0.95 0.3 0.1" class="visual" material="Blade001_material"/>
            <geom class="collision" type="box" pos="-0.01826089 0.04772887 -0.04420773" size="0.03555736690759659 0.011566841043531895 0.005374473053961992" quat="1.0 0.0 0.0 0.0"/>
            <geom class="collision" type="box" pos="-0.01660209 0.02411597 -0.04357884" size="0.010374368168413639 0.011566841043531895 0.0021979371085762978" quat="1.0 0.0 0.0 0.0"/>
            <geom class="collision" type="box" pos="-0.01660209 0.07107933 -0.04357884" size="0.010374368168413639 0.011566841043531895 0.0021979371085762978" quat="1.0 0.0 0.0 0.0"/>
            <geom class="collision" type="box" pos="-0.01660209 0.09607778 -0.05061881" size="0.010374368168413639 0.01796589232981205 0.0011200293665751815" quat="0.9813559651374817 -0.19219909608364105 -0.0 0.0"/>
            <geom class="collision" type="box" pos="-0.01660209 -0.00235559 -0.05061881" size="0.010374368168413639 0.01796589232981205 0.0011200293665751815" quat="0.9813559651374817 0.19219909608364105 0.0 0.0"/>
            <geom class="collision" type="box" pos="-0.06340711 0.04655903 -0.03094639" size="0.013877377845346928 0.0055869086645543575 0.0011185097973793745" quat="0.9225588440895081 0.0 0.3858564496040344 0.0"/>
            <geom class="collision" type="box" pos="0.02965547 0.04655903 -0.03094639" size="0.013877377845346928 0.0055869086645543575 0.0011185097973793745" quat="0.9225588440895081 0.0 -0.3858564496040344 0.0"/>
          </body>
          <body name="Jug001_Clear">
            <geom class="region" name="reg_int" type="box" pos="-0.017753785 0.04698981 0.09888576" size="0.022582325 0.06463076000000001 0.11066815"/>
            <geom mesh="Jug001_Clear_vis" type="mesh" solimp="0.998 0.998 0.001" solref="0.001 1" friction="0.95 0.3 0.1" class="visual" material="Jug001_Clear_material"/>
            <geom class="collision" type="box" pos="0.02975277 -0.01388730 0.07544540" size="0.0721902921795845 0.012196497060358524 0.13525761663913727" quat="0.9156303405761719 0.017245326191186905 0.007563496939837933 0.40157994627952576"/>
            <geom class="collision" type="box" pos="-0.06811962 0.11111925 0.07610477" size="0.07833114266395569 0.012838413007557392 0.13396118581295013" quat="0.914870023727417 -0.019253043457865715 -0.032436903566122055 0.4019826352596283"/>
            <geom class="collision" type="box" pos="-0.07223981 -0.01232059 0.07612204" size="0.0721672773361206 0.012000609189271927 0.13558508455753326" quat="0.4066144526004791 -0.017574811354279518 -0.011982575058937073 0.9133521914482117"/>
            <geom class="collision" type="box" pos="0.03248799 0.10532500 0.07599545" size="0.07356119900941849 0.010724218562245369 0.13674744963645935" quat="0.4069778621196747 -0.0019201186951249838 0.007655052468180656 0.9134039282798767"/>
          </body>
        </body>
        <body name="Knob001">
          <joint axis="0.0 0.42261821031570435 -0.9063078165054321" pos="-0.01493116 -0.10340426 -0.16157910" limited="true" name="Knob001_joint" range="0.0 4.1887902047863905" type="hinge" damping="0.05" frictionloss="0.1" armature="0.001"/>
          <geom mesh="Knob001_vis" type="mesh" solimp="0.998 0.998 0.001" solref="0.001 1" friction="0.95 0.3 0.1" class="visual" material="Knob001_material"/>
          <geom class="collision" type="cylinder" pos="-0.01481691 -0.09886119 -0.16865791" size="0.026953713968396187 0.004453835543245077" quat="0.9746725559234619 0.22363674640655518 -4.965733631128541e-17 -1.5369836527898264e-24" density="0.001"/>
          <geom class="collision" type="box" pos="-0.01453726 -0.10554808 -0.15796772" size="0.0061064972542226315 0.020651644095778465 0.011173461563885212" quat="0.8418465256690979 0.2161499410867691 0.09332498162984848 -0.4856584072113037" density="0.001"/>
        </body>
        <geom class="region" name="reg_main" type="box" pos="-0.021296125 2.7999999999139824e-07 3.350000000179598e-07" size="0.133710725 0.16606809 0.296851645"/>
      </body>
      <site rgba="0 1 0 0" size="0.005" pos="-0.02878341 0.0469905 0.24770313" name="anchor_site"/>
    </body>
  </worldbody>
  <actuator>
    <motor name="Button001_joint_actuator" joint="Button001_joint" gear="0.5"/>
    <motor name="Button002_joint_actuator" joint="Button002_joint" gear="0.5"/>
    <!-- <motor name="Jug001_joint_actuator" joint="Jug001_joint" gear="0.5"/> -->
    <motor name="Knob001_joint_actuator" joint="Knob001_joint" gear="10"/>
    <!-- <motor name="Lid001_joint_actuator" joint="Lid001_joint" gear="0.5"/> -->
    <motor name="Blade001_joint_actuator" joint="Blade001_joint" gear="10"/>
  </actuator>
</mujoco>
