<?xml version='1.0' encoding='UTF-8'?>
<mujoco model="model">
  <option timestep="0.0005" gravity="0.0 0.0 -9.81"/>
  <compiler angle="radian"/>
  <asset>
    <mesh file="visuals/blade.obj" name="blade_vis"/>
    <mesh file="visuals/Body001.obj" name="Body001_vis"/>
    <mesh file="visuals/knob_speed.obj" name="knob_speed_vis"/>
    <mesh file="visuals/pitcher.obj" name="pitcher_vis"/>
    <mesh file="visuals/pitcher_main.obj" name="pitcher_main_vis"/>
    <mesh file="visuals/power_button.obj" name="power_button_vis"/>
    <mesh file="visuals/pulse_button.obj" name="pulse_button_vis"/>
    <texture file="visuals/T_BC001.png" name="Body001_material" type="2d"/>
    <material name="Body001_material" rgba="1 1 1 1.0" texture="Body001_material" shininess="0.141421377658844" specular="0.33333333333333337"/>
    <texture file="visuals/T_BC001.png" name="knob_speed_material" type="2d"/>
    <material name="knob_speed_material" rgba="1 1 1 1.0" texture="knob_speed_material" shininess="0.141421377658844" specular="0.33333333333333337"/>
    <texture file="visuals/T_BC001.png" name="pitcher_material" type="2d"/>
    <material name="pitcher_material" rgba="1 1 1 1.0" texture="pitcher_material" shininess="0.141421377658844" specular="0.33333333333333337"/>
    <texture file="visuals/T_BC001.png" name="blade_material" type="2d"/>
    <material name="blade_material" rgba="1 1 1 1.0" texture="blade_material" shininess="0.141421377658844" specular="0.33333333333333337"/>
    <texture file="visuals/T_BC001.png" name="pitcher_main_material" type="2d"/>
    <material name="pitcher_main_material" rgba="1 1 1 0.699999988079071" texture="pitcher_main_material" shininess="0.8264863044023514" specular="0.7872340339187474"/>
    <texture file="visuals/T_BC001.png" name="power_button_material" type="2d"/>
    <material name="power_button_material" rgba="1 1 1 1.0" texture="power_button_material" shininess="0.141421377658844" specular="0.33333333333333337"/>
    <texture file="visuals/T_BC001.png" name="pulse_button_material" type="2d"/>
    <material name="pulse_button_material" rgba="1 1 1 1.0" texture="pulse_button_material" shininess="0.141421377658844" specular="0.33333333333333337"/>
  </asset>
  <default>
    <default class="visual">
      <geom conaffinity="0" contype="0" group="1" type="mesh"/>
    </default>
    <default class="collision">
      <geom group="0" rgba="0.5 0 0 0.5" density="1" solref="0.001 1" solimp="0.998 0.998 0.001"/>
    </default>
    <default class="spawn">
      <geom group="0" rgba="1 1 1 0.5" contype="0" conaffinity="0"/>
      <site group="0" rgba="1 1 1 0.5"/>
    </default>
    <default class="region">
      <geom group="1" conaffinity="0" contype="0" rgba="0 1 0 0" mass="0"/>
    </default>
  </default>
  <worldbody>
    <body>
      <body name="object">
        <geom mesh="Body001_vis" type="mesh" solimp="0.998 0.998 0.001" solref="0.001 1" friction="0.95 0.3 0.1" class="visual" material="Body001_material"/>
        <geom type="box" pos="-0.02199307 -0.01426714 -0.19971108" size="0.12968866527080536 0.05051147937774658 0.07040132582187653" quat="1.0 0.0 0.0 0.0" class="collision"/>
        <geom type="box" pos="-0.02279170 -0.10773172 -0.21642616" size="0.1301640272140503 0.05060109868645668 0.053686242550611496" quat="1.0 0.0 0.0 0.0" class="collision"/>
        <geom type="cylinder" pos="-0.02201305 0.04989900 -0.13258525" size="0.09668879210948944 0.03932907059788704" quat="1.0 0.0 0.0 0.0" class="collision"/>
        <geom type="cylinder" pos="-0.02185263 0.02982562 -0.21110181" size="0.1277042180299759 0.059179969131946564" quat="1.0 0.0 0.0 0.0" class="collision"/>
        <geom type="cylinder" pos="-0.06508007 0.05195520 -0.15638965" size="0.07243027538061142 0.033565230667591095" quat="1.0 0.0 0.0 0.0" class="collision"/>
        <geom type="cylinder" pos="-0.01597317 0.08287974 -0.15638965" size="0.07243027538061142 0.033565230667591095" quat="1.0 0.0 0.0 0.0" class="collision"/>
        <geom type="cylinder" pos="0.00944537 0.07108207 -0.15638965" size="0.07243027538061142 0.033565230667591095" quat="1.0 0.0 0.0 0.0" class="collision"/>
        <geom type="cylinder" pos="0.02916410 0.04479512 -0.15638965" size="0.07243027538061142 0.033565230667591095" quat="1.0 0.0 0.0 0.0" class="collision"/>
        <geom type="cylinder" pos="-0.04529861 0.07605683 -0.15638965" size="0.07243027538061142 0.033565230667591095" quat="1.0 0.0 0.0 0.0" class="collision"/>
        <body name="knob_speed">
          <joint axis="0.0 0.42261821031570435 -0.9063078165054321" pos="-0.01949416 -0.09858876 -0.13575610" limited="true" name="knob_speed_joint" range="0.0 4.1887902047863905" type="hinge" damping="0.05" armature="0.001"/>
          <geom mesh="knob_speed_vis" type="mesh" solimp="0.998 0.998 0.001" solref="0.001 1" friction="0.95 0.3 0.1" class="visual" material="knob_speed_material"/>
          <geom type="cylinder" pos="-0.01937991 -0.09404569 -0.14283491" size="0.026953713968396187 0.004453835543245077" quat="0.9746725559234619 0.22363674640655518 -4.965733631128541e-17 -1.5369836527898264e-24" class="collision"/>
          <geom class="collision" type="box" pos="-0.01910026 -0.10073258 -0.13214472" size="0.0061064972542226315 0.020651644095778465 0.011173461563885212" quat="0.8418465256690979 0.2161499410867691 0.09332498162984848 -0.4856584072113037" name="knob_speed_main"/>
        </body>
        <body name="pitcher">
          <!--<joint axis="0.0 0.0 1.0" pos="0.02548297 0.05180837 0.07390832" limited="true" name="pitcher_joint" range="0.0 0.05" type="slide" damping="1" frictionloss="1" armature=".01" stiffness="0.05"/>-->
          <geom mesh="pitcher_vis" type="mesh" solimp="0.998 0.998 0.001" solref="0.001 1" friction="0.95 0.3 0.1" class="visual" material="pitcher_material"/>
          <geom class="collision" type="box" pos="0.09629673 0.05202537 0.21673198" size="0.02094653993844986 0.016030292958021164 0.010851765982806683" quat="1.0 0.0 0.0 0.0" name="pitcher_handle_0"/>
          <geom class="collision" type="box" pos="0.07794306 0.05186071 0.04688044" size="0.017213819548487663 0.013093107379972935 0.012797565199434757" quat="1.0 0.0 0.0 0.0" name="pitcher_handle_1"/>
          <geom class="collision" type="box" pos="0.13286267 0.05202537 0.16014906" size="0.015919027850031853 0.016030292958021164 0.06743469834327698" quat="1.0 0.0 0.0 0.0" name="pitcher_handle_2"/>
          <geom class="collision" type="box" pos="0.12502524 0.05173888 0.08015375" size="0.020866841077804565 0.014718655496835709 0.014991585165262222" quat="0.8585997819900513 -6.927193485495309e-09 -0.512646496295929 -1.6028577576321368e-08" name="pitcher_handle_3"/>
          <geom type="cylinder" pos="-0.02201305 0.04989900 -0.06326365" size="0.09668877720832825 0.02689594402909279" quat="1.0 0.0 0.0 0.0" class="collision"/>
          <geom class="collision" type="box" pos="0.10477706 0.05173888 0.05577364" size="0.0190419964492321 0.014718655496835709 0.013767176307737827" quat="0.9641115069389343 7.396467438525178e-09 -0.26549768447875977 1.711440766882788e-08" name="pitcher_handle_4"/>
          <body name="blade">
            <!-- <joint axis="0.0 0.0 1.0" pos="-0.02151012 0.05179550 -0.01338543" limited="false" name="blade_joint" range="0 360" type="hinge" damping="1" frictionloss="1" armature=".01" stiffness="0.05"/> -->
            <geom mesh="blade_vis" type="mesh" solimp="0.998 0.998 0.001" solref="0.001 1" friction="0.95 0.3 0.1" class="visual" material="blade_material"/>
            <geom type="box" pos="-0.02282389 0.05254437 -0.01838473" size="0.03555736690759659 0.011566841043531895 0.005374473053961992" quat="1.0 0.0 0.0 0.0" class="collision"/>
            <geom type="box" pos="-0.02116509 0.02893147 -0.01775584" size="0.010374368168413639 0.011566841043531895 0.0021979371085762978" quat="1.0 0.0 0.0 0.0" class="collision"/>
            <geom type="box" pos="-0.02116509 0.07589483 -0.01775584" size="0.010374368168413639 0.011566841043531895 0.0021979371085762978" quat="1.0 0.0 0.0 0.0" class="collision"/>
            <geom type="box" pos="-0.02116509 0.09679450 -0.02312628" size="0.010374367237091064 0.012277994304895401 0.0011200300650671124" quat="0.9813559651374817 -0.19219909608364105 -0.0 0.0" class="collision"/>
            <geom type="box" pos="-0.02116509 0.00890204 -0.02217177" size="0.010374367237091064 0.009923008270561695 0.0011200300650671124" quat="0.9813559651374817 0.19219909608364105 0.0 0.0" class="collision"/>
            <geom type="box" pos="-0.06797011 0.05137453 -0.00512339" size="0.013877377845346928 0.0055869086645543575 0.001118509448133409" quat="0.9225588440895081 0.0 0.3858564496040344 0.0" class="collision"/>
            <geom type="box" pos="0.02509247 0.05137453 -0.00512339" size="0.013877379707992077 0.0055869086645543575 0.001118509448133409" quat="0.9225588440895081 0.0 -0.3858564496040344 0.0" class="collision"/>
          </body>
          <body name="pitcher_main">
            <geom class="region" type="cylinder" size="0.05791444703936577 0.11232888698577881" pos="-0.02077075 0.05404016 0.12025465" rgba="0 0 1 0.5" name="reg_int"/>
            <geom mesh="pitcher_main_vis" type="mesh" solimp="0.998 0.998 0.001" solref="0.001 1" friction="0.95 0.3 0.1" class="visual" material="pitcher_main_material"/>
            <geom type="box" pos="-0.08440144 0.10650524 0.11646234" size="0.042045958340168 0.004149169195443392 0.1530502587556839" quat="0.9263641834259033 -0.04800304025411606 -0.036923766136169434 0.3717280924320221" class="collision"/>
            <geom type="box" pos="-0.12730362 0.06677897 0.17227225" size="0.01971113495528698 0.004149168264120817 0.09649276733398438" quat="0.8696958422660828 -0.04780135676264763 -0.04569670185446739 0.4891379475593567" class="collision"/>
            <geom type="box" pos="-0.10518152 0.06182063 0.02139261" size="0.012013556435704231 0.004149165935814381 0.055805500596761703" quat="0.8699575662612915 -0.04277625307440758 -0.04287014156579971 0.4893936812877655" class="collision"/>
            <geom type="box" pos="-0.04211553 0.13761025 0.11843667" size="0.01705811731517315 0.004149168264120817 0.1530502587556839" quat="0.9774184823036194 -0.05376477539539337 -0.027874834835529327 0.20244856178760529" class="collision"/>
            <geom type="box" pos="0.03500572 0.10650525 0.11646235" size="0.0420459620654583 0.00414917292073369 0.1530502587556839" quat="0.9058413505554199 -0.03774869069457054 0.01987173780798912 -0.42146363854408264" class="collision"/>
            <geom type="box" pos="-0.00247474 0.14193490 0.11669371" size="0.014213469810783863 0.004149169195443392 0.1530502885580063" quat="0.9606580138206482 -0.04039445519447327 0.013716344721615314 -0.27443811297416687" class="collision"/>
            <geom type="box" pos="-0.02368115 0.14614255 0.11669372" size="0.014213466085493565 0.004149169661104679 0.1530502885580063" quat="0.9990887641906738 -0.042605455964803696 0.0021506804041564465 -0.0013561727246269584" class="collision"/>
            <geom type="box" pos="0.06354436 0.06296573 0.11623319" size="0.01606355421245098 0.00414917292073369 0.1530502885580063" quat="0.8138395547866821 -0.03349398449063301 0.02641974203288555 -0.579521656036377" class="collision"/>
            <geom type="box" pos="-0.08440145 -0.00289365 0.11646233" size="0.042045958340168 0.004149169195443392 0.1530502587556839" quat="0.9263641238212585 0.04800306260585785 -0.036923784762620926 -0.37172818183898926" class="collision"/>
            <geom type="box" pos="-0.12730362 0.03683261 0.17227225" size="0.01971113495528698 0.004149168264120817 0.09649276733398438" quat="0.8696958422660828 0.04780134931206703 -0.045696698129177094 -0.4891379475593567" class="collision"/>
            <geom type="box" pos="-0.10518152 0.04179097 0.02139261" size="0.012013556435704231 0.004149165935814381 0.055805500596761703" quat="0.8699575066566467 0.04277624562382698 -0.042870134115219116 -0.48939380049705505" class="collision"/>
            <geom type="box" pos="-0.04211553 -0.03399868 0.11843667" size="0.01705811731517315 0.004149168264120817 0.1530502587556839" quat="0.9774184823036194 0.05376475676894188 -0.02787482552230358 -0.2024485170841217" class="collision"/>
            <geom type="box" pos="0.03500572 -0.00289367 0.11646235" size="0.0420459620654583 0.00414917292073369 0.1530502587556839" quat="0.9058413505554199 0.03774869069457054 0.01987173594534397 0.42146363854408264" class="collision"/>
            <geom type="box" pos="-0.00247474 -0.03832332 0.11669371" size="0.014213469810783863 0.004149169195443392 0.1530502885580063" quat="0.9606580138206482 0.040394458919763565 0.013716345652937889 0.27443811297416687" class="collision"/>
            <geom type="box" pos="-0.02368115 -0.04253097 0.11669371" size="0.014213466085493565 0.004149169661104679 0.1530502885580063" quat="0.9990887641906738 0.04260546341538429 0.002150680171325803 0.001356172258965671" class="collision"/>
            <geom type="box" pos="0.06354436 0.04064585 0.11623319" size="0.01606355421245098 0.00414917292073369 0.1530502885580063" quat="0.8138395547866821 0.03349398449063301 0.026419747620821 0.579521656036377" class="collision"/>
          </body>
        </body>
        <body name="power_button">
          <joint axis="0.0 0.4226182997226715 -0.9063078165054321" pos="0.05295218 -0.11072256 -0.15263854" limited="true" name="power_button_joint" range="0.0 0.003" type="slide" damping="1" frictionloss="1" armature=".01" stiffness="1" springref="-0.1"/>
          <geom mesh="power_button_vis" type="mesh" solimp="0.998 0.998 0.001" solref="0.001 1" friction="0.95 0.3 0.1" class="visual" material="power_button_material"/>
          <geom class="collision" type="box" pos="0.05247067 -0.11123342 -0.15138203" size="0.015535996295511723 0.009651546366512775 0.0032402225770056248" quat="0.969495415687561 0.24482029676437378 0.009978671558201313 0.00648893415927887" name="power_button_main"/>
        </body>
        <body name="pulse_button">
          <joint axis="-5.615260167215187e-18 0.4226182997226715 -0.9063078165054321" pos="-0.09323169 -0.11077095 -0.15263073" limited="true" name="pulse_button_joint" range="0.0 0.003" type="slide" damping="1" frictionloss="1" armature=".01" stiffness="1" springref="-0.1"/>
          <geom mesh="pulse_button_vis" type="mesh" solimp="0.998 0.998 0.001" solref="0.001 1" friction="0.95 0.3 0.1" class="visual" material="pulse_button_material"/>
          <geom class="collision" type="box" pos="-0.09355254 -0.11231460 -0.15147408" size="0.015483303926885128 0.008930300362408161 0.002988857915624976" quat="0.9694134593009949 0.2453550100326538 -0.0021198231261223555 -0.005826357286423445" name="pulse_button_main"/>
        </body>
        <geom class="region" name="reg_main" type="box" pos="-3.500000000933312e-08 1.4499999999306734e-07 1.700000000215418e-07" size="0.150444465 0.16125245500000002 0.2710285"/>
      </body>
      <site rgba="0 1 0 0" size="0.005" pos="-0.03334941 0.05179600 0.27355863" name="anchor_site"/>
    </body>
  </worldbody>
  <actuator>
    <motor name="knob_speed_joint_actuator" joint="knob_speed_joint" gear="10"/>
    <motor name="pitcher_joint_actuator" joint="pitcher_joint" gear="10"/>
    <motor name="power_button_joint_actuator" joint="power_button_joint" gear="0.5"/>
    <motor name="pulse_button_joint_actuator" joint="pulse_button_joint" gear="0.5"/>
    <!-- <motor name="blade_joint_actuator" joint="blade_joint" gear="0.5"/> -->
  </actuator>
</mujoco>
